[2020-03-25 23:40:59,632][auth.py:96][INFO][1748] - {"api_name": "http://127.0.0.1:5000/login", "user_ip": "127.0.0.1", "user_name": "None", "status_code":"200"}
[2020-03-25 23:41:04,134][auth.py:96][INFO][14772] - {"api_name": "http://127.0.0.1:5000/login", "user_ip": "127.0.0.1", "user_name": "None", "status_code":"302"}
[2020-03-25 23:41:04,192][auth.py:96][INFO][14056] - {"api_name": "http://127.0.0.1:5000/register", "user_ip": "127.0.0.1", "user_name": "None", "status_code":"200"}
[2020-03-25 23:41:07,417][auth.py:96][INFO][8828] - {"api_name": "http://127.0.0.1:5000/validate", "user_ip": "127.0.0.1", "user_name": "None", "status_code":"200"}
[2020-03-25 23:41:11,354][auth.py:96][INFO][15784] - {"api_name": "http://127.0.0.1:5000/register", "user_ip": "127.0.0.1", "user_name": "None", "status_code":"302"}
[2020-03-25 23:41:11,363][auth.py:96][INFO][12772] - {"api_name": "http://127.0.0.1:5000/login", "user_ip": "127.0.0.1", "user_name": "None", "status_code":"200"}
[2020-03-25 23:41:14,482][auth.py:96][INFO][16800] - {"api_name": "http://127.0.0.1:5000/login", "user_ip": "127.0.0.1", "user_name": "None", "status_code":"302"}
[2020-03-25 23:41:14,512][view.py:42][INFO][16712] - {"api_name": "http://127.0.0.1:5000/index", "user_ip": "127.0.0.1", "user_name": "None", "status_code":"200"}
[2020-03-25 23:41:14,951][routes.py:71][INFO][5908] - {"api_name": "http://127.0.0.1:5000/getPriorityList?user=0", "user_ip": "127.0.0.1", "user_name": "None", "status_code":"200"}
[2020-03-25 23:41:19,181][auth.py:96][INFO][14848] - {"api_name": "http://127.0.0.1:5000/logout", "user_ip": "127.0.0.1", "user_name": "None", "status_code":"302"}
[2020-03-25 23:41:19,192][auth.py:96][INFO][11936] - {"api_name": "http://127.0.0.1:5000/login", "user_ip": "127.0.0.1", "user_name": "None", "status_code":"200"}
[2020-03-25 23:41:20,239][auth.py:96][INFO][11092] - {"api_name": "http://127.0.0.1:5000/login", "user_ip": "127.0.0.1", "user_name": "None", "status_code":"302"}
[2020-03-25 23:41:20,248][view.py:42][INFO][4464] - {"api_name": "http://127.0.0.1:5000/index", "user_ip": "127.0.0.1", "user_name": "None", "status_code":"200"}
[2020-03-25 23:41:20,404][routes.py:71][INFO][13848] - {"api_name": "http://127.0.0.1:5000/getPriorityList?user=0", "user_ip": "127.0.0.1", "user_name": "None", "status_code":"200"}
[2020-03-25 23:41:22,116][auth.py:96][INFO][10880] - {"api_name": "http://127.0.0.1:5000/logout", "user_ip": "127.0.0.1", "user_name": "None", "status_code":"302"}
[2020-03-25 23:41:22,127][auth.py:96][INFO][15956] - {"api_name": "http://127.0.0.1:5000/login", "user_ip": "127.0.0.1", "user_name": "None", "status_code":"200"}
[2020-03-25 23:41:22,939][auth.py:96][INFO][12776] - {"api_name": "http://127.0.0.1:5000/register", "user_ip": "127.0.0.1", "user_name": "None", "status_code":"200"}
[2020-03-25 23:41:24,606][auth.py:96][INFO][14528] - {"api_name": "http://127.0.0.1:5000/validate", "user_ip": "127.0.0.1", "user_name": "None", "status_code":"200"}
[2020-03-25 23:41:29,340][auth.py:96][INFO][13492] - {"api_name": "http://127.0.0.1:5000/login", "user_ip": "127.0.0.1", "user_name": "None", "status_code":"200"}
[2020-03-25 23:41:30,641][auth.py:96][INFO][5000] - {"api_name": "http://127.0.0.1:5000/login", "user_ip": "127.0.0.1", "user_name": "None", "status_code":"302"}
[2020-03-25 23:41:30,651][view.py:42][INFO][16644] - {"api_name": "http://127.0.0.1:5000/index", "user_ip": "127.0.0.1", "user_name": "None", "status_code":"200"}
[2020-03-25 23:41:30,792][routes.py:71][INFO][17344] - {"api_name": "http://127.0.0.1:5000/getPriorityList?user=0", "user_ip": "127.0.0.1", "user_name": "None", "status_code":"200"}
[2020-03-25 23:43:37,741][auth.py:96][INFO][13612] - {"api_name": "http://127.0.0.1:5000/logout", "user_ip": "127.0.0.1", "user_name": "None", "status_code":"302"}
[2020-03-25 23:43:37,759][auth.py:96][INFO][1748] - {"api_name": "http://127.0.0.1:5000/login", "user_ip": "127.0.0.1", "user_name": "None", "status_code":"200"}
[2020-03-25 23:43:39,356][auth.py:96][INFO][9512] - {"api_name": "http://127.0.0.1:5000/register", "user_ip": "127.0.0.1", "user_name": "None", "status_code":"200"}
[2020-03-25 23:43:40,892][auth.py:96][INFO][17064] - {"api_name": "http://127.0.0.1:5000/validate", "user_ip": "127.0.0.1", "user_name": "None", "status_code":"200"}
[2020-03-25 23:43:57,843][auth.py:96][INFO][11928] - {"api_name": "http://127.0.0.1:5000/register", "user_ip": "127.0.0.1", "user_name": "None", "status_code":"302"}
[2020-03-25 23:43:57,850][auth.py:96][INFO][9656] - {"api_name": "http://127.0.0.1:5000/login", "user_ip": "127.0.0.1", "user_name": "None", "status_code":"200"}
[2020-03-25 23:43:58,705][auth.py:96][INFO][16712] - {"api_name": "http://127.0.0.1:5000/login", "user_ip": "127.0.0.1", "user_name": "None", "status_code":"302"}
[2020-03-25 23:43:58,716][view.py:42][INFO][14724] - {"api_name": "http://127.0.0.1:5000/index", "user_ip": "127.0.0.1", "user_name": "None", "status_code":"200"}
[2020-03-25 23:43:58,818][routes.py:71][INFO][9460] - {"api_name": "http://127.0.0.1:5000/getPriorityList?user=0", "user_ip": "127.0.0.1", "user_name": "None", "status_code":"200"}
[2020-03-25 23:52:49,293][view.py:42][INFO][15664] - {"api_name": "http://127.0.0.1:5000/index", "user_ip": "127.0.0.1", "user_name": "None", "status_code":"200"}
[2020-03-25 23:52:49,403][routes.py:71][INFO][2972] - {"api_name": "http://127.0.0.1:5000/getPriorityList?user=0", "user_ip": "127.0.0.1", "user_name": "None", "status_code":"200"}
[2020-03-25 23:55:04,820][view.py:43][INFO][8200] - {"api_name": "http://127.0.0.1:5000/index", "user_ip": "127.0.0.1", "user_name": "None", "status_code":"302"}
[2020-03-25 23:55:04,891][auth.py:96][INFO][4252] - {"api_name": "http://127.0.0.1:5000/login?next=%2Findex", "user_ip": "127.0.0.1", "user_name": "None", "status_code":"200"}
[2020-03-25 23:55:20,637][auth.py:96][INFO][15940] - {"api_name": "http://127.0.0.1:5000/login", "user_ip": "127.0.0.1", "user_name": "None", "status_code":"302"}
[2020-03-25 23:55:20,652][auth.py:96][INFO][11640] - {"api_name": "http://127.0.0.1:5000/register", "user_ip": "127.0.0.1", "user_name": "None", "status_code":"200"}
[2020-03-25 23:55:22,428][auth.py:96][INFO][8244] - {"api_name": "http://127.0.0.1:5000/validate", "user_ip": "127.0.0.1", "user_name": "None", "status_code":"200"}
[2020-03-25 23:55:25,797][auth.py:96][INFO][16284] - {"api_name": "http://127.0.0.1:5000/register", "user_ip": "127.0.0.1", "user_name": "None", "status_code":"302"}
[2020-03-25 23:55:25,831][auth.py:96][INFO][4464] - {"api_name": "http://127.0.0.1:5000/login", "user_ip": "127.0.0.1", "user_name": "None", "status_code":"200"}
[2020-03-25 23:55:27,990][auth.py:96][INFO][1252] - {"api_name": "http://127.0.0.1:5000/register", "user_ip": "127.0.0.1", "user_name": "None", "status_code":"200"}
[2020-03-25 23:55:29,639][auth.py:96][INFO][12956] - {"api_name": "http://127.0.0.1:5000/validate", "user_ip": "127.0.0.1", "user_name": "None", "status_code":"200"}
[2020-03-25 23:55:32,458][auth.py:96][INFO][10608] - {"api_name": "http://127.0.0.1:5000/register", "user_ip": "127.0.0.1", "user_name": "None", "status_code":"302"}
[2020-03-25 23:55:32,467][auth.py:96][INFO][13196] - {"api_name": "http://127.0.0.1:5000/login", "user_ip": "127.0.0.1", "user_name": "None", "status_code":"200"}
[2020-03-25 23:55:33,976][auth.py:96][INFO][16160] - {"api_name": "http://127.0.0.1:5000/login", "user_ip": "127.0.0.1", "user_name": "None", "status_code":"302"}
[2020-03-25 23:55:33,989][app.py:1891][ERROR][16688] - Exception on /index [GET]
Traceback (most recent call last):
  File "D:\ProgramData\Miniconda3\envs\comp8715\lib\site-packages\flask\app.py", line 2446, in wsgi_app
    response = self.full_dispatch_request()
  File "D:\ProgramData\Miniconda3\envs\comp8715\lib\site-packages\flask\app.py", line 1951, in full_dispatch_request
    rv = self.handle_user_exception(e)
  File "D:\ProgramData\Miniconda3\envs\comp8715\lib\site-packages\flask_cors\extension.py", line 161, in wrapped_function
    return cors_after_request(app.make_response(f(*args, **kwargs)))
  File "D:\ProgramData\Miniconda3\envs\comp8715\lib\site-packages\flask\app.py", line 1820, in handle_user_exception
    reraise(exc_type, exc_value, tb)
  File "D:\ProgramData\Miniconda3\envs\comp8715\lib\site-packages\flask\_compat.py", line 39, in reraise
    raise value
  File "D:\ProgramData\Miniconda3\envs\comp8715\lib\site-packages\flask\app.py", line 1949, in full_dispatch_request
    rv = self.dispatch_request()
  File "D:\ProgramData\Miniconda3\envs\comp8715\lib\site-packages\flask\app.py", line 1935, in dispatch_request
    return self.view_functions[rule.endpoint](**req.view_args)
  File "D:\ProgramData\Miniconda3\envs\comp8715\lib\site-packages\flask_login\utils.py", line 272, in decorated_view
    return func(*args, **kwargs)
  File "D:\TedZhang\Courses\COMP8715\SAT-Track\server\views\view.py", line 10, in index
    redirect(url_for('login.html'))
  File "D:\ProgramData\Miniconda3\envs\comp8715\lib\site-packages\flask\helpers.py", line 370, in url_for
    return appctx.app.handle_url_build_error(error, endpoint, values)
  File "D:\ProgramData\Miniconda3\envs\comp8715\lib\site-packages\flask\app.py", line 2215, in handle_url_build_error
    reraise(exc_type, exc_value, tb)
  File "D:\ProgramData\Miniconda3\envs\comp8715\lib\site-packages\flask\_compat.py", line 39, in reraise
    raise value
  File "D:\ProgramData\Miniconda3\envs\comp8715\lib\site-packages\flask\helpers.py", line 358, in url_for
    endpoint, values, method=method, force_external=external
  File "D:\ProgramData\Miniconda3\envs\comp8715\lib\site-packages\werkzeug\routing.py", line 2179, in build
    raise BuildError(endpoint, values, method, self)
werkzeug.routing.BuildError: Could not build url for endpoint 'login.html'. Did you mean 'auth.login' instead?
[2020-03-25 23:55:34,100][view.py:40][INFO][16688] - {"api_name": "http://127.0.0.1:5000/index", "user_ip": "127.0.0.1", "user_name": "None", "status_code":"500"}
[2020-03-25 23:56:22,080][view.py:43][INFO][15308] - {"api_name": "http://127.0.0.1:5000/index", "user_ip": "127.0.0.1", "user_name": "None", "status_code":"200"}
[2020-03-25 23:56:22,269][routes.py:71][INFO][16380] - {"api_name": "http://127.0.0.1:5000/getPriorityList?user=0", "user_ip": "127.0.0.1", "user_name": "None", "status_code":"200"}
[2020-03-25 23:57:53,746][view.py:45][INFO][17068] - {"api_name": "http://127.0.0.1:5000/index", "user_ip": "127.0.0.1", "user_name": "None", "status_code":"200"}
[2020-03-25 23:57:53,837][routes.py:71][INFO][14280] - {"api_name": "http://127.0.0.1:5000/getPriorityList?user=0", "user_ip": "127.0.0.1", "user_name": "None", "status_code":"200"}
[2020-03-25 23:58:43,846][view.py:45][INFO][12772] - {"api_name": "http://127.0.0.1:5000/index", "user_ip": "127.0.0.1", "user_name": "None", "status_code":"200"}
[2020-03-25 23:58:43,914][routes.py:71][INFO][3744] - {"api_name": "http://127.0.0.1:5000/getPriorityList?user=0", "user_ip": "127.0.0.1", "user_name": "None", "status_code":"200"}
[2020-03-27 00:15:09,338][app.py:1891][ERROR][15416] - Exception on /deleteTask [GET]
Traceback (most recent call last):
  File "D:\ProgramData\Miniconda3\envs\comp8715\lib\site-packages\flask\app.py", line 2446, in wsgi_app
    response = self.full_dispatch_request()
  File "D:\ProgramData\Miniconda3\envs\comp8715\lib\site-packages\flask\app.py", line 1952, in full_dispatch_request
    return self.finalize_request(rv)
  File "D:\ProgramData\Miniconda3\envs\comp8715\lib\site-packages\flask\app.py", line 1967, in finalize_request
    response = self.make_response(rv)
  File "D:\ProgramData\Miniconda3\envs\comp8715\lib\site-packages\flask\app.py", line 2097, in make_response
    "The view function did not return a valid response. The"
TypeError: The view function did not return a valid response. The function either returned None or ended without a return statement.
[2020-03-27 01:50:45,692][app.py:1891][ERROR][784] - Exception on /index [GET]
Traceback (most recent call last):
  File "D:\ProgramData\Miniconda3\envs\comp8715\lib\site-packages\flask\app.py", line 2446, in wsgi_app
    response = self.full_dispatch_request()
  File "D:\ProgramData\Miniconda3\envs\comp8715\lib\site-packages\flask\app.py", line 1951, in full_dispatch_request
    rv = self.handle_user_exception(e)
  File "D:\ProgramData\Miniconda3\envs\comp8715\lib\site-packages\flask_cors\extension.py", line 161, in wrapped_function
    return cors_after_request(app.make_response(f(*args, **kwargs)))
  File "D:\ProgramData\Miniconda3\envs\comp8715\lib\site-packages\flask\app.py", line 1820, in handle_user_exception
    reraise(exc_type, exc_value, tb)
  File "D:\ProgramData\Miniconda3\envs\comp8715\lib\site-packages\flask\_compat.py", line 39, in reraise
    raise value
  File "D:\ProgramData\Miniconda3\envs\comp8715\lib\site-packages\flask\app.py", line 1949, in full_dispatch_request
    rv = self.dispatch_request()
  File "D:\ProgramData\Miniconda3\envs\comp8715\lib\site-packages\flask\app.py", line 1935, in dispatch_request
    return self.view_functions[rule.endpoint](**req.view_args)
  File "D:\TedZhang\Courses\COMP8715\SAT-Track\server\views\view.py", line 12, in index
    Simulation.init_db(user_id, user_info_pool, satellite_database)
  File "D:\TedZhang\Courses\COMP8715\SAT-Track\server\services\simulate_for_dev.py", line 11, in init_db
    origin['priority'] = priority
TypeError: 'NoneType' object does not support item assignment
[2020-03-29 13:04:38,609][app.py:1891][ERROR][1036] - Exception on /index [GET]
Traceback (most recent call last):
  File "D:\ProgramData\Miniconda3\envs\comp8715\lib\site-packages\flask\app.py", line 2446, in wsgi_app
    response = self.full_dispatch_request()
  File "D:\ProgramData\Miniconda3\envs\comp8715\lib\site-packages\flask\app.py", line 1951, in full_dispatch_request
    rv = self.handle_user_exception(e)
  File "D:\ProgramData\Miniconda3\envs\comp8715\lib\site-packages\flask_cors\extension.py", line 161, in wrapped_function
    return cors_after_request(app.make_response(f(*args, **kwargs)))
  File "D:\ProgramData\Miniconda3\envs\comp8715\lib\site-packages\flask\app.py", line 1820, in handle_user_exception
    reraise(exc_type, exc_value, tb)
  File "D:\ProgramData\Miniconda3\envs\comp8715\lib\site-packages\flask\_compat.py", line 39, in reraise
    raise value
  File "D:\ProgramData\Miniconda3\envs\comp8715\lib\site-packages\flask\app.py", line 1949, in full_dispatch_request
    rv = self.dispatch_request()
  File "D:\ProgramData\Miniconda3\envs\comp8715\lib\site-packages\flask\app.py", line 1935, in dispatch_request
    return self.view_functions[rule.endpoint](**req.view_args)
  File "D:\ProgramData\Miniconda3\envs\comp8715\lib\site-packages\flask_login\utils.py", line 270, in decorated_view
    elif not current_user.is_authenticated:
  File "D:\ProgramData\Miniconda3\envs\comp8715\lib\site-packages\werkzeug\local.py", line 347, in __getattr__
    return getattr(self._get_current_object(), name)
  File "D:\ProgramData\Miniconda3\envs\comp8715\lib\site-packages\werkzeug\local.py", line 306, in _get_current_object
    return self.__local()
  File "D:\ProgramData\Miniconda3\envs\comp8715\lib\site-packages\flask_login\utils.py", line 26, in <lambda>
    current_user = LocalProxy(lambda: _get_user())
  File "D:\ProgramData\Miniconda3\envs\comp8715\lib\site-packages\flask_login\utils.py", line 346, in _get_user
    current_app.login_manager._load_user()
  File "D:\ProgramData\Miniconda3\envs\comp8715\lib\site-packages\flask_login\login_manager.py", line 318, in _load_user
    user = self._user_callback(user_id)
  File "D:\TedZhang\Courses\COMP8715\SAT-Track\server\__init__.py", line 42, in load_user
    return User.get(user_id)
AttributeError: type object 'User' has no attribute 'get'
[2020-03-29 13:05:59,424][app.py:1891][ERROR][17016] - Exception on /deleteTask [GET]
Traceback (most recent call last):
  File "D:\ProgramData\Miniconda3\envs\comp8715\lib\site-packages\flask\app.py", line 2446, in wsgi_app
    response = self.full_dispatch_request()
  File "D:\ProgramData\Miniconda3\envs\comp8715\lib\site-packages\flask\app.py", line 1951, in full_dispatch_request
    rv = self.handle_user_exception(e)
  File "D:\ProgramData\Miniconda3\envs\comp8715\lib\site-packages\flask_cors\extension.py", line 161, in wrapped_function
    return cors_after_request(app.make_response(f(*args, **kwargs)))
  File "D:\ProgramData\Miniconda3\envs\comp8715\lib\site-packages\flask\app.py", line 1820, in handle_user_exception
    reraise(exc_type, exc_value, tb)
  File "D:\ProgramData\Miniconda3\envs\comp8715\lib\site-packages\flask\_compat.py", line 39, in reraise
    raise value
  File "D:\ProgramData\Miniconda3\envs\comp8715\lib\site-packages\flask\app.py", line 1949, in full_dispatch_request
    rv = self.dispatch_request()
  File "D:\ProgramData\Miniconda3\envs\comp8715\lib\site-packages\flask\app.py", line 1935, in dispatch_request
    return self.view_functions[rule.endpoint](**req.view_args)
  File "D:\TedZhang\Courses\COMP8715\SAT-Track\server\views\view.py", line 101, in delete_task
    priority_manager = PriorityManager(user_id)
  File "D:\TedZhang\Courses\COMP8715\SAT-Track\server\services\data_storage_service.py", line 40, in __init__
    for task in User.get(user_id).priority:
AttributeError: type object 'User' has no attribute 'get'
[2020-03-29 13:06:00,081][app.py:1891][ERROR][8100] - Exception on /deleteTask [GET]
Traceback (most recent call last):
  File "D:\ProgramData\Miniconda3\envs\comp8715\lib\site-packages\flask\app.py", line 2446, in wsgi_app
    response = self.full_dispatch_request()
  File "D:\ProgramData\Miniconda3\envs\comp8715\lib\site-packages\flask\app.py", line 1951, in full_dispatch_request
    rv = self.handle_user_exception(e)
  File "D:\ProgramData\Miniconda3\envs\comp8715\lib\site-packages\flask_cors\extension.py", line 161, in wrapped_function
    return cors_after_request(app.make_response(f(*args, **kwargs)))
  File "D:\ProgramData\Miniconda3\envs\comp8715\lib\site-packages\flask\app.py", line 1820, in handle_user_exception
    reraise(exc_type, exc_value, tb)
  File "D:\ProgramData\Miniconda3\envs\comp8715\lib\site-packages\flask\_compat.py", line 39, in reraise
    raise value
  File "D:\ProgramData\Miniconda3\envs\comp8715\lib\site-packages\flask\app.py", line 1949, in full_dispatch_request
    rv = self.dispatch_request()
  File "D:\ProgramData\Miniconda3\envs\comp8715\lib\site-packages\flask\app.py", line 1935, in dispatch_request
    return self.view_functions[rule.endpoint](**req.view_args)
  File "D:\TedZhang\Courses\COMP8715\SAT-Track\server\views\view.py", line 101, in delete_task
    priority_manager = PriorityManager(user_id)
  File "D:\TedZhang\Courses\COMP8715\SAT-Track\server\services\data_storage_service.py", line 40, in __init__
    for task in User.get(user_id).priority:
AttributeError: type object 'User' has no attribute 'get'
[2020-03-29 13:12:33,556][app.py:1891][ERROR][17860] - Exception on /login [POST]
Traceback (most recent call last):
  File "D:\ProgramData\Miniconda3\envs\comp8715\lib\site-packages\flask\app.py", line 2446, in wsgi_app
    response = self.full_dispatch_request()
  File "D:\ProgramData\Miniconda3\envs\comp8715\lib\site-packages\flask\app.py", line 1951, in full_dispatch_request
    rv = self.handle_user_exception(e)
  File "D:\ProgramData\Miniconda3\envs\comp8715\lib\site-packages\flask_cors\extension.py", line 161, in wrapped_function
    return cors_after_request(app.make_response(f(*args, **kwargs)))
  File "D:\ProgramData\Miniconda3\envs\comp8715\lib\site-packages\flask\app.py", line 1820, in handle_user_exception
    reraise(exc_type, exc_value, tb)
  File "D:\ProgramData\Miniconda3\envs\comp8715\lib\site-packages\flask\_compat.py", line 39, in reraise
    raise value
  File "D:\ProgramData\Miniconda3\envs\comp8715\lib\site-packages\flask\app.py", line 1949, in full_dispatch_request
    rv = self.dispatch_request()
  File "D:\ProgramData\Miniconda3\envs\comp8715\lib\site-packages\flask\app.py", line 1935, in dispatch_request
    return self.view_functions[rule.endpoint](**req.view_args)
  File "D:\TedZhang\Courses\COMP8715\SAT-Track\server\views\auth.py", line 61, in login
    user = UserManager.get(id)
  File "D:\TedZhang\Courses\COMP8715\SAT-Track\server\services\data_storage_service.py", line 14, in get
    priority = [Task(task['id'], task['name']) for task in res['priority']]
  File "D:\TedZhang\Courses\COMP8715\SAT-Track\server\services\data_storage_service.py", line 14, in <listcomp>
    priority = [Task(task['id'], task['name']) for task in res['priority']]
TypeError: string indices must be integers
[2020-03-29 13:20:05,971][app.py:1891][ERROR][7712] - Exception on /getUserInfo [GET]
Traceback (most recent call last):
  File "D:\ProgramData\Miniconda3\envs\comp8715\lib\site-packages\flask\app.py", line 2446, in wsgi_app
    response = self.full_dispatch_request()
  File "D:\ProgramData\Miniconda3\envs\comp8715\lib\site-packages\flask\app.py", line 1951, in full_dispatch_request
    rv = self.handle_user_exception(e)
  File "D:\ProgramData\Miniconda3\envs\comp8715\lib\site-packages\flask_cors\extension.py", line 161, in wrapped_function
    return cors_after_request(app.make_response(f(*args, **kwargs)))
  File "D:\ProgramData\Miniconda3\envs\comp8715\lib\site-packages\flask\app.py", line 1820, in handle_user_exception
    reraise(exc_type, exc_value, tb)
  File "D:\ProgramData\Miniconda3\envs\comp8715\lib\site-packages\flask\_compat.py", line 39, in reraise
    raise value
  File "D:\ProgramData\Miniconda3\envs\comp8715\lib\site-packages\flask\app.py", line 1949, in full_dispatch_request
    rv = self.dispatch_request()
  File "D:\ProgramData\Miniconda3\envs\comp8715\lib\site-packages\flask\app.py", line 1935, in dispatch_request
    return self.view_functions[rule.endpoint](**req.view_args)
  File "D:\TedZhang\Courses\COMP8715\SAT-Track\server\views\view.py", line 52, in get_user_info
    priority=user.priority
  File "D:\ProgramData\Miniconda3\envs\comp8715\lib\site-packages\flask\json\__init__.py", line 370, in jsonify
    dumps(data, indent=indent, separators=separators) + "\n",
  File "D:\ProgramData\Miniconda3\envs\comp8715\lib\site-packages\flask\json\__init__.py", line 211, in dumps
    rv = _json.dumps(obj, **kwargs)
  File "D:\ProgramData\Miniconda3\envs\comp8715\lib\json\__init__.py", line 238, in dumps
    **kw).encode(obj)
  File "D:\ProgramData\Miniconda3\envs\comp8715\lib\json\encoder.py", line 199, in encode
    chunks = self.iterencode(o, _one_shot=True)
  File "D:\ProgramData\Miniconda3\envs\comp8715\lib\json\encoder.py", line 257, in iterencode
    return _iterencode(o, 0)
  File "D:\ProgramData\Miniconda3\envs\comp8715\lib\site-packages\flask\json\__init__.py", line 100, in default
    return _json.JSONEncoder.default(self, o)
  File "D:\ProgramData\Miniconda3\envs\comp8715\lib\json\encoder.py", line 179, in default
    raise TypeError(f'Object of type {o.__class__.__name__} '
TypeError: Object of type Task is not JSON serializable
[2020-03-29 13:24:29,673][app.py:1891][ERROR][8776] - Exception on /getUserInfo [GET]
Traceback (most recent call last):
  File "D:\ProgramData\Miniconda3\envs\comp8715\lib\site-packages\flask\app.py", line 2446, in wsgi_app
    response = self.full_dispatch_request()
  File "D:\ProgramData\Miniconda3\envs\comp8715\lib\site-packages\flask\app.py", line 1951, in full_dispatch_request
    rv = self.handle_user_exception(e)
  File "D:\ProgramData\Miniconda3\envs\comp8715\lib\site-packages\flask_cors\extension.py", line 161, in wrapped_function
    return cors_after_request(app.make_response(f(*args, **kwargs)))
  File "D:\ProgramData\Miniconda3\envs\comp8715\lib\site-packages\flask\app.py", line 1820, in handle_user_exception
    reraise(exc_type, exc_value, tb)
  File "D:\ProgramData\Miniconda3\envs\comp8715\lib\site-packages\flask\_compat.py", line 39, in reraise
    raise value
  File "D:\ProgramData\Miniconda3\envs\comp8715\lib\site-packages\flask\app.py", line 1949, in full_dispatch_request
    rv = self.dispatch_request()
  File "D:\ProgramData\Miniconda3\envs\comp8715\lib\site-packages\flask\app.py", line 1935, in dispatch_request
    return self.view_functions[rule.endpoint](**req.view_args)
  File "D:\TedZhang\Courses\COMP8715\SAT-Track\server\views\view.py", line 49, in get_user_info
    priority=user.priority
  File "D:\ProgramData\Miniconda3\envs\comp8715\lib\site-packages\flask\json\__init__.py", line 370, in jsonify
    dumps(data, indent=indent, separators=separators) + "\n",
  File "D:\ProgramData\Miniconda3\envs\comp8715\lib\site-packages\flask\json\__init__.py", line 211, in dumps
    rv = _json.dumps(obj, **kwargs)
  File "D:\ProgramData\Miniconda3\envs\comp8715\lib\json\__init__.py", line 238, in dumps
    **kw).encode(obj)
  File "D:\ProgramData\Miniconda3\envs\comp8715\lib\json\encoder.py", line 199, in encode
    chunks = self.iterencode(o, _one_shot=True)
  File "D:\ProgramData\Miniconda3\envs\comp8715\lib\json\encoder.py", line 257, in iterencode
    return _iterencode(o, 0)
  File "D:\ProgramData\Miniconda3\envs\comp8715\lib\site-packages\flask\json\__init__.py", line 100, in default
    return _json.JSONEncoder.default(self, o)
  File "D:\ProgramData\Miniconda3\envs\comp8715\lib\json\encoder.py", line 179, in default
    raise TypeError(f'Object of type {o.__class__.__name__} '
TypeError: Object of type Task is not JSON serializable
[2020-03-29 15:00:15,217][app.py:1891][ERROR][4040] - Exception on /index [GET]
Traceback (most recent call last):
  File "D:\ProgramData\Miniconda3\envs\comp8715\lib\site-packages\flask\app.py", line 2446, in wsgi_app
    response = self.full_dispatch_request()
  File "D:\ProgramData\Miniconda3\envs\comp8715\lib\site-packages\flask\app.py", line 1951, in full_dispatch_request
    rv = self.handle_user_exception(e)
  File "D:\ProgramData\Miniconda3\envs\comp8715\lib\site-packages\flask_cors\extension.py", line 161, in wrapped_function
    return cors_after_request(app.make_response(f(*args, **kwargs)))
  File "D:\ProgramData\Miniconda3\envs\comp8715\lib\site-packages\flask\app.py", line 1820, in handle_user_exception
    reraise(exc_type, exc_value, tb)
  File "D:\ProgramData\Miniconda3\envs\comp8715\lib\site-packages\flask\_compat.py", line 39, in reraise
    raise value
  File "D:\ProgramData\Miniconda3\envs\comp8715\lib\site-packages\flask\app.py", line 1949, in full_dispatch_request
    rv = self.dispatch_request()
  File "D:\ProgramData\Miniconda3\envs\comp8715\lib\site-packages\flask\app.py", line 1935, in dispatch_request
    return self.view_functions[rule.endpoint](**req.view_args)
  File "D:\ProgramData\Miniconda3\envs\comp8715\lib\site-packages\flask_login\utils.py", line 270, in decorated_view
    elif not current_user.is_authenticated:
  File "D:\ProgramData\Miniconda3\envs\comp8715\lib\site-packages\werkzeug\local.py", line 347, in __getattr__
    return getattr(self._get_current_object(), name)
  File "D:\ProgramData\Miniconda3\envs\comp8715\lib\site-packages\werkzeug\local.py", line 306, in _get_current_object
    return self.__local()
  File "D:\ProgramData\Miniconda3\envs\comp8715\lib\site-packages\flask_login\utils.py", line 26, in <lambda>
    current_user = LocalProxy(lambda: _get_user())
  File "D:\ProgramData\Miniconda3\envs\comp8715\lib\site-packages\flask_login\utils.py", line 346, in _get_user
    current_app.login_manager._load_user()
  File "D:\ProgramData\Miniconda3\envs\comp8715\lib\site-packages\flask_login\login_manager.py", line 318, in _load_user
    user = self._user_callback(user_id)
  File "D:\TedZhang\Courses\COMP8715\SAT-Track\server\__init__.py", line 42, in load_user
    return UserManager.get(user_id)
  File "D:\TedZhang\Courses\COMP8715\SAT-Track\server\services\data_storage_service.py", line 12, in get
    res = user_info_pool.get(id)
NameError: name 'user_info_pool' is not defined
[2020-03-29 15:05:36,593][app.py:1891][ERROR][7712] - Exception on /deleteTask [GET]
Traceback (most recent call last):
  File "D:\ProgramData\Miniconda3\envs\comp8715\lib\site-packages\flask\app.py", line 2446, in wsgi_app
    response = self.full_dispatch_request()
  File "D:\ProgramData\Miniconda3\envs\comp8715\lib\site-packages\flask\app.py", line 1951, in full_dispatch_request
    rv = self.handle_user_exception(e)
  File "D:\ProgramData\Miniconda3\envs\comp8715\lib\site-packages\flask_cors\extension.py", line 161, in wrapped_function
    return cors_after_request(app.make_response(f(*args, **kwargs)))
  File "D:\ProgramData\Miniconda3\envs\comp8715\lib\site-packages\flask\app.py", line 1820, in handle_user_exception
    reraise(exc_type, exc_value, tb)
  File "D:\ProgramData\Miniconda3\envs\comp8715\lib\site-packages\flask\_compat.py", line 39, in reraise
    raise value
  File "D:\ProgramData\Miniconda3\envs\comp8715\lib\site-packages\flask\app.py", line 1949, in full_dispatch_request
    rv = self.dispatch_request()
  File "D:\ProgramData\Miniconda3\envs\comp8715\lib\site-packages\flask\app.py", line 1935, in dispatch_request
    return self.view_functions[rule.endpoint](**req.view_args)
  File "D:\TedZhang\Courses\COMP8715\SAT-Track\server\views\view.py", line 100, in delete_task
    if PriorityManager.delete(user.priority, satellite_id):
  File "D:\TedZhang\Courses\COMP8715\SAT-Track\server\services\data_storage_service.py", line 66, in delete
    priority.remove(satellite_id)
  File "D:\TedZhang\Courses\COMP8715\SAT-Track\server\models\objects.py", line 46, in remove
    return self.__tasks.remove(self.get(id))
  File "D:\TedZhang\Courses\COMP8715\SAT-Track\server\models\objects.py", line 38, in get
    return self.__tasks[self.__tasks.index(id)]
ValueError: '#000' is not in list
[2020-03-29 15:06:38,089][app.py:1891][ERROR][17880] - Exception on /deleteTask [GET]
Traceback (most recent call last):
  File "D:\ProgramData\Miniconda3\envs\comp8715\lib\site-packages\flask\app.py", line 2446, in wsgi_app
    response = self.full_dispatch_request()
  File "D:\ProgramData\Miniconda3\envs\comp8715\lib\site-packages\flask\app.py", line 1951, in full_dispatch_request
    rv = self.handle_user_exception(e)
  File "D:\ProgramData\Miniconda3\envs\comp8715\lib\site-packages\flask_cors\extension.py", line 161, in wrapped_function
    return cors_after_request(app.make_response(f(*args, **kwargs)))
  File "D:\ProgramData\Miniconda3\envs\comp8715\lib\site-packages\flask\app.py", line 1820, in handle_user_exception
    reraise(exc_type, exc_value, tb)
  File "D:\ProgramData\Miniconda3\envs\comp8715\lib\site-packages\flask\_compat.py", line 39, in reraise
    raise value
  File "D:\ProgramData\Miniconda3\envs\comp8715\lib\site-packages\flask\app.py", line 1949, in full_dispatch_request
    rv = self.dispatch_request()
  File "D:\ProgramData\Miniconda3\envs\comp8715\lib\site-packages\flask\app.py", line 1935, in dispatch_request
    return self.view_functions[rule.endpoint](**req.view_args)
  File "D:\TedZhang\Courses\COMP8715\SAT-Track\server\views\view.py", line 100, in delete_task
    if PriorityManager.delete(user.priority, satellite_id):
  File "D:\TedZhang\Courses\COMP8715\SAT-Track\server\services\data_storage_service.py", line 66, in delete
    priority.remove(satellite_id)
  File "D:\TedZhang\Courses\COMP8715\SAT-Track\server\models\objects.py", line 46, in remove
    return self.__tasks.remove(self.get(id))
  File "D:\TedZhang\Courses\COMP8715\SAT-Track\server\models\objects.py", line 38, in get
    return self.__tasks[self.__task_ids.index(id)]
ValueError: '#000' is not in list
[2020-03-29 15:07:21,384][app.py:1891][ERROR][12368] - Exception on /deleteTask [GET]
Traceback (most recent call last):
  File "D:\ProgramData\Miniconda3\envs\comp8715\lib\site-packages\flask\app.py", line 2446, in wsgi_app
    response = self.full_dispatch_request()
  File "D:\ProgramData\Miniconda3\envs\comp8715\lib\site-packages\flask\app.py", line 1951, in full_dispatch_request
    rv = self.handle_user_exception(e)
  File "D:\ProgramData\Miniconda3\envs\comp8715\lib\site-packages\flask_cors\extension.py", line 161, in wrapped_function
    return cors_after_request(app.make_response(f(*args, **kwargs)))
  File "D:\ProgramData\Miniconda3\envs\comp8715\lib\site-packages\flask\app.py", line 1820, in handle_user_exception
    reraise(exc_type, exc_value, tb)
  File "D:\ProgramData\Miniconda3\envs\comp8715\lib\site-packages\flask\_compat.py", line 39, in reraise
    raise value
  File "D:\ProgramData\Miniconda3\envs\comp8715\lib\site-packages\flask\app.py", line 1949, in full_dispatch_request
    rv = self.dispatch_request()
  File "D:\ProgramData\Miniconda3\envs\comp8715\lib\site-packages\flask\app.py", line 1935, in dispatch_request
    return self.view_functions[rule.endpoint](**req.view_args)
  File "D:\TedZhang\Courses\COMP8715\SAT-Track\server\views\view.py", line 100, in delete_task
    if PriorityManager.delete(user.priority, satellite_id):
  File "D:\TedZhang\Courses\COMP8715\SAT-Track\server\services\data_storage_service.py", line 66, in delete
    priority.remove(satellite_id)
  File "D:\TedZhang\Courses\COMP8715\SAT-Track\server\models\objects.py", line 48, in remove
    return self.__tasks.remove(self.get(id))
  File "D:\TedZhang\Courses\COMP8715\SAT-Track\server\models\objects.py", line 38, in get
    index = self.__task_ids.index(id)
ValueError: '#000' is not in list
[2020-03-29 15:08:32,919][app.py:1891][ERROR][17620] - Exception on /deleteTask [GET]
Traceback (most recent call last):
  File "D:\ProgramData\Miniconda3\envs\comp8715\lib\site-packages\flask\app.py", line 2446, in wsgi_app
    response = self.full_dispatch_request()
  File "D:\ProgramData\Miniconda3\envs\comp8715\lib\site-packages\flask\app.py", line 1951, in full_dispatch_request
    rv = self.handle_user_exception(e)
  File "D:\ProgramData\Miniconda3\envs\comp8715\lib\site-packages\flask_cors\extension.py", line 161, in wrapped_function
    return cors_after_request(app.make_response(f(*args, **kwargs)))
  File "D:\ProgramData\Miniconda3\envs\comp8715\lib\site-packages\flask\app.py", line 1820, in handle_user_exception
    reraise(exc_type, exc_value, tb)
  File "D:\ProgramData\Miniconda3\envs\comp8715\lib\site-packages\flask\_compat.py", line 39, in reraise
    raise value
  File "D:\ProgramData\Miniconda3\envs\comp8715\lib\site-packages\flask\app.py", line 1949, in full_dispatch_request
    rv = self.dispatch_request()
  File "D:\ProgramData\Miniconda3\envs\comp8715\lib\site-packages\flask\app.py", line 1935, in dispatch_request
    return self.view_functions[rule.endpoint](**req.view_args)
  File "D:\TedZhang\Courses\COMP8715\SAT-Track\server\views\view.py", line 100, in delete_task
    if PriorityManager.delete(user.priority, satellite_id):
  File "D:\TedZhang\Courses\COMP8715\SAT-Track\server\services\data_storage_service.py", line 66, in delete
    priority.remove(satellite_id)
  File "D:\TedZhang\Courses\COMP8715\SAT-Track\server\models\objects.py", line 49, in remove
    return self.__tasks.remove(self.get(id))
  File "D:\TedZhang\Courses\COMP8715\SAT-Track\server\models\objects.py", line 40, in get
    index = self.__task_ids.index(id)
ValueError: '#000' is not in list
[2020-03-29 15:09:36,385][app.py:1891][ERROR][468] - Exception on /deleteTask [GET]
Traceback (most recent call last):
  File "D:\ProgramData\Miniconda3\envs\comp8715\lib\site-packages\flask\app.py", line 2446, in wsgi_app
    response = self.full_dispatch_request()
  File "D:\ProgramData\Miniconda3\envs\comp8715\lib\site-packages\flask\app.py", line 1951, in full_dispatch_request
    rv = self.handle_user_exception(e)
  File "D:\ProgramData\Miniconda3\envs\comp8715\lib\site-packages\flask_cors\extension.py", line 161, in wrapped_function
    return cors_after_request(app.make_response(f(*args, **kwargs)))
  File "D:\ProgramData\Miniconda3\envs\comp8715\lib\site-packages\flask\app.py", line 1820, in handle_user_exception
    reraise(exc_type, exc_value, tb)
  File "D:\ProgramData\Miniconda3\envs\comp8715\lib\site-packages\flask\_compat.py", line 39, in reraise
    raise value
  File "D:\ProgramData\Miniconda3\envs\comp8715\lib\site-packages\flask\app.py", line 1949, in full_dispatch_request
    rv = self.dispatch_request()
  File "D:\ProgramData\Miniconda3\envs\comp8715\lib\site-packages\flask\app.py", line 1935, in dispatch_request
    return self.view_functions[rule.endpoint](**req.view_args)
  File "D:\TedZhang\Courses\COMP8715\SAT-Track\server\views\view.py", line 100, in delete_task
    if PriorityManager.delete(user.priority, satellite_id):
  File "D:\TedZhang\Courses\COMP8715\SAT-Track\server\services\data_storage_service.py", line 66, in delete
    priority.remove(satellite_id)
  File "D:\TedZhang\Courses\COMP8715\SAT-Track\server\models\objects.py", line 49, in remove
    return self.__tasks.remove(self.get(id))
  File "D:\TedZhang\Courses\COMP8715\SAT-Track\server\models\objects.py", line 40, in get
    index = self.__task_ids.index(id)
ValueError: '#000' is not in list
[2020-03-29 16:03:46,480][app.py:1891][ERROR][15984] - Exception on /deleteTask [GET]
Traceback (most recent call last):
  File "D:\ProgramData\Miniconda3\envs\comp8715\lib\site-packages\flask\app.py", line 2446, in wsgi_app
    response = self.full_dispatch_request()
  File "D:\ProgramData\Miniconda3\envs\comp8715\lib\site-packages\flask\app.py", line 1951, in full_dispatch_request
    rv = self.handle_user_exception(e)
  File "D:\ProgramData\Miniconda3\envs\comp8715\lib\site-packages\flask_cors\extension.py", line 161, in wrapped_function
    return cors_after_request(app.make_response(f(*args, **kwargs)))
  File "D:\ProgramData\Miniconda3\envs\comp8715\lib\site-packages\flask\app.py", line 1820, in handle_user_exception
    reraise(exc_type, exc_value, tb)
  File "D:\ProgramData\Miniconda3\envs\comp8715\lib\site-packages\flask\_compat.py", line 39, in reraise
    raise value
  File "D:\ProgramData\Miniconda3\envs\comp8715\lib\site-packages\flask\app.py", line 1949, in full_dispatch_request
    rv = self.dispatch_request()
  File "D:\ProgramData\Miniconda3\envs\comp8715\lib\site-packages\flask\app.py", line 1935, in dispatch_request
    return self.view_functions[rule.endpoint](**req.view_args)
  File "D:\TedZhang\Courses\COMP8715\SAT-Track\server\views\view.py", line 108, in delete_task
    tasks = user.priority = PriorityManager.delete(user.priority, satellite_id)
  File "D:\TedZhang\Courses\COMP8715\SAT-Track\server\services\data_storage_service.py", line 70, in delete
    priority = Priority(tasks)
  File "D:\TedZhang\Courses\COMP8715\SAT-Track\server\models\objects.py", line 34, in __init__
    self.__tasks = [Task(task['id'], task['name']) for task in priority]
TypeError: 'NoneType' object is not iterable
[2020-03-29 16:03:46,681][app.py:1891][ERROR][15224] - Exception on /deleteTask [GET]
Traceback (most recent call last):
  File "D:\ProgramData\Miniconda3\envs\comp8715\lib\site-packages\flask\app.py", line 2446, in wsgi_app
    response = self.full_dispatch_request()
  File "D:\ProgramData\Miniconda3\envs\comp8715\lib\site-packages\flask\app.py", line 1951, in full_dispatch_request
    rv = self.handle_user_exception(e)
  File "D:\ProgramData\Miniconda3\envs\comp8715\lib\site-packages\flask_cors\extension.py", line 161, in wrapped_function
    return cors_after_request(app.make_response(f(*args, **kwargs)))
  File "D:\ProgramData\Miniconda3\envs\comp8715\lib\site-packages\flask\app.py", line 1820, in handle_user_exception
    reraise(exc_type, exc_value, tb)
  File "D:\ProgramData\Miniconda3\envs\comp8715\lib\site-packages\flask\_compat.py", line 39, in reraise
    raise value
  File "D:\ProgramData\Miniconda3\envs\comp8715\lib\site-packages\flask\app.py", line 1949, in full_dispatch_request
    rv = self.dispatch_request()
  File "D:\ProgramData\Miniconda3\envs\comp8715\lib\site-packages\flask\app.py", line 1935, in dispatch_request
    return self.view_functions[rule.endpoint](**req.view_args)
  File "D:\TedZhang\Courses\COMP8715\SAT-Track\server\views\view.py", line 108, in delete_task
    tasks = user.priority = PriorityManager.delete(user.priority, satellite_id)
  File "D:\TedZhang\Courses\COMP8715\SAT-Track\server\services\data_storage_service.py", line 70, in delete
    priority = Priority(tasks)
  File "D:\TedZhang\Courses\COMP8715\SAT-Track\server\models\objects.py", line 34, in __init__
    self.__tasks = [Task(task['id'], task['name']) for task in priority]
TypeError: 'NoneType' object is not iterable
[2020-03-29 16:03:46,810][app.py:1891][ERROR][8744] - Exception on /deleteTask [GET]
Traceback (most recent call last):
  File "D:\ProgramData\Miniconda3\envs\comp8715\lib\site-packages\flask\app.py", line 2446, in wsgi_app
    response = self.full_dispatch_request()
  File "D:\ProgramData\Miniconda3\envs\comp8715\lib\site-packages\flask\app.py", line 1951, in full_dispatch_request
    rv = self.handle_user_exception(e)
  File "D:\ProgramData\Miniconda3\envs\comp8715\lib\site-packages\flask_cors\extension.py", line 161, in wrapped_function
    return cors_after_request(app.make_response(f(*args, **kwargs)))
  File "D:\ProgramData\Miniconda3\envs\comp8715\lib\site-packages\flask\app.py", line 1820, in handle_user_exception
    reraise(exc_type, exc_value, tb)
  File "D:\ProgramData\Miniconda3\envs\comp8715\lib\site-packages\flask\_compat.py", line 39, in reraise
    raise value
  File "D:\ProgramData\Miniconda3\envs\comp8715\lib\site-packages\flask\app.py", line 1949, in full_dispatch_request
    rv = self.dispatch_request()
  File "D:\ProgramData\Miniconda3\envs\comp8715\lib\site-packages\flask\app.py", line 1935, in dispatch_request
    return self.view_functions[rule.endpoint](**req.view_args)
  File "D:\TedZhang\Courses\COMP8715\SAT-Track\server\views\view.py", line 108, in delete_task
    tasks = user.priority = PriorityManager.delete(user.priority, satellite_id)
  File "D:\TedZhang\Courses\COMP8715\SAT-Track\server\services\data_storage_service.py", line 70, in delete
    priority = Priority(tasks)
  File "D:\TedZhang\Courses\COMP8715\SAT-Track\server\models\objects.py", line 34, in __init__
    self.__tasks = [Task(task['id'], task['name']) for task in priority]
TypeError: 'NoneType' object is not iterable
[2020-03-29 21:22:07,205][app.py:1891][ERROR][13000] - Exception on /activateTask [GET]
Traceback (most recent call last):
  File "D:\ProgramData\Miniconda3\envs\comp8715\lib\site-packages\flask\app.py", line 2446, in wsgi_app
    response = self.full_dispatch_request()
  File "D:\ProgramData\Miniconda3\envs\comp8715\lib\site-packages\flask\app.py", line 1951, in full_dispatch_request
    rv = self.handle_user_exception(e)
  File "D:\ProgramData\Miniconda3\envs\comp8715\lib\site-packages\flask_cors\extension.py", line 161, in wrapped_function
    return cors_after_request(app.make_response(f(*args, **kwargs)))
  File "D:\ProgramData\Miniconda3\envs\comp8715\lib\site-packages\flask\app.py", line 1820, in handle_user_exception
    reraise(exc_type, exc_value, tb)
  File "D:\ProgramData\Miniconda3\envs\comp8715\lib\site-packages\flask\_compat.py", line 39, in reraise
    raise value
  File "D:\ProgramData\Miniconda3\envs\comp8715\lib\site-packages\flask\app.py", line 1949, in full_dispatch_request
    rv = self.dispatch_request()
  File "D:\ProgramData\Miniconda3\envs\comp8715\lib\site-packages\flask\app.py", line 1935, in dispatch_request
    return self.view_functions[rule.endpoint](**req.view_args)
  File "D:\TedZhang\Courses\COMP8715\SAT-Track\server\views\view.py", line 117, in activate_task
    tasks, is_active = controll_activate_task(user_id, satellite_id)
NameError: name 'controll_activate_task' is not defined
[2020-03-29 21:22:24,602][app.py:1891][ERROR][7044] - Exception on /activateTask [GET]
Traceback (most recent call last):
  File "D:\ProgramData\Miniconda3\envs\comp8715\lib\site-packages\flask\app.py", line 2446, in wsgi_app
    response = self.full_dispatch_request()
  File "D:\ProgramData\Miniconda3\envs\comp8715\lib\site-packages\flask\app.py", line 1951, in full_dispatch_request
    rv = self.handle_user_exception(e)
  File "D:\ProgramData\Miniconda3\envs\comp8715\lib\site-packages\flask_cors\extension.py", line 161, in wrapped_function
    return cors_after_request(app.make_response(f(*args, **kwargs)))
  File "D:\ProgramData\Miniconda3\envs\comp8715\lib\site-packages\flask\app.py", line 1820, in handle_user_exception
    reraise(exc_type, exc_value, tb)
  File "D:\ProgramData\Miniconda3\envs\comp8715\lib\site-packages\flask\_compat.py", line 39, in reraise
    raise value
  File "D:\ProgramData\Miniconda3\envs\comp8715\lib\site-packages\flask\app.py", line 1949, in full_dispatch_request
    rv = self.dispatch_request()
  File "D:\ProgramData\Miniconda3\envs\comp8715\lib\site-packages\flask\app.py", line 1935, in dispatch_request
    return self.view_functions[rule.endpoint](**req.view_args)
  File "D:\TedZhang\Courses\COMP8715\SAT-Track\server\views\view.py", line 117, in activate_task
    tasks, is_active = controll_activate_task_or_not(user_id, satellite_id)
  File "D:\TedZhang\Courses\COMP8715\SAT-Track\server\controllers\user_behavior_controller.py", line 27, in controll_activate_task_or_not
    tasks, executable, is_active = user.priority, _, _ = PriorityManager.activate(user.priority, satellite_id)
ValueError: not enough values to unpack (expected 3, got 2)
[2020-03-29 21:58:45,833][app.py:1891][ERROR][8860] - Exception on /activateTask [GET]
Traceback (most recent call last):
  File "D:\ProgramData\Miniconda3\envs\comp8715\lib\site-packages\flask\app.py", line 2446, in wsgi_app
    response = self.full_dispatch_request()
  File "D:\ProgramData\Miniconda3\envs\comp8715\lib\site-packages\flask\app.py", line 1951, in full_dispatch_request
    rv = self.handle_user_exception(e)
  File "D:\ProgramData\Miniconda3\envs\comp8715\lib\site-packages\flask_cors\extension.py", line 161, in wrapped_function
    return cors_after_request(app.make_response(f(*args, **kwargs)))
  File "D:\ProgramData\Miniconda3\envs\comp8715\lib\site-packages\flask\app.py", line 1820, in handle_user_exception
    reraise(exc_type, exc_value, tb)
  File "D:\ProgramData\Miniconda3\envs\comp8715\lib\site-packages\flask\_compat.py", line 39, in reraise
    raise value
  File "D:\ProgramData\Miniconda3\envs\comp8715\lib\site-packages\flask\app.py", line 1949, in full_dispatch_request
    rv = self.dispatch_request()
  File "D:\ProgramData\Miniconda3\envs\comp8715\lib\site-packages\flask\app.py", line 1935, in dispatch_request
    return self.view_functions[rule.endpoint](**req.view_args)
  File "D:\TedZhang\Courses\COMP8715\SAT-Track\server\views\view.py", line 117, in activate_task
    tasks, is_active = controll_activate_task(user_id, satellite_id)
TypeError: cannot unpack non-iterable bool object
[2020-03-29 22:23:25,156][app.py:1891][ERROR][17308] - Exception on /index [GET]
Traceback (most recent call last):
  File "D:\ProgramData\Miniconda3\envs\comp8715\lib\site-packages\flask\app.py", line 2446, in wsgi_app
    response = self.full_dispatch_request()
  File "D:\ProgramData\Miniconda3\envs\comp8715\lib\site-packages\flask\app.py", line 1951, in full_dispatch_request
    rv = self.handle_user_exception(e)
  File "D:\ProgramData\Miniconda3\envs\comp8715\lib\site-packages\flask_cors\extension.py", line 161, in wrapped_function
    return cors_after_request(app.make_response(f(*args, **kwargs)))
  File "D:\ProgramData\Miniconda3\envs\comp8715\lib\site-packages\flask\app.py", line 1820, in handle_user_exception
    reraise(exc_type, exc_value, tb)
  File "D:\ProgramData\Miniconda3\envs\comp8715\lib\site-packages\flask\_compat.py", line 39, in reraise
    raise value
  File "D:\ProgramData\Miniconda3\envs\comp8715\lib\site-packages\flask\app.py", line 1949, in full_dispatch_request
    rv = self.dispatch_request()
  File "D:\ProgramData\Miniconda3\envs\comp8715\lib\site-packages\flask\app.py", line 1935, in dispatch_request
    return self.view_functions[rule.endpoint](**req.view_args)
  File "D:\ProgramData\Miniconda3\envs\comp8715\lib\site-packages\flask_login\utils.py", line 270, in decorated_view
    elif not current_user.is_authenticated:
  File "D:\ProgramData\Miniconda3\envs\comp8715\lib\site-packages\werkzeug\local.py", line 347, in __getattr__
    return getattr(self._get_current_object(), name)
  File "D:\ProgramData\Miniconda3\envs\comp8715\lib\site-packages\werkzeug\local.py", line 306, in _get_current_object
    return self.__local()
  File "D:\ProgramData\Miniconda3\envs\comp8715\lib\site-packages\flask_login\utils.py", line 26, in <lambda>
    current_user = LocalProxy(lambda: _get_user())
  File "D:\ProgramData\Miniconda3\envs\comp8715\lib\site-packages\flask_login\utils.py", line 346, in _get_user
    current_app.login_manager._load_user()
  File "D:\ProgramData\Miniconda3\envs\comp8715\lib\site-packages\flask_login\login_manager.py", line 318, in _load_user
    user = self._user_callback(user_id)
  File "D:\TedZhang\Courses\COMP8715\SAT-Track\server\__init__.py", line 42, in load_user
    return UserManager.get(user_id)
  File "D:\TedZhang\Courses\COMP8715\SAT-Track\server\services\data_storage_service.py", line 13, in get
    print('get user(', res['email'], ')\'s info:', res['priority'])
TypeError: 'NoneType' object is not subscriptable
[2020-03-29 23:09:00,369][app.py:1891][ERROR][4424] - Exception on /searchNewTask [GET]
Traceback (most recent call last):
  File "D:\ProgramData\Miniconda3\envs\comp8715\lib\site-packages\flask\app.py", line 2446, in wsgi_app
    response = self.full_dispatch_request()
  File "D:\ProgramData\Miniconda3\envs\comp8715\lib\site-packages\flask\app.py", line 1951, in full_dispatch_request
    rv = self.handle_user_exception(e)
  File "D:\ProgramData\Miniconda3\envs\comp8715\lib\site-packages\flask_cors\extension.py", line 161, in wrapped_function
    return cors_after_request(app.make_response(f(*args, **kwargs)))
  File "D:\ProgramData\Miniconda3\envs\comp8715\lib\site-packages\flask\app.py", line 1820, in handle_user_exception
    reraise(exc_type, exc_value, tb)
  File "D:\ProgramData\Miniconda3\envs\comp8715\lib\site-packages\flask\_compat.py", line 39, in reraise
    raise value
  File "D:\ProgramData\Miniconda3\envs\comp8715\lib\site-packages\flask\app.py", line 1949, in full_dispatch_request
    rv = self.dispatch_request()
  File "D:\ProgramData\Miniconda3\envs\comp8715\lib\site-packages\flask\app.py", line 1935, in dispatch_request
    return self.view_functions[rule.endpoint](**req.view_args)
  File "D:\TedZhang\Courses\COMP8715\SAT-Track\server\views\view.py", line 137, in search_new_task
    status, tasks = controll_search_new_task(user_id, satellite_id)
  File "D:\TedZhang\Courses\COMP8715\SAT-Track\server\controllers\user_behavior_controller.py", line 53, in controll_search_new_task
    status, tasks = PriorityManager.insert(user.priority, satellite)
AttributeError: 'NoneType' object has no attribute 'priority'
[2020-04-03 00:51:54,008][app.py:1891][ERROR][17904] - Exception on /searchNewTask [GET]
Traceback (most recent call last):
  File "D:\ProgramData\Miniconda3\envs\comp8715\lib\site-packages\flask\app.py", line 2446, in wsgi_app
    response = self.full_dispatch_request()
  File "D:\ProgramData\Miniconda3\envs\comp8715\lib\site-packages\flask\app.py", line 1951, in full_dispatch_request
    rv = self.handle_user_exception(e)
  File "D:\ProgramData\Miniconda3\envs\comp8715\lib\site-packages\flask_cors\extension.py", line 161, in wrapped_function
    return cors_after_request(app.make_response(f(*args, **kwargs)))
  File "D:\ProgramData\Miniconda3\envs\comp8715\lib\site-packages\flask\app.py", line 1820, in handle_user_exception
    reraise(exc_type, exc_value, tb)
  File "D:\ProgramData\Miniconda3\envs\comp8715\lib\site-packages\flask\_compat.py", line 39, in reraise
    raise value
  File "D:\ProgramData\Miniconda3\envs\comp8715\lib\site-packages\flask\app.py", line 1949, in full_dispatch_request
    rv = self.dispatch_request()
  File "D:\ProgramData\Miniconda3\envs\comp8715\lib\site-packages\flask\app.py", line 1935, in dispatch_request
    return self.view_functions[rule.endpoint](**req.view_args)
  File "D:\TedZhang\Courses\COMP8715\SAT-Track\server\views\view.py", line 141, in search_new_task
    status, tasks = controll_search_new_task(user_id, satellite_id)
  File "D:\TedZhang\Courses\COMP8715\SAT-Track\server\controllers\user_behavior_controller.py", line 69, in controll_search_new_task
    satellite = fetch_satellite_info(satellite_id)
  File "D:\TedZhang\Courses\COMP8715\SAT-Track\server\services\satellite_location_service.py", line 6, in fetch_satellite_info
    res = Spyder(id).parse()
  File "D:\TedZhang\Courses\COMP8715\SAT-Track\server\services\spyder.py", line 33, in parse
    return result[0].split()
IndexError: list index out of range
[2020-04-03 01:42:22,359][app.py:1891][ERROR][21008] - Exception on /searchNewTask [GET]
Traceback (most recent call last):
  File "D:\ProgramData\Miniconda3\envs\comp8715\lib\site-packages\flask\app.py", line 2446, in wsgi_app
    response = self.full_dispatch_request()
  File "D:\ProgramData\Miniconda3\envs\comp8715\lib\site-packages\flask\app.py", line 1951, in full_dispatch_request
    rv = self.handle_user_exception(e)
  File "D:\ProgramData\Miniconda3\envs\comp8715\lib\site-packages\flask_cors\extension.py", line 161, in wrapped_function
    return cors_after_request(app.make_response(f(*args, **kwargs)))
  File "D:\ProgramData\Miniconda3\envs\comp8715\lib\site-packages\flask\app.py", line 1820, in handle_user_exception
    reraise(exc_type, exc_value, tb)
  File "D:\ProgramData\Miniconda3\envs\comp8715\lib\site-packages\flask\_compat.py", line 39, in reraise
    raise value
  File "D:\ProgramData\Miniconda3\envs\comp8715\lib\site-packages\flask\app.py", line 1949, in full_dispatch_request
    rv = self.dispatch_request()
  File "D:\ProgramData\Miniconda3\envs\comp8715\lib\site-packages\flask\app.py", line 1935, in dispatch_request
    return self.view_functions[rule.endpoint](**req.view_args)
  File "D:\TedZhang\Courses\COMP8715\SAT-Track\server\views\view.py", line 141, in search_new_task
    status, tasks = controll_search_new_task(user_id, satellite_id)
  File "D:\TedZhang\Courses\COMP8715\SAT-Track\server\controllers\user_behavior_controller.py", line 70, in controll_search_new_task
    satellite = fetch_satellite_info(satellite_id) if satellite is None else satellite
  File "D:\TedZhang\Courses\COMP8715\SAT-Track\server\services\satellite_location_service.py", line 32, in fetch_satellite_info
    executor = ThreadPoolExecutor(max_workers=conf.MAX_WORKERS)
NameError: name 'ThreadPoolExecutor' is not defined
[2020-04-03 01:44:27,089][app.py:1891][ERROR][1312] - Exception on /searchNewTask [GET]
Traceback (most recent call last):
  File "D:\ProgramData\Miniconda3\envs\comp8715\lib\site-packages\flask\app.py", line 2446, in wsgi_app
    response = self.full_dispatch_request()
  File "D:\ProgramData\Miniconda3\envs\comp8715\lib\site-packages\flask\app.py", line 1951, in full_dispatch_request
    rv = self.handle_user_exception(e)
  File "D:\ProgramData\Miniconda3\envs\comp8715\lib\site-packages\flask_cors\extension.py", line 161, in wrapped_function
    return cors_after_request(app.make_response(f(*args, **kwargs)))
  File "D:\ProgramData\Miniconda3\envs\comp8715\lib\site-packages\flask\app.py", line 1820, in handle_user_exception
    reraise(exc_type, exc_value, tb)
  File "D:\ProgramData\Miniconda3\envs\comp8715\lib\site-packages\flask\_compat.py", line 39, in reraise
    raise value
  File "D:\ProgramData\Miniconda3\envs\comp8715\lib\site-packages\flask\app.py", line 1949, in full_dispatch_request
    rv = self.dispatch_request()
  File "D:\ProgramData\Miniconda3\envs\comp8715\lib\site-packages\flask\app.py", line 1935, in dispatch_request
    return self.view_functions[rule.endpoint](**req.view_args)
  File "D:\TedZhang\Courses\COMP8715\SAT-Track\server\views\view.py", line 141, in search_new_task
    status, tasks = controll_search_new_task(user_id, satellite_id)
  File "D:\TedZhang\Courses\COMP8715\SAT-Track\server\controllers\user_behavior_controller.py", line 70, in controll_search_new_task
    satellite = fetch_satellite_info(satellite_id) if satellite is None else satellite
  File "D:\TedZhang\Courses\COMP8715\SAT-Track\server\services\satellite_location_service.py", line 32, in fetch_satellite_info
    executor = ThreadPoolExecutor(max_workers=conf.MAX_WORKERS)
NameError: name 'conf' is not defined
[2020-04-05 23:59:08,142][app.py:1891][ERROR][17352] - Exception on /searchNewTask [GET]
Traceback (most recent call last):
  File "D:\ProgramData\Miniconda3\envs\comp8715\lib\site-packages\flask\app.py", line 2446, in wsgi_app
    response = self.full_dispatch_request()
  File "D:\ProgramData\Miniconda3\envs\comp8715\lib\site-packages\flask\app.py", line 1951, in full_dispatch_request
    rv = self.handle_user_exception(e)
  File "D:\ProgramData\Miniconda3\envs\comp8715\lib\site-packages\flask_cors\extension.py", line 161, in wrapped_function
    return cors_after_request(app.make_response(f(*args, **kwargs)))
  File "D:\ProgramData\Miniconda3\envs\comp8715\lib\site-packages\flask\app.py", line 1820, in handle_user_exception
    reraise(exc_type, exc_value, tb)
  File "D:\ProgramData\Miniconda3\envs\comp8715\lib\site-packages\flask\_compat.py", line 39, in reraise
    raise value
  File "D:\ProgramData\Miniconda3\envs\comp8715\lib\site-packages\flask\app.py", line 1949, in full_dispatch_request
    rv = self.dispatch_request()
  File "D:\ProgramData\Miniconda3\envs\comp8715\lib\site-packages\flask\app.py", line 1935, in dispatch_request
    return self.view_functions[rule.endpoint](**req.view_args)
  File "D:\TedZhang\Courses\COMP8715\SAT-Track\server\views\view.py", line 141, in search_new_task
    status, tasks = controll_search_new_task(user_id, satellite_id)
  File "D:\TedZhang\Courses\COMP8715\SAT-Track\server\controllers\user_behavior_controller.py", line 69, in controll_search_new_task
    satellite = SatelliteManager.get(satellite_id)
  File "D:\TedZhang\Courses\COMP8715\SAT-Track\server\services\data_storage_service.py", line 120, in get
    satellite_database.search(info)
  File "D:\TedZhang\Courses\COMP8715\SAT-Track\utilities\es_io.py", line 115, in search
    response = es.search(index=self.table, size=conf.ES_QUERY_MAX_SIZE, body=body)
  File "D:\ProgramData\Miniconda3\envs\comp8715\lib\site-packages\elasticsearch\client\utils.py", line 84, in _wrapped
    return func(*args, params=params, **kwargs)
  File "D:\ProgramData\Miniconda3\envs\comp8715\lib\site-packages\elasticsearch\client\__init__.py", line 811, in search
    "GET", _make_path(index, "_search"), params=params, body=body
  File "D:\ProgramData\Miniconda3\envs\comp8715\lib\site-packages\elasticsearch\transport.py", line 358, in perform_request
    timeout=timeout,
  File "D:\ProgramData\Miniconda3\envs\comp8715\lib\site-packages\elasticsearch\connection\http_urllib3.py", line 257, in perform_request
    self._raise_error(response.status, raw_data)
  File "D:\ProgramData\Miniconda3\envs\comp8715\lib\site-packages\elasticsearch\connection\base.py", line 182, in _raise_error
    status_code, error_message, additional_info
elasticsearch.exceptions.RequestError: RequestError(400, 'illegal_argument_exception', 'query malformed, empty clause found at [1:11]')
