[2020-04-19 01:22:36,433][app.py:1891][ERROR][4552] - Exception on /searchSatellite [GET]
Traceback (most recent call last):
  File "D:\ProgramData\Miniconda3\envs\comp8715\lib\site-packages\flask\app.py", line 2446, in wsgi_app
    response = self.full_dispatch_request()
  File "D:\ProgramData\Miniconda3\envs\comp8715\lib\site-packages\flask\app.py", line 1951, in full_dispatch_request
    rv = self.handle_user_exception(e)
  File "D:\ProgramData\Miniconda3\envs\comp8715\lib\site-packages\flask_cors\extension.py", line 161, in wrapped_function
    return cors_after_request(app.make_response(f(*args, **kwargs)))
  File "D:\ProgramData\Miniconda3\envs\comp8715\lib\site-packages\flask\app.py", line 1820, in handle_user_exception
    reraise(exc_type, exc_value, tb)
  File "D:\ProgramData\Miniconda3\envs\comp8715\lib\site-packages\flask\_compat.py", line 39, in reraise
    raise value
  File "D:\ProgramData\Miniconda3\envs\comp8715\lib\site-packages\flask\app.py", line 1949, in full_dispatch_request
    rv = self.dispatch_request()
  File "D:\ProgramData\Miniconda3\envs\comp8715\lib\site-packages\flask\app.py", line 1935, in dispatch_request
    return self.view_functions[rule.endpoint](**req.view_args)
  File "D:\TedZhang\Courses\COMP8715\SAT-Track\server\views\view.py", line 139, in search_new_task
    user_input = int(request.args.get('input'))
ValueError: invalid literal for int() with base 10: 'vaguard 1'
[2020-04-19 01:24:04,503][app.py:1891][ERROR][9624] - Exception on /searchSatellite [GET]
Traceback (most recent call last):
  File "D:\ProgramData\Miniconda3\envs\comp8715\lib\site-packages\flask\app.py", line 2446, in wsgi_app
    response = self.full_dispatch_request()
  File "D:\ProgramData\Miniconda3\envs\comp8715\lib\site-packages\flask\app.py", line 1951, in full_dispatch_request
    rv = self.handle_user_exception(e)
  File "D:\ProgramData\Miniconda3\envs\comp8715\lib\site-packages\flask_cors\extension.py", line 161, in wrapped_function
    return cors_after_request(app.make_response(f(*args, **kwargs)))
  File "D:\ProgramData\Miniconda3\envs\comp8715\lib\site-packages\flask\app.py", line 1820, in handle_user_exception
    reraise(exc_type, exc_value, tb)
  File "D:\ProgramData\Miniconda3\envs\comp8715\lib\site-packages\flask\_compat.py", line 39, in reraise
    raise value
  File "D:\ProgramData\Miniconda3\envs\comp8715\lib\site-packages\flask\app.py", line 1949, in full_dispatch_request
    rv = self.dispatch_request()
  File "D:\ProgramData\Miniconda3\envs\comp8715\lib\site-packages\flask\app.py", line 1935, in dispatch_request
    return self.view_functions[rule.endpoint](**req.view_args)
  File "D:\TedZhang\Courses\COMP8715\SAT-Track\server\views\view.py", line 139, in search_new_task
    user_input = int(request.args.get('input'))
ValueError: invalid literal for int() with base 10: 'vaguard 1'
[2020-04-19 01:24:43,877][app.py:1891][ERROR][15900] - Exception on /searchSatellite [GET]
Traceback (most recent call last):
  File "D:\ProgramData\Miniconda3\envs\comp8715\lib\site-packages\flask\app.py", line 2446, in wsgi_app
    response = self.full_dispatch_request()
  File "D:\ProgramData\Miniconda3\envs\comp8715\lib\site-packages\flask\app.py", line 1951, in full_dispatch_request
    rv = self.handle_user_exception(e)
  File "D:\ProgramData\Miniconda3\envs\comp8715\lib\site-packages\flask_cors\extension.py", line 161, in wrapped_function
    return cors_after_request(app.make_response(f(*args, **kwargs)))
  File "D:\ProgramData\Miniconda3\envs\comp8715\lib\site-packages\flask\app.py", line 1820, in handle_user_exception
    reraise(exc_type, exc_value, tb)
  File "D:\ProgramData\Miniconda3\envs\comp8715\lib\site-packages\flask\_compat.py", line 39, in reraise
    raise value
  File "D:\ProgramData\Miniconda3\envs\comp8715\lib\site-packages\flask\app.py", line 1949, in full_dispatch_request
    rv = self.dispatch_request()
  File "D:\ProgramData\Miniconda3\envs\comp8715\lib\site-packages\flask\app.py", line 1935, in dispatch_request
    return self.view_functions[rule.endpoint](**req.view_args)
  File "D:\TedZhang\Courses\COMP8715\SAT-Track\server\views\view.py", line 141, in search_new_task
    status, tasks = controll_search_new_task(user_id, user_input)
  File "D:\TedZhang\Courses\COMP8715\SAT-Track\server\controllers\user_behavior_controller.py", line 69, in controll_search_new_task
    satellite_lst = search_satellites_from_es(user_input)
  File "D:\TedZhang\Courses\COMP8715\SAT-Track\server\services\satellite_search_service.py", line 182, in search_satellites_from_es
    res = satellite_database.search_by_body(search_body)
NameError: name 'satellite_database' is not defined
[2020-04-19 01:42:26,729][app.py:1891][ERROR][12160] - Exception on /index [GET]
Traceback (most recent call last):
  File "D:\ProgramData\Miniconda3\envs\comp8715\lib\site-packages\flask\app.py", line 2446, in wsgi_app
    response = self.full_dispatch_request()
  File "D:\ProgramData\Miniconda3\envs\comp8715\lib\site-packages\flask\app.py", line 1951, in full_dispatch_request
    rv = self.handle_user_exception(e)
  File "D:\ProgramData\Miniconda3\envs\comp8715\lib\site-packages\flask_cors\extension.py", line 161, in wrapped_function
    return cors_after_request(app.make_response(f(*args, **kwargs)))
  File "D:\ProgramData\Miniconda3\envs\comp8715\lib\site-packages\flask\app.py", line 1820, in handle_user_exception
    reraise(exc_type, exc_value, tb)
  File "D:\ProgramData\Miniconda3\envs\comp8715\lib\site-packages\flask\_compat.py", line 39, in reraise
    raise value
  File "D:\ProgramData\Miniconda3\envs\comp8715\lib\site-packages\flask\app.py", line 1949, in full_dispatch_request
    rv = self.dispatch_request()
  File "D:\ProgramData\Miniconda3\envs\comp8715\lib\site-packages\flask\app.py", line 1935, in dispatch_request
    return self.view_functions[rule.endpoint](**req.view_args)
  File "D:\ProgramData\Miniconda3\envs\comp8715\lib\site-packages\flask_login\utils.py", line 272, in decorated_view
    return func(*args, **kwargs)
  File "D:\TedZhang\Courses\COMP8715\SAT-Track\server\views\view.py", line 12, in index
    from utilities.simulate_for_dev import Simulation
ImportError: cannot import name 'Simulation' from 'utilities.simulate_for_dev' (D:\TedZhang\Courses\COMP8715\SAT-Track\utilities\simulate_for_dev.py)
[2020-04-19 01:52:22,462][app.py:1891][ERROR][2388] - Exception on /searchSatellite [GET]
Traceback (most recent call last):
  File "D:\ProgramData\Miniconda3\envs\comp8715\lib\site-packages\flask\app.py", line 2446, in wsgi_app
    response = self.full_dispatch_request()
  File "D:\ProgramData\Miniconda3\envs\comp8715\lib\site-packages\flask\app.py", line 1951, in full_dispatch_request
    rv = self.handle_user_exception(e)
  File "D:\ProgramData\Miniconda3\envs\comp8715\lib\site-packages\flask_cors\extension.py", line 161, in wrapped_function
    return cors_after_request(app.make_response(f(*args, **kwargs)))
  File "D:\ProgramData\Miniconda3\envs\comp8715\lib\site-packages\flask\app.py", line 1820, in handle_user_exception
    reraise(exc_type, exc_value, tb)
  File "D:\ProgramData\Miniconda3\envs\comp8715\lib\site-packages\flask\_compat.py", line 39, in reraise
    raise value
  File "D:\ProgramData\Miniconda3\envs\comp8715\lib\site-packages\flask\app.py", line 1949, in full_dispatch_request
    rv = self.dispatch_request()
  File "D:\ProgramData\Miniconda3\envs\comp8715\lib\site-packages\flask\app.py", line 1935, in dispatch_request
    return self.view_functions[rule.endpoint](**req.view_args)
  File "D:\TedZhang\Courses\COMP8715\SAT-Track\server\views\view.py", line 137, in search_satellite
    status, tasks = controll_search_new_task(user_id, user_input)
  File "D:\TedZhang\Courses\COMP8715\SAT-Track\server\controllers\user_behavior_controller.py", line 78, in controll_search_new_task
    status_, res = SatelliteManager.to_satellites(satellite_lst)
  File "D:\TedZhang\Courses\COMP8715\SAT-Track\server\services\data_storage_service.py", line 140, in to_satellites
    print(len(lst), lst(satellites))
TypeError: 'list' object is not callable
[2020-04-19 02:07:50,794][app.py:1891][ERROR][5336] - Exception on /searchSatellite [GET]
Traceback (most recent call last):
  File "D:\ProgramData\Miniconda3\envs\comp8715\lib\site-packages\flask\app.py", line 2446, in wsgi_app
    response = self.full_dispatch_request()
  File "D:\ProgramData\Miniconda3\envs\comp8715\lib\site-packages\flask\app.py", line 1951, in full_dispatch_request
    rv = self.handle_user_exception(e)
  File "D:\ProgramData\Miniconda3\envs\comp8715\lib\site-packages\flask_cors\extension.py", line 161, in wrapped_function
    return cors_after_request(app.make_response(f(*args, **kwargs)))
  File "D:\ProgramData\Miniconda3\envs\comp8715\lib\site-packages\flask\app.py", line 1820, in handle_user_exception
    reraise(exc_type, exc_value, tb)
  File "D:\ProgramData\Miniconda3\envs\comp8715\lib\site-packages\flask\_compat.py", line 39, in reraise
    raise value
  File "D:\ProgramData\Miniconda3\envs\comp8715\lib\site-packages\flask\app.py", line 1949, in full_dispatch_request
    rv = self.dispatch_request()
  File "D:\ProgramData\Miniconda3\envs\comp8715\lib\site-packages\flask\app.py", line 1935, in dispatch_request
    return self.view_functions[rule.endpoint](**req.view_args)
  File "D:\TedZhang\Courses\COMP8715\SAT-Track\server\views\view.py", line 137, in search_satellite
    status, tasks = controll_search_new_task(user_id, user_input)
  File "D:\TedZhang\Courses\COMP8715\SAT-Track\server\controllers\user_behavior_controller.py", line 69, in controll_search_new_task
    satellite_lst = search_satellites_from_es(user_input)
  File "D:\TedZhang\Courses\COMP8715\SAT-Track\server\services\satellite_search_service.py", line 188, in search_satellites_from_es
    search_body = turn_to_query_body(classes, user_input)
  File "D:\TedZhang\Courses\COMP8715\SAT-Track\server\services\satellite_search_service.py", line 162, in turn_to_query_body
    extract_input = extract_input.lstrip().rstrip()
AttributeError: 'list' object has no attribute 'lstrip'
[2020-04-19 03:40:52,179][app.py:1891][ERROR][2568] - Exception on /searchSatellite [GET]
Traceback (most recent call last):
  File "D:\ProgramData\Miniconda3\envs\comp8715\lib\site-packages\flask\app.py", line 2446, in wsgi_app
    response = self.full_dispatch_request()
  File "D:\ProgramData\Miniconda3\envs\comp8715\lib\site-packages\flask\app.py", line 1951, in full_dispatch_request
    rv = self.handle_user_exception(e)
  File "D:\ProgramData\Miniconda3\envs\comp8715\lib\site-packages\flask_cors\extension.py", line 161, in wrapped_function
    return cors_after_request(app.make_response(f(*args, **kwargs)))
  File "D:\ProgramData\Miniconda3\envs\comp8715\lib\site-packages\flask\app.py", line 1820, in handle_user_exception
    reraise(exc_type, exc_value, tb)
  File "D:\ProgramData\Miniconda3\envs\comp8715\lib\site-packages\flask\_compat.py", line 39, in reraise
    raise value
  File "D:\ProgramData\Miniconda3\envs\comp8715\lib\site-packages\flask\app.py", line 1949, in full_dispatch_request
    rv = self.dispatch_request()
  File "D:\ProgramData\Miniconda3\envs\comp8715\lib\site-packages\flask\app.py", line 1935, in dispatch_request
    return self.view_functions[rule.endpoint](**req.view_args)
  File "D:\TedZhang\Courses\COMP8715\SAT-Track\server\views\view.py", line 137, in search_satellite
    status, satellites = controll_search_satellites(user_id, user_input)
  File "D:\TedZhang\Courses\COMP8715\SAT-Track\server\controllers\user_behavior_controller.py", line 85, in controll_search_satellites
    print('error in controll_search_satellites: errors(' + str(len(errors)) + ') =', errors)
TypeError: object of type 'NoneType' has no len()
[2020-04-19 03:52:31,531][app.py:1891][ERROR][14156] - Exception on /selectSatellite [GET]
Traceback (most recent call last):
  File "D:\ProgramData\Miniconda3\envs\comp8715\lib\site-packages\flask\app.py", line 2446, in wsgi_app
    response = self.full_dispatch_request()
  File "D:\ProgramData\Miniconda3\envs\comp8715\lib\site-packages\flask\app.py", line 1951, in full_dispatch_request
    rv = self.handle_user_exception(e)
  File "D:\ProgramData\Miniconda3\envs\comp8715\lib\site-packages\flask_cors\extension.py", line 161, in wrapped_function
    return cors_after_request(app.make_response(f(*args, **kwargs)))
  File "D:\ProgramData\Miniconda3\envs\comp8715\lib\site-packages\flask\app.py", line 1820, in handle_user_exception
    reraise(exc_type, exc_value, tb)
  File "D:\ProgramData\Miniconda3\envs\comp8715\lib\site-packages\flask\_compat.py", line 39, in reraise
    raise value
  File "D:\ProgramData\Miniconda3\envs\comp8715\lib\site-packages\flask\app.py", line 1949, in full_dispatch_request
    rv = self.dispatch_request()
  File "D:\ProgramData\Miniconda3\envs\comp8715\lib\site-packages\flask\app.py", line 1935, in dispatch_request
    return self.view_functions[rule.endpoint](**req.view_args)
  File "D:\TedZhang\Courses\COMP8715\SAT-Track\server\views\view.py", line 159, in select_satellite
    status, satellites = controll_select_satellite(user_id, satellite_id)
  File "D:\TedZhang\Courses\COMP8715\SAT-Track\server\controllers\user_behavior_controller.py", line 94, in controll_select_satellite
    status, tasks = PriorityManager.insert(user.priority, satellite)
  File "D:\TedZhang\Courses\COMP8715\SAT-Track\server\services\data_storage_service.py", line 107, in insert
    satellite_id = satellite.norad_id
AttributeError: 'tuple' object has no attribute 'norad_id'
[2020-04-19 03:53:42,098][app.py:1891][ERROR][13000] - Exception on /selectSatellite [GET]
Traceback (most recent call last):
  File "D:\ProgramData\Miniconda3\envs\comp8715\lib\site-packages\flask\app.py", line 2446, in wsgi_app
    response = self.full_dispatch_request()
  File "D:\ProgramData\Miniconda3\envs\comp8715\lib\site-packages\flask\app.py", line 1951, in full_dispatch_request
    rv = self.handle_user_exception(e)
  File "D:\ProgramData\Miniconda3\envs\comp8715\lib\site-packages\flask_cors\extension.py", line 161, in wrapped_function
    return cors_after_request(app.make_response(f(*args, **kwargs)))
  File "D:\ProgramData\Miniconda3\envs\comp8715\lib\site-packages\flask\app.py", line 1820, in handle_user_exception
    reraise(exc_type, exc_value, tb)
  File "D:\ProgramData\Miniconda3\envs\comp8715\lib\site-packages\flask\_compat.py", line 39, in reraise
    raise value
  File "D:\ProgramData\Miniconda3\envs\comp8715\lib\site-packages\flask\app.py", line 1949, in full_dispatch_request
    rv = self.dispatch_request()
  File "D:\ProgramData\Miniconda3\envs\comp8715\lib\site-packages\flask\app.py", line 1935, in dispatch_request
    return self.view_functions[rule.endpoint](**req.view_args)
  File "D:\TedZhang\Courses\COMP8715\SAT-Track\server\views\view.py", line 159, in select_satellite
    status, satellites = controll_select_satellite(user_id, satellite_id)
  File "D:\TedZhang\Courses\COMP8715\SAT-Track\server\controllers\user_behavior_controller.py", line 94, in controll_select_satellite
    print(dict(satellite))
TypeError: cannot convert dictionary update sequence element #0 to a sequence
[2020-04-19 03:54:15,042][app.py:1891][ERROR][5248] - Exception on /selectSatellite [GET]
Traceback (most recent call last):
  File "D:\ProgramData\Miniconda3\envs\comp8715\lib\site-packages\flask\app.py", line 2446, in wsgi_app
    response = self.full_dispatch_request()
  File "D:\ProgramData\Miniconda3\envs\comp8715\lib\site-packages\flask\app.py", line 1951, in full_dispatch_request
    rv = self.handle_user_exception(e)
  File "D:\ProgramData\Miniconda3\envs\comp8715\lib\site-packages\flask_cors\extension.py", line 161, in wrapped_function
    return cors_after_request(app.make_response(f(*args, **kwargs)))
  File "D:\ProgramData\Miniconda3\envs\comp8715\lib\site-packages\flask\app.py", line 1820, in handle_user_exception
    reraise(exc_type, exc_value, tb)
  File "D:\ProgramData\Miniconda3\envs\comp8715\lib\site-packages\flask\_compat.py", line 39, in reraise
    raise value
  File "D:\ProgramData\Miniconda3\envs\comp8715\lib\site-packages\flask\app.py", line 1949, in full_dispatch_request
    rv = self.dispatch_request()
  File "D:\ProgramData\Miniconda3\envs\comp8715\lib\site-packages\flask\app.py", line 1935, in dispatch_request
    return self.view_functions[rule.endpoint](**req.view_args)
  File "D:\TedZhang\Courses\COMP8715\SAT-Track\server\views\view.py", line 159, in select_satellite
    status, satellites = controll_select_satellite(user_id, satellite_id)
  File "D:\TedZhang\Courses\COMP8715\SAT-Track\server\controllers\user_behavior_controller.py", line 94, in controll_select_satellite
    print(dict(satellite))
TypeError: cannot convert dictionary update sequence element #0 to a sequence
[2020-04-19 03:55:03,506][app.py:1891][ERROR][2204] - Exception on /selectSatellite [GET]
Traceback (most recent call last):
  File "D:\ProgramData\Miniconda3\envs\comp8715\lib\site-packages\flask\app.py", line 2446, in wsgi_app
    response = self.full_dispatch_request()
  File "D:\ProgramData\Miniconda3\envs\comp8715\lib\site-packages\flask\app.py", line 1951, in full_dispatch_request
    rv = self.handle_user_exception(e)
  File "D:\ProgramData\Miniconda3\envs\comp8715\lib\site-packages\flask_cors\extension.py", line 161, in wrapped_function
    return cors_after_request(app.make_response(f(*args, **kwargs)))
  File "D:\ProgramData\Miniconda3\envs\comp8715\lib\site-packages\flask\app.py", line 1820, in handle_user_exception
    reraise(exc_type, exc_value, tb)
  File "D:\ProgramData\Miniconda3\envs\comp8715\lib\site-packages\flask\_compat.py", line 39, in reraise
    raise value
  File "D:\ProgramData\Miniconda3\envs\comp8715\lib\site-packages\flask\app.py", line 1949, in full_dispatch_request
    rv = self.dispatch_request()
  File "D:\ProgramData\Miniconda3\envs\comp8715\lib\site-packages\flask\app.py", line 1935, in dispatch_request
    return self.view_functions[rule.endpoint](**req.view_args)
  File "D:\TedZhang\Courses\COMP8715\SAT-Track\server\views\view.py", line 159, in select_satellite
    status, satellites = controll_select_satellite(user_id, satellite_id)
  File "D:\TedZhang\Courses\COMP8715\SAT-Track\server\controllers\user_behavior_controller.py", line 94, in controll_select_satellite
    print(dict(satellite))
TypeError: cannot convert dictionary update sequence element #0 to a sequence
[2020-04-19 03:55:34,522][app.py:1891][ERROR][12344] - Exception on /selectSatellite [GET]
Traceback (most recent call last):
  File "D:\ProgramData\Miniconda3\envs\comp8715\lib\site-packages\flask\app.py", line 2446, in wsgi_app
    response = self.full_dispatch_request()
  File "D:\ProgramData\Miniconda3\envs\comp8715\lib\site-packages\flask\app.py", line 1951, in full_dispatch_request
    rv = self.handle_user_exception(e)
  File "D:\ProgramData\Miniconda3\envs\comp8715\lib\site-packages\flask_cors\extension.py", line 161, in wrapped_function
    return cors_after_request(app.make_response(f(*args, **kwargs)))
  File "D:\ProgramData\Miniconda3\envs\comp8715\lib\site-packages\flask\app.py", line 1820, in handle_user_exception
    reraise(exc_type, exc_value, tb)
  File "D:\ProgramData\Miniconda3\envs\comp8715\lib\site-packages\flask\_compat.py", line 39, in reraise
    raise value
  File "D:\ProgramData\Miniconda3\envs\comp8715\lib\site-packages\flask\app.py", line 1949, in full_dispatch_request
    rv = self.dispatch_request()
  File "D:\ProgramData\Miniconda3\envs\comp8715\lib\site-packages\flask\app.py", line 1935, in dispatch_request
    return self.view_functions[rule.endpoint](**req.view_args)
  File "D:\TedZhang\Courses\COMP8715\SAT-Track\server\views\view.py", line 159, in select_satellite
    status, satellites = controll_select_satellite(user_id, satellite_id)
  File "D:\TedZhang\Courses\COMP8715\SAT-Track\server\controllers\user_behavior_controller.py", line 94, in controll_select_satellite
    print(dict(satellite))
TypeError: cannot convert dictionary update sequence element #0 to a sequence
[2020-04-19 03:57:07,894][app.py:1891][ERROR][5792] - Exception on /selectSatellite [GET]
Traceback (most recent call last):
  File "D:\ProgramData\Miniconda3\envs\comp8715\lib\site-packages\flask\app.py", line 2446, in wsgi_app
    response = self.full_dispatch_request()
  File "D:\ProgramData\Miniconda3\envs\comp8715\lib\site-packages\flask\app.py", line 1951, in full_dispatch_request
    rv = self.handle_user_exception(e)
  File "D:\ProgramData\Miniconda3\envs\comp8715\lib\site-packages\flask_cors\extension.py", line 161, in wrapped_function
    return cors_after_request(app.make_response(f(*args, **kwargs)))
  File "D:\ProgramData\Miniconda3\envs\comp8715\lib\site-packages\flask\app.py", line 1820, in handle_user_exception
    reraise(exc_type, exc_value, tb)
  File "D:\ProgramData\Miniconda3\envs\comp8715\lib\site-packages\flask\_compat.py", line 39, in reraise
    raise value
  File "D:\ProgramData\Miniconda3\envs\comp8715\lib\site-packages\flask\app.py", line 1949, in full_dispatch_request
    rv = self.dispatch_request()
  File "D:\ProgramData\Miniconda3\envs\comp8715\lib\site-packages\flask\app.py", line 1935, in dispatch_request
    return self.view_functions[rule.endpoint](**req.view_args)
  File "D:\TedZhang\Courses\COMP8715\SAT-Track\server\views\view.py", line 159, in select_satellite
    status, satellites = controll_select_satellite(user_id, satellite_id)
  File "D:\TedZhang\Courses\COMP8715\SAT-Track\server\controllers\user_behavior_controller.py", line 95, in controll_select_satellite
    status, tasks = PriorityManager.insert(user.priority, satellite)
  File "D:\TedZhang\Courses\COMP8715\SAT-Track\server\services\data_storage_service.py", line 107, in insert
    satellite_id = satellite.norad_id
AttributeError: 'tuple' object has no attribute 'norad_id'
[2020-04-21 17:34:32,484][app.py:1891][ERROR][14032] - Exception on /searchSatellite [GET]
Traceback (most recent call last):
  File "D:\ProgramData\Miniconda3\envs\comp8715\lib\site-packages\flask\app.py", line 2446, in wsgi_app
    response = self.full_dispatch_request()
  File "D:\ProgramData\Miniconda3\envs\comp8715\lib\site-packages\flask\app.py", line 1951, in full_dispatch_request
    rv = self.handle_user_exception(e)
  File "D:\ProgramData\Miniconda3\envs\comp8715\lib\site-packages\flask_cors\extension.py", line 161, in wrapped_function
    return cors_after_request(app.make_response(f(*args, **kwargs)))
  File "D:\ProgramData\Miniconda3\envs\comp8715\lib\site-packages\flask\app.py", line 1820, in handle_user_exception
    reraise(exc_type, exc_value, tb)
  File "D:\ProgramData\Miniconda3\envs\comp8715\lib\site-packages\flask\_compat.py", line 39, in reraise
    raise value
  File "D:\ProgramData\Miniconda3\envs\comp8715\lib\site-packages\flask\app.py", line 1949, in full_dispatch_request
    rv = self.dispatch_request()
  File "D:\ProgramData\Miniconda3\envs\comp8715\lib\site-packages\flask\app.py", line 1935, in dispatch_request
    return self.view_functions[rule.endpoint](**req.view_args)
  File "D:\TedZhang\Courses\COMP8715\SAT-Track\server\views\view.py", line 138, in search_satellite
    status, satellites = controll_search_satellites(user_id, user_input)
  File "D:\TedZhang\Courses\COMP8715\SAT-Track\server\controllers\user_behavior_controller.py", line 69, in controll_search_satellites
    satellite_lst = search_satellites_from_es(user_input)
  File "D:\TedZhang\Courses\COMP8715\SAT-Track\server\services\satellite_search_service.py", line 188, in search_satellites_from_es
    search_body = turn_to_query_body(classes, user_input)
  File "D:\TedZhang\Courses\COMP8715\SAT-Track\server\services\satellite_search_service.py", line 138, in turn_to_query_body
    must.append({'match': {'launch_unixtime': to_date(classes)[1]}})
  File "D:\TedZhang\Courses\COMP8715\SAT-Track\server\services\satellite_search_service.py", line 123, in to_date
    return ripe_date, Utils.to_all_unixtime(ripe_date)
  File "D:\TedZhang\Courses\COMP8715\SAT-Track\utilities\utils.py", line 32, in to_all_unixtime
    date = datetime.datetime.strptime(date + ' 00:00:00', '%Y-%m-%d %H:%M:%S')
  File "D:\ProgramData\Miniconda3\envs\comp8715\lib\_strptime.py", line 577, in _strptime_datetime
    tt, fraction, gmtoff_fraction = _strptime(data_string, format)
  File "D:\ProgramData\Miniconda3\envs\comp8715\lib\_strptime.py", line 359, in _strptime
    (data_string, format))
ValueError: time data '1983-07- 00:00:00' does not match format '%Y-%m-%d %H:%M:%S'
[2020-04-21 17:44:31,169][app.py:1891][ERROR][2000] - Exception on /searchSatellite [GET]
Traceback (most recent call last):
  File "D:\ProgramData\Miniconda3\envs\comp8715\lib\site-packages\flask\app.py", line 2446, in wsgi_app
    response = self.full_dispatch_request()
  File "D:\ProgramData\Miniconda3\envs\comp8715\lib\site-packages\flask\app.py", line 1951, in full_dispatch_request
    rv = self.handle_user_exception(e)
  File "D:\ProgramData\Miniconda3\envs\comp8715\lib\site-packages\flask_cors\extension.py", line 161, in wrapped_function
    return cors_after_request(app.make_response(f(*args, **kwargs)))
  File "D:\ProgramData\Miniconda3\envs\comp8715\lib\site-packages\flask\app.py", line 1820, in handle_user_exception
    reraise(exc_type, exc_value, tb)
  File "D:\ProgramData\Miniconda3\envs\comp8715\lib\site-packages\flask\_compat.py", line 39, in reraise
    raise value
  File "D:\ProgramData\Miniconda3\envs\comp8715\lib\site-packages\flask\app.py", line 1949, in full_dispatch_request
    rv = self.dispatch_request()
  File "D:\ProgramData\Miniconda3\envs\comp8715\lib\site-packages\flask\app.py", line 1935, in dispatch_request
    return self.view_functions[rule.endpoint](**req.view_args)
  File "D:\TedZhang\Courses\COMP8715\SAT-Track\server\views\view.py", line 138, in search_satellite
    status, satellites = controll_search_satellites(user_id, user_input)
  File "D:\TedZhang\Courses\COMP8715\SAT-Track\server\controllers\user_behavior_controller.py", line 69, in controll_search_satellites
    satellite_lst = search_satellites_from_es(user_input)
  File "D:\TedZhang\Courses\COMP8715\SAT-Track\server\services\satellite_search_service.py", line 188, in search_satellites_from_es
    search_body = turn_to_query_body(classes, user_input)
  File "D:\TedZhang\Courses\COMP8715\SAT-Track\server\services\satellite_search_service.py", line 138, in turn_to_query_body
    must.append({'match': {'launch_unixtime': to_date(classes)[1]}})
  File "D:\TedZhang\Courses\COMP8715\SAT-Track\server\services\satellite_search_service.py", line 123, in to_date
    return ripe_date, Utils.to_all_unixtime(ripe_date)
  File "D:\TedZhang\Courses\COMP8715\SAT-Track\utilities\utils.py", line 32, in to_all_unixtime
    date = datetime.datetime.strptime(date + ' 00:00:00', '%Y-%m-%d %H:%M:%S')
  File "D:\ProgramData\Miniconda3\envs\comp8715\lib\_strptime.py", line 577, in _strptime_datetime
    tt, fraction, gmtoff_fraction = _strptime(data_string, format)
  File "D:\ProgramData\Miniconda3\envs\comp8715\lib\_strptime.py", line 359, in _strptime
    (data_string, format))
ValueError: time data '2008-01- 00:00:00' does not match format '%Y-%m-%d %H:%M:%S'
[2020-04-21 17:44:45,856][app.py:1891][ERROR][7336] - Exception on /searchSatellite [GET]
Traceback (most recent call last):
  File "D:\ProgramData\Miniconda3\envs\comp8715\lib\site-packages\flask\app.py", line 2446, in wsgi_app
    response = self.full_dispatch_request()
  File "D:\ProgramData\Miniconda3\envs\comp8715\lib\site-packages\flask\app.py", line 1951, in full_dispatch_request
    rv = self.handle_user_exception(e)
  File "D:\ProgramData\Miniconda3\envs\comp8715\lib\site-packages\flask_cors\extension.py", line 161, in wrapped_function
    return cors_after_request(app.make_response(f(*args, **kwargs)))
  File "D:\ProgramData\Miniconda3\envs\comp8715\lib\site-packages\flask\app.py", line 1820, in handle_user_exception
    reraise(exc_type, exc_value, tb)
  File "D:\ProgramData\Miniconda3\envs\comp8715\lib\site-packages\flask\_compat.py", line 39, in reraise
    raise value
  File "D:\ProgramData\Miniconda3\envs\comp8715\lib\site-packages\flask\app.py", line 1949, in full_dispatch_request
    rv = self.dispatch_request()
  File "D:\ProgramData\Miniconda3\envs\comp8715\lib\site-packages\flask\app.py", line 1935, in dispatch_request
    return self.view_functions[rule.endpoint](**req.view_args)
  File "D:\TedZhang\Courses\COMP8715\SAT-Track\server\views\view.py", line 138, in search_satellite
    status, satellites = controll_search_satellites(user_id, user_input)
  File "D:\TedZhang\Courses\COMP8715\SAT-Track\server\controllers\user_behavior_controller.py", line 69, in controll_search_satellites
    satellite_lst = search_satellites_from_es(user_input)
  File "D:\TedZhang\Courses\COMP8715\SAT-Track\server\services\satellite_search_service.py", line 188, in search_satellites_from_es
    search_body = turn_to_query_body(classes, user_input)
  File "D:\TedZhang\Courses\COMP8715\SAT-Track\server\services\satellite_search_service.py", line 138, in turn_to_query_body
    must.append({'match': {'launch_unixtime': to_date(classes)[1]}})
  File "D:\TedZhang\Courses\COMP8715\SAT-Track\server\services\satellite_search_service.py", line 123, in to_date
    return ripe_date, Utils.to_all_unixtime(ripe_date)
  File "D:\TedZhang\Courses\COMP8715\SAT-Track\utilities\utils.py", line 32, in to_all_unixtime
    date = datetime.datetime.strptime(date + ' 00:00:00', '%Y-%m-%d %H:%M:%S')
  File "D:\ProgramData\Miniconda3\envs\comp8715\lib\_strptime.py", line 577, in _strptime_datetime
    tt, fraction, gmtoff_fraction = _strptime(data_string, format)
  File "D:\ProgramData\Miniconda3\envs\comp8715\lib\_strptime.py", line 359, in _strptime
    (data_string, format))
ValueError: time data '2010-06- 00:00:00' does not match format '%Y-%m-%d %H:%M:%S'
[2020-04-21 18:30:24,024][app.py:1891][ERROR][7852] - Exception on /searchSatellite [GET]
Traceback (most recent call last):
  File "D:\ProgramData\Miniconda3\envs\comp8715\lib\site-packages\flask\app.py", line 2446, in wsgi_app
    response = self.full_dispatch_request()
  File "D:\ProgramData\Miniconda3\envs\comp8715\lib\site-packages\flask\app.py", line 1951, in full_dispatch_request
    rv = self.handle_user_exception(e)
  File "D:\ProgramData\Miniconda3\envs\comp8715\lib\site-packages\flask_cors\extension.py", line 161, in wrapped_function
    return cors_after_request(app.make_response(f(*args, **kwargs)))
  File "D:\ProgramData\Miniconda3\envs\comp8715\lib\site-packages\flask\app.py", line 1820, in handle_user_exception
    reraise(exc_type, exc_value, tb)
  File "D:\ProgramData\Miniconda3\envs\comp8715\lib\site-packages\flask\_compat.py", line 39, in reraise
    raise value
  File "D:\ProgramData\Miniconda3\envs\comp8715\lib\site-packages\flask\app.py", line 1949, in full_dispatch_request
    rv = self.dispatch_request()
  File "D:\ProgramData\Miniconda3\envs\comp8715\lib\site-packages\flask\app.py", line 1935, in dispatch_request
    return self.view_functions[rule.endpoint](**req.view_args)
  File "D:\TedZhang\Courses\COMP8715\SAT-Track\server\views\view.py", line 138, in search_satellite
    status, satellites = controll_search_satellites(user_id, user_input)
  File "D:\TedZhang\Courses\COMP8715\SAT-Track\server\controllers\user_behavior_controller.py", line 69, in controll_search_satellites
    satellite_lst = search_satellites_from_es(user_input)
  File "D:\TedZhang\Courses\COMP8715\SAT-Track\server\services\satellite_search_service.py", line 188, in search_satellites_from_es
    search_body = turn_to_query_body(classes, user_input)
  File "D:\TedZhang\Courses\COMP8715\SAT-Track\server\services\satellite_search_service.py", line 138, in turn_to_query_body
    must.append({'match': {'launch_unixtime': to_date(classes)[1]}})
  File "D:\TedZhang\Courses\COMP8715\SAT-Track\server\services\satellite_search_service.py", line 123, in to_date
    return ripe_date, Utils.to_all_unixtime(ripe_date)
  File "D:\TedZhang\Courses\COMP8715\SAT-Track\utilities\utils.py", line 32, in to_all_unixtime
    date = datetime.datetime.strptime(date + ' 00:00:00', '%Y-%m-%d %H:%M:%S')
  File "D:\ProgramData\Miniconda3\envs\comp8715\lib\_strptime.py", line 577, in _strptime_datetime
    tt, fraction, gmtoff_fraction = _strptime(data_string, format)
  File "D:\ProgramData\Miniconda3\envs\comp8715\lib\_strptime.py", line 359, in _strptime
    (data_string, format))
ValueError: time data '1998-11- 00:00:00' does not match format '%Y-%m-%d %H:%M:%S'
[2020-04-21 18:33:26,985][app.py:1891][ERROR][7564] - Exception on /searchSatellite [GET]
Traceback (most recent call last):
  File "D:\ProgramData\Miniconda3\envs\comp8715\lib\site-packages\flask\app.py", line 2446, in wsgi_app
    response = self.full_dispatch_request()
  File "D:\ProgramData\Miniconda3\envs\comp8715\lib\site-packages\flask\app.py", line 1951, in full_dispatch_request
    rv = self.handle_user_exception(e)
  File "D:\ProgramData\Miniconda3\envs\comp8715\lib\site-packages\flask_cors\extension.py", line 161, in wrapped_function
    return cors_after_request(app.make_response(f(*args, **kwargs)))
  File "D:\ProgramData\Miniconda3\envs\comp8715\lib\site-packages\flask\app.py", line 1820, in handle_user_exception
    reraise(exc_type, exc_value, tb)
  File "D:\ProgramData\Miniconda3\envs\comp8715\lib\site-packages\flask\_compat.py", line 39, in reraise
    raise value
  File "D:\ProgramData\Miniconda3\envs\comp8715\lib\site-packages\flask\app.py", line 1949, in full_dispatch_request
    rv = self.dispatch_request()
  File "D:\ProgramData\Miniconda3\envs\comp8715\lib\site-packages\flask\app.py", line 1935, in dispatch_request
    return self.view_functions[rule.endpoint](**req.view_args)
  File "D:\TedZhang\Courses\COMP8715\SAT-Track\server\views\view.py", line 138, in search_satellite
    status, satellites = controll_search_satellites(user_id, user_input)
  File "D:\TedZhang\Courses\COMP8715\SAT-Track\server\controllers\user_behavior_controller.py", line 69, in controll_search_satellites
    satellite_lst = search_satellites_from_es(user_input)
  File "D:\TedZhang\Courses\COMP8715\SAT-Track\server\services\satellite_search_service.py", line 188, in search_satellites_from_es
    search_body = turn_to_query_body(classes, user_input)
  File "D:\TedZhang\Courses\COMP8715\SAT-Track\server\services\satellite_search_service.py", line 138, in turn_to_query_body
    must.append({'match': {'launch_unixtime': to_date(classes)[1]}})
  File "D:\TedZhang\Courses\COMP8715\SAT-Track\server\services\satellite_search_service.py", line 123, in to_date
    return ripe_date, Utils.to_all_unixtime(ripe_date)
  File "D:\TedZhang\Courses\COMP8715\SAT-Track\utilities\utils.py", line 32, in to_all_unixtime
    date = datetime.datetime.strptime(date + ' 00:00:00', '%Y-%m-%d %H:%M:%S')
  File "D:\ProgramData\Miniconda3\envs\comp8715\lib\_strptime.py", line 577, in _strptime_datetime
    tt, fraction, gmtoff_fraction = _strptime(data_string, format)
  File "D:\ProgramData\Miniconda3\envs\comp8715\lib\_strptime.py", line 359, in _strptime
    (data_string, format))
ValueError: time data '1998-11- 00:00:00' does not match format '%Y-%m-%d %H:%M:%S'
[2020-04-21 18:34:59,496][app.py:1891][ERROR][8420] - Exception on /searchSatellite [GET]
Traceback (most recent call last):
  File "D:\ProgramData\Miniconda3\envs\comp8715\lib\site-packages\flask\app.py", line 2446, in wsgi_app
    response = self.full_dispatch_request()
  File "D:\ProgramData\Miniconda3\envs\comp8715\lib\site-packages\flask\app.py", line 1951, in full_dispatch_request
    rv = self.handle_user_exception(e)
  File "D:\ProgramData\Miniconda3\envs\comp8715\lib\site-packages\flask_cors\extension.py", line 161, in wrapped_function
    return cors_after_request(app.make_response(f(*args, **kwargs)))
  File "D:\ProgramData\Miniconda3\envs\comp8715\lib\site-packages\flask\app.py", line 1820, in handle_user_exception
    reraise(exc_type, exc_value, tb)
  File "D:\ProgramData\Miniconda3\envs\comp8715\lib\site-packages\flask\_compat.py", line 39, in reraise
    raise value
  File "D:\ProgramData\Miniconda3\envs\comp8715\lib\site-packages\flask\app.py", line 1949, in full_dispatch_request
    rv = self.dispatch_request()
  File "D:\ProgramData\Miniconda3\envs\comp8715\lib\site-packages\flask\app.py", line 1935, in dispatch_request
    return self.view_functions[rule.endpoint](**req.view_args)
  File "D:\TedZhang\Courses\COMP8715\SAT-Track\server\views\view.py", line 138, in search_satellite
    status, satellites = controll_search_satellites(user_id, user_input)
  File "D:\TedZhang\Courses\COMP8715\SAT-Track\server\controllers\user_behavior_controller.py", line 69, in controll_search_satellites
    satellite_lst = search_satellites_from_es(user_input)
  File "D:\TedZhang\Courses\COMP8715\SAT-Track\server\services\satellite_search_service.py", line 189, in search_satellites_from_es
    search_body = turn_to_query_body(classes, user_input)
  File "D:\TedZhang\Courses\COMP8715\SAT-Track\server\services\satellite_search_service.py", line 139, in turn_to_query_body
    must.append({'match': {'launch_unixtime': to_date(classes)[1]}})
  File "D:\TedZhang\Courses\COMP8715\SAT-Track\server\services\satellite_search_service.py", line 124, in to_date
    return ripe_date, Utils.to_all_unixtime(ripe_date)
  File "D:\TedZhang\Courses\COMP8715\SAT-Track\utilities\utils.py", line 32, in to_all_unixtime
    date = datetime.datetime.strptime(date + ' 00:00:00', '%Y-%m-%d %H:%M:%S')
  File "D:\ProgramData\Miniconda3\envs\comp8715\lib\_strptime.py", line 577, in _strptime_datetime
    tt, fraction, gmtoff_fraction = _strptime(data_string, format)
  File "D:\ProgramData\Miniconda3\envs\comp8715\lib\_strptime.py", line 359, in _strptime
    (data_string, format))
ValueError: time data '1998-11- 00:00:00' does not match format '%Y-%m-%d %H:%M:%S'
[2020-04-21 18:35:28,796][app.py:1891][ERROR][14048] - Exception on /searchSatellite [GET]
Traceback (most recent call last):
  File "D:\ProgramData\Miniconda3\envs\comp8715\lib\site-packages\flask\app.py", line 2446, in wsgi_app
    response = self.full_dispatch_request()
  File "D:\ProgramData\Miniconda3\envs\comp8715\lib\site-packages\flask\app.py", line 1951, in full_dispatch_request
    rv = self.handle_user_exception(e)
  File "D:\ProgramData\Miniconda3\envs\comp8715\lib\site-packages\flask_cors\extension.py", line 161, in wrapped_function
    return cors_after_request(app.make_response(f(*args, **kwargs)))
  File "D:\ProgramData\Miniconda3\envs\comp8715\lib\site-packages\flask\app.py", line 1820, in handle_user_exception
    reraise(exc_type, exc_value, tb)
  File "D:\ProgramData\Miniconda3\envs\comp8715\lib\site-packages\flask\_compat.py", line 39, in reraise
    raise value
  File "D:\ProgramData\Miniconda3\envs\comp8715\lib\site-packages\flask\app.py", line 1949, in full_dispatch_request
    rv = self.dispatch_request()
  File "D:\ProgramData\Miniconda3\envs\comp8715\lib\site-packages\flask\app.py", line 1935, in dispatch_request
    return self.view_functions[rule.endpoint](**req.view_args)
  File "D:\TedZhang\Courses\COMP8715\SAT-Track\server\views\view.py", line 138, in search_satellite
    status, satellites = controll_search_satellites(user_id, user_input)
  File "D:\TedZhang\Courses\COMP8715\SAT-Track\server\controllers\user_behavior_controller.py", line 69, in controll_search_satellites
    satellite_lst = search_satellites_from_es(user_input)
  File "D:\TedZhang\Courses\COMP8715\SAT-Track\server\services\satellite_search_service.py", line 189, in search_satellites_from_es
    search_body = turn_to_query_body(classes, user_input)
  File "D:\TedZhang\Courses\COMP8715\SAT-Track\server\services\satellite_search_service.py", line 139, in turn_to_query_body
    must.append({'match': {'launch_unixtime': to_date(classes)[1]}})
  File "D:\TedZhang\Courses\COMP8715\SAT-Track\server\services\satellite_search_service.py", line 124, in to_date
    return ripe_date, Utils.to_all_unixtime(ripe_date)
  File "D:\TedZhang\Courses\COMP8715\SAT-Track\utilities\utils.py", line 32, in to_all_unixtime
    date = datetime.datetime.strptime(date + ' 00:00:00', '%Y-%m-%d %H:%M:%S')
  File "D:\ProgramData\Miniconda3\envs\comp8715\lib\_strptime.py", line 577, in _strptime_datetime
    tt, fraction, gmtoff_fraction = _strptime(data_string, format)
  File "D:\ProgramData\Miniconda3\envs\comp8715\lib\_strptime.py", line 359, in _strptime
    (data_string, format))
ValueError: time data '1998-11- 00:00:00' does not match format '%Y-%m-%d %H:%M:%S'
[2020-04-21 18:36:10,179][app.py:1891][ERROR][13816] - Exception on /searchSatellite [GET]
Traceback (most recent call last):
  File "D:\ProgramData\Miniconda3\envs\comp8715\lib\site-packages\flask\app.py", line 2446, in wsgi_app
    response = self.full_dispatch_request()
  File "D:\ProgramData\Miniconda3\envs\comp8715\lib\site-packages\flask\app.py", line 1951, in full_dispatch_request
    rv = self.handle_user_exception(e)
  File "D:\ProgramData\Miniconda3\envs\comp8715\lib\site-packages\flask_cors\extension.py", line 161, in wrapped_function
    return cors_after_request(app.make_response(f(*args, **kwargs)))
  File "D:\ProgramData\Miniconda3\envs\comp8715\lib\site-packages\flask\app.py", line 1820, in handle_user_exception
    reraise(exc_type, exc_value, tb)
  File "D:\ProgramData\Miniconda3\envs\comp8715\lib\site-packages\flask\_compat.py", line 39, in reraise
    raise value
  File "D:\ProgramData\Miniconda3\envs\comp8715\lib\site-packages\flask\app.py", line 1949, in full_dispatch_request
    rv = self.dispatch_request()
  File "D:\ProgramData\Miniconda3\envs\comp8715\lib\site-packages\flask\app.py", line 1935, in dispatch_request
    return self.view_functions[rule.endpoint](**req.view_args)
  File "D:\TedZhang\Courses\COMP8715\SAT-Track\server\views\view.py", line 138, in search_satellite
    status, satellites = controll_search_satellites(user_id, user_input)
  File "D:\TedZhang\Courses\COMP8715\SAT-Track\server\controllers\user_behavior_controller.py", line 69, in controll_search_satellites
    satellite_lst = search_satellites_from_es(user_input)
  File "D:\TedZhang\Courses\COMP8715\SAT-Track\server\services\satellite_search_service.py", line 190, in search_satellites_from_es
    search_body = turn_to_query_body(classes, user_input)
  File "D:\TedZhang\Courses\COMP8715\SAT-Track\server\services\satellite_search_service.py", line 140, in turn_to_query_body
    must.append({'match': {'launch_unixtime': to_date(classes)[1]}})
  File "D:\TedZhang\Courses\COMP8715\SAT-Track\server\services\satellite_search_service.py", line 125, in to_date
    return ripe_date, Utils.to_all_unixtime(ripe_date)
  File "D:\TedZhang\Courses\COMP8715\SAT-Track\utilities\utils.py", line 32, in to_all_unixtime
    date = datetime.datetime.strptime(date + ' 00:00:00', '%Y-%m-%d %H:%M:%S')
  File "D:\ProgramData\Miniconda3\envs\comp8715\lib\_strptime.py", line 577, in _strptime_datetime
    tt, fraction, gmtoff_fraction = _strptime(data_string, format)
  File "D:\ProgramData\Miniconda3\envs\comp8715\lib\_strptime.py", line 359, in _strptime
    (data_string, format))
ValueError: time data '1998-11- 00:00:00' does not match format '%Y-%m-%d %H:%M:%S'
[2020-04-21 21:06:47,471][app.py:1891][ERROR][14132] - Exception on /searchSatellite [GET]
Traceback (most recent call last):
  File "D:\ProgramData\Miniconda3\envs\comp8715\lib\site-packages\flask\app.py", line 2446, in wsgi_app
    response = self.full_dispatch_request()
  File "D:\ProgramData\Miniconda3\envs\comp8715\lib\site-packages\flask\app.py", line 1951, in full_dispatch_request
    rv = self.handle_user_exception(e)
  File "D:\ProgramData\Miniconda3\envs\comp8715\lib\site-packages\flask_cors\extension.py", line 161, in wrapped_function
    return cors_after_request(app.make_response(f(*args, **kwargs)))
  File "D:\ProgramData\Miniconda3\envs\comp8715\lib\site-packages\flask\app.py", line 1820, in handle_user_exception
    reraise(exc_type, exc_value, tb)
  File "D:\ProgramData\Miniconda3\envs\comp8715\lib\site-packages\flask\_compat.py", line 39, in reraise
    raise value
  File "D:\ProgramData\Miniconda3\envs\comp8715\lib\site-packages\flask\app.py", line 1949, in full_dispatch_request
    rv = self.dispatch_request()
  File "D:\ProgramData\Miniconda3\envs\comp8715\lib\site-packages\flask\app.py", line 1935, in dispatch_request
    return self.view_functions[rule.endpoint](**req.view_args)
  File "D:\TedZhang\Courses\COMP8715\SAT-Track\server\views\view.py", line 138, in search_satellite
    status, satellites = controll_search_satellites(user_id, user_input)
  File "D:\TedZhang\Courses\COMP8715\SAT-Track\server\controllers\user_behavior_controller.py", line 69, in controll_search_satellites
    satellite_lst = search_satellites_from_es(user_input)
  File "D:\TedZhang\Courses\COMP8715\SAT-Track\server\services\satellite_search_service.py", line 191, in search_satellites_from_es
    search_body = turn_to_query_body(classes, user_input)
  File "D:\TedZhang\Courses\COMP8715\SAT-Track\server\services\satellite_search_service.py", line 142, in turn_to_query_body
    and ((k == 'is_number' or k == 'is_year' or k == 'is_month' or k == 'is_day') and classes['is_date'][0][0] >= 0.6):
TypeError: '>=' not supported between instances of 'str' and 'float'
[2020-04-21 21:24:56,932][app.py:1891][ERROR][7700] - Exception on /searchSatellite [GET]
Traceback (most recent call last):
  File "D:\ProgramData\Miniconda3\envs\comp8715\lib\site-packages\flask\app.py", line 2446, in wsgi_app
    response = self.full_dispatch_request()
  File "D:\ProgramData\Miniconda3\envs\comp8715\lib\site-packages\flask\app.py", line 1951, in full_dispatch_request
    rv = self.handle_user_exception(e)
  File "D:\ProgramData\Miniconda3\envs\comp8715\lib\site-packages\flask_cors\extension.py", line 161, in wrapped_function
    return cors_after_request(app.make_response(f(*args, **kwargs)))
  File "D:\ProgramData\Miniconda3\envs\comp8715\lib\site-packages\flask\app.py", line 1820, in handle_user_exception
    reraise(exc_type, exc_value, tb)
  File "D:\ProgramData\Miniconda3\envs\comp8715\lib\site-packages\flask\_compat.py", line 39, in reraise
    raise value
  File "D:\ProgramData\Miniconda3\envs\comp8715\lib\site-packages\flask\app.py", line 1949, in full_dispatch_request
    rv = self.dispatch_request()
  File "D:\ProgramData\Miniconda3\envs\comp8715\lib\site-packages\flask\app.py", line 1935, in dispatch_request
    return self.view_functions[rule.endpoint](**req.view_args)
  File "D:\TedZhang\Courses\COMP8715\SAT-Track\server\views\view.py", line 138, in search_satellite
    status, satellites = controll_search_satellites(user_id, user_input)
  File "D:\TedZhang\Courses\COMP8715\SAT-Track\server\controllers\user_behavior_controller.py", line 69, in controll_search_satellites
    satellite_lst = search_satellites_from_es(user_input)
  File "D:\TedZhang\Courses\COMP8715\SAT-Track\server\services\satellite_search_service.py", line 195, in search_satellites_from_es
    res = satellite_database.search_by_body(search_body)
  File "D:\TedZhang\Courses\COMP8715\SAT-Track\utilities\es_io.py", line 137, in search_by_body
    response = es.search(index=self.table, size=conf.ES_QUERY_MAX_SIZE, body=body)
  File "D:\ProgramData\Miniconda3\envs\comp8715\lib\site-packages\elasticsearch\client\utils.py", line 84, in _wrapped
    return func(*args, params=params, **kwargs)
  File "D:\ProgramData\Miniconda3\envs\comp8715\lib\site-packages\elasticsearch\client\__init__.py", line 811, in search
    "GET", _make_path(index, "_search"), params=params, body=body
  File "D:\ProgramData\Miniconda3\envs\comp8715\lib\site-packages\elasticsearch\transport.py", line 358, in perform_request
    timeout=timeout,
  File "D:\ProgramData\Miniconda3\envs\comp8715\lib\site-packages\elasticsearch\connection\http_urllib3.py", line 257, in perform_request
    self._raise_error(response.status, raw_data)
  File "D:\ProgramData\Miniconda3\envs\comp8715\lib\site-packages\elasticsearch\connection\base.py", line 182, in _raise_error
    status_code, error_message, additional_info
elasticsearch.exceptions.RequestError: RequestError(400, 'parsing_exception', "[fuzzy] query doesn't support multiple fields, found [extract] and [fuzziness]")
[2020-04-22 00:46:32,153][app.py:1891][ERROR][12244] - Exception on /searchSatellite [GET]
Traceback (most recent call last):
  File "D:\ProgramData\Miniconda3\envs\comp8715\lib\site-packages\flask\app.py", line 2446, in wsgi_app
    response = self.full_dispatch_request()
  File "D:\ProgramData\Miniconda3\envs\comp8715\lib\site-packages\flask\app.py", line 1951, in full_dispatch_request
    rv = self.handle_user_exception(e)
  File "D:\ProgramData\Miniconda3\envs\comp8715\lib\site-packages\flask_cors\extension.py", line 161, in wrapped_function
    return cors_after_request(app.make_response(f(*args, **kwargs)))
  File "D:\ProgramData\Miniconda3\envs\comp8715\lib\site-packages\flask\app.py", line 1820, in handle_user_exception
    reraise(exc_type, exc_value, tb)
  File "D:\ProgramData\Miniconda3\envs\comp8715\lib\site-packages\flask\_compat.py", line 39, in reraise
    raise value
  File "D:\ProgramData\Miniconda3\envs\comp8715\lib\site-packages\flask\app.py", line 1949, in full_dispatch_request
    rv = self.dispatch_request()
  File "D:\ProgramData\Miniconda3\envs\comp8715\lib\site-packages\flask\app.py", line 1935, in dispatch_request
    return self.view_functions[rule.endpoint](**req.view_args)
  File "D:\TedZhang\Courses\COMP8715\SAT-Track\server\views\view.py", line 138, in search_satellite
    status, satellites = controll_search_satellites(user_id, user_input)
  File "D:\TedZhang\Courses\COMP8715\SAT-Track\server\controllers\user_behavior_controller.py", line 72, in controll_search_satellites
    print(len(satellite_lst))
TypeError: object of type 'NoneType' has no len()
