[2020-04-19 01:22:36,433][app.py:1891][ERROR][4552] - Exception on /searchSatellite [GET]
Traceback (most recent call last):
  File "D:\ProgramData\Miniconda3\envs\comp8715\lib\site-packages\flask\app.py", line 2446, in wsgi_app
    response = self.full_dispatch_request()
  File "D:\ProgramData\Miniconda3\envs\comp8715\lib\site-packages\flask\app.py", line 1951, in full_dispatch_request
    rv = self.handle_user_exception(e)
  File "D:\ProgramData\Miniconda3\envs\comp8715\lib\site-packages\flask_cors\extension.py", line 161, in wrapped_function
    return cors_after_request(app.make_response(f(*args, **kwargs)))
  File "D:\ProgramData\Miniconda3\envs\comp8715\lib\site-packages\flask\app.py", line 1820, in handle_user_exception
    reraise(exc_type, exc_value, tb)
  File "D:\ProgramData\Miniconda3\envs\comp8715\lib\site-packages\flask\_compat.py", line 39, in reraise
    raise value
  File "D:\ProgramData\Miniconda3\envs\comp8715\lib\site-packages\flask\app.py", line 1949, in full_dispatch_request
    rv = self.dispatch_request()
  File "D:\ProgramData\Miniconda3\envs\comp8715\lib\site-packages\flask\app.py", line 1935, in dispatch_request
    return self.view_functions[rule.endpoint](**req.view_args)
  File "D:\TedZhang\Courses\COMP8715\SAT-Track\server\views\view.py", line 139, in search_new_task
    user_input = int(request.args.get('input'))
ValueError: invalid literal for int() with base 10: 'vaguard 1'
[2020-04-19 01:24:04,503][app.py:1891][ERROR][9624] - Exception on /searchSatellite [GET]
Traceback (most recent call last):
  File "D:\ProgramData\Miniconda3\envs\comp8715\lib\site-packages\flask\app.py", line 2446, in wsgi_app
    response = self.full_dispatch_request()
  File "D:\ProgramData\Miniconda3\envs\comp8715\lib\site-packages\flask\app.py", line 1951, in full_dispatch_request
    rv = self.handle_user_exception(e)
  File "D:\ProgramData\Miniconda3\envs\comp8715\lib\site-packages\flask_cors\extension.py", line 161, in wrapped_function
    return cors_after_request(app.make_response(f(*args, **kwargs)))
  File "D:\ProgramData\Miniconda3\envs\comp8715\lib\site-packages\flask\app.py", line 1820, in handle_user_exception
    reraise(exc_type, exc_value, tb)
  File "D:\ProgramData\Miniconda3\envs\comp8715\lib\site-packages\flask\_compat.py", line 39, in reraise
    raise value
  File "D:\ProgramData\Miniconda3\envs\comp8715\lib\site-packages\flask\app.py", line 1949, in full_dispatch_request
    rv = self.dispatch_request()
  File "D:\ProgramData\Miniconda3\envs\comp8715\lib\site-packages\flask\app.py", line 1935, in dispatch_request
    return self.view_functions[rule.endpoint](**req.view_args)
  File "D:\TedZhang\Courses\COMP8715\SAT-Track\server\views\view.py", line 139, in search_new_task
    user_input = int(request.args.get('input'))
ValueError: invalid literal for int() with base 10: 'vaguard 1'
[2020-04-19 01:24:43,877][app.py:1891][ERROR][15900] - Exception on /searchSatellite [GET]
Traceback (most recent call last):
  File "D:\ProgramData\Miniconda3\envs\comp8715\lib\site-packages\flask\app.py", line 2446, in wsgi_app
    response = self.full_dispatch_request()
  File "D:\ProgramData\Miniconda3\envs\comp8715\lib\site-packages\flask\app.py", line 1951, in full_dispatch_request
    rv = self.handle_user_exception(e)
  File "D:\ProgramData\Miniconda3\envs\comp8715\lib\site-packages\flask_cors\extension.py", line 161, in wrapped_function
    return cors_after_request(app.make_response(f(*args, **kwargs)))
  File "D:\ProgramData\Miniconda3\envs\comp8715\lib\site-packages\flask\app.py", line 1820, in handle_user_exception
    reraise(exc_type, exc_value, tb)
  File "D:\ProgramData\Miniconda3\envs\comp8715\lib\site-packages\flask\_compat.py", line 39, in reraise
    raise value
  File "D:\ProgramData\Miniconda3\envs\comp8715\lib\site-packages\flask\app.py", line 1949, in full_dispatch_request
    rv = self.dispatch_request()
  File "D:\ProgramData\Miniconda3\envs\comp8715\lib\site-packages\flask\app.py", line 1935, in dispatch_request
    return self.view_functions[rule.endpoint](**req.view_args)
  File "D:\TedZhang\Courses\COMP8715\SAT-Track\server\views\view.py", line 141, in search_new_task
    status, tasks = controll_search_new_task(user_id, user_input)
  File "D:\TedZhang\Courses\COMP8715\SAT-Track\server\controllers\user_behavior_controller.py", line 69, in controll_search_new_task
    satellite_lst = search_satellites_from_es(user_input)
  File "D:\TedZhang\Courses\COMP8715\SAT-Track\server\services\satellite_search_service.py", line 182, in search_satellites_from_es
    res = satellite_database.search_by_body(search_body)
NameError: name 'satellite_database' is not defined
[2020-04-19 01:42:26,729][app.py:1891][ERROR][12160] - Exception on /index [GET]
Traceback (most recent call last):
  File "D:\ProgramData\Miniconda3\envs\comp8715\lib\site-packages\flask\app.py", line 2446, in wsgi_app
    response = self.full_dispatch_request()
  File "D:\ProgramData\Miniconda3\envs\comp8715\lib\site-packages\flask\app.py", line 1951, in full_dispatch_request
    rv = self.handle_user_exception(e)
  File "D:\ProgramData\Miniconda3\envs\comp8715\lib\site-packages\flask_cors\extension.py", line 161, in wrapped_function
    return cors_after_request(app.make_response(f(*args, **kwargs)))
  File "D:\ProgramData\Miniconda3\envs\comp8715\lib\site-packages\flask\app.py", line 1820, in handle_user_exception
    reraise(exc_type, exc_value, tb)
  File "D:\ProgramData\Miniconda3\envs\comp8715\lib\site-packages\flask\_compat.py", line 39, in reraise
    raise value
  File "D:\ProgramData\Miniconda3\envs\comp8715\lib\site-packages\flask\app.py", line 1949, in full_dispatch_request
    rv = self.dispatch_request()
  File "D:\ProgramData\Miniconda3\envs\comp8715\lib\site-packages\flask\app.py", line 1935, in dispatch_request
    return self.view_functions[rule.endpoint](**req.view_args)
  File "D:\ProgramData\Miniconda3\envs\comp8715\lib\site-packages\flask_login\utils.py", line 272, in decorated_view
    return func(*args, **kwargs)
  File "D:\TedZhang\Courses\COMP8715\SAT-Track\server\views\view.py", line 12, in index
    from utilities.simulate_for_dev import Simulation
ImportError: cannot import name 'Simulation' from 'utilities.simulate_for_dev' (D:\TedZhang\Courses\COMP8715\SAT-Track\utilities\simulate_for_dev.py)
[2020-04-19 01:52:22,462][app.py:1891][ERROR][2388] - Exception on /searchSatellite [GET]
Traceback (most recent call last):
  File "D:\ProgramData\Miniconda3\envs\comp8715\lib\site-packages\flask\app.py", line 2446, in wsgi_app
    response = self.full_dispatch_request()
  File "D:\ProgramData\Miniconda3\envs\comp8715\lib\site-packages\flask\app.py", line 1951, in full_dispatch_request
    rv = self.handle_user_exception(e)
  File "D:\ProgramData\Miniconda3\envs\comp8715\lib\site-packages\flask_cors\extension.py", line 161, in wrapped_function
    return cors_after_request(app.make_response(f(*args, **kwargs)))
  File "D:\ProgramData\Miniconda3\envs\comp8715\lib\site-packages\flask\app.py", line 1820, in handle_user_exception
    reraise(exc_type, exc_value, tb)
  File "D:\ProgramData\Miniconda3\envs\comp8715\lib\site-packages\flask\_compat.py", line 39, in reraise
    raise value
  File "D:\ProgramData\Miniconda3\envs\comp8715\lib\site-packages\flask\app.py", line 1949, in full_dispatch_request
    rv = self.dispatch_request()
  File "D:\ProgramData\Miniconda3\envs\comp8715\lib\site-packages\flask\app.py", line 1935, in dispatch_request
    return self.view_functions[rule.endpoint](**req.view_args)
  File "D:\TedZhang\Courses\COMP8715\SAT-Track\server\views\view.py", line 137, in search_satellite
    status, tasks = controll_search_new_task(user_id, user_input)
  File "D:\TedZhang\Courses\COMP8715\SAT-Track\server\controllers\user_behavior_controller.py", line 78, in controll_search_new_task
    status_, res = SatelliteManager.to_satellites(satellite_lst)
  File "D:\TedZhang\Courses\COMP8715\SAT-Track\server\services\data_storage_service.py", line 140, in to_satellites
    print(len(lst), lst(satellites))
TypeError: 'list' object is not callable
[2020-04-19 02:07:50,794][app.py:1891][ERROR][5336] - Exception on /searchSatellite [GET]
Traceback (most recent call last):
  File "D:\ProgramData\Miniconda3\envs\comp8715\lib\site-packages\flask\app.py", line 2446, in wsgi_app
    response = self.full_dispatch_request()
  File "D:\ProgramData\Miniconda3\envs\comp8715\lib\site-packages\flask\app.py", line 1951, in full_dispatch_request
    rv = self.handle_user_exception(e)
  File "D:\ProgramData\Miniconda3\envs\comp8715\lib\site-packages\flask_cors\extension.py", line 161, in wrapped_function
    return cors_after_request(app.make_response(f(*args, **kwargs)))
  File "D:\ProgramData\Miniconda3\envs\comp8715\lib\site-packages\flask\app.py", line 1820, in handle_user_exception
    reraise(exc_type, exc_value, tb)
  File "D:\ProgramData\Miniconda3\envs\comp8715\lib\site-packages\flask\_compat.py", line 39, in reraise
    raise value
  File "D:\ProgramData\Miniconda3\envs\comp8715\lib\site-packages\flask\app.py", line 1949, in full_dispatch_request
    rv = self.dispatch_request()
  File "D:\ProgramData\Miniconda3\envs\comp8715\lib\site-packages\flask\app.py", line 1935, in dispatch_request
    return self.view_functions[rule.endpoint](**req.view_args)
  File "D:\TedZhang\Courses\COMP8715\SAT-Track\server\views\view.py", line 137, in search_satellite
    status, tasks = controll_search_new_task(user_id, user_input)
  File "D:\TedZhang\Courses\COMP8715\SAT-Track\server\controllers\user_behavior_controller.py", line 69, in controll_search_new_task
    satellite_lst = search_satellites_from_es(user_input)
  File "D:\TedZhang\Courses\COMP8715\SAT-Track\server\services\satellite_search_service.py", line 188, in search_satellites_from_es
    search_body = turn_to_query_body(classes, user_input)
  File "D:\TedZhang\Courses\COMP8715\SAT-Track\server\services\satellite_search_service.py", line 162, in turn_to_query_body
    extract_input = extract_input.lstrip().rstrip()
AttributeError: 'list' object has no attribute 'lstrip'
