[2020-04-19 01:22:36,433][app.py:1891][ERROR][4552] - Exception on /searchSatellite [GET]
Traceback (most recent call last):
  File "D:\ProgramData\Miniconda3\envs\comp8715\lib\site-packages\flask\app.py", line 2446, in wsgi_app
    response = self.full_dispatch_request()
  File "D:\ProgramData\Miniconda3\envs\comp8715\lib\site-packages\flask\app.py", line 1951, in full_dispatch_request
    rv = self.handle_user_exception(e)
  File "D:\ProgramData\Miniconda3\envs\comp8715\lib\site-packages\flask_cors\extension.py", line 161, in wrapped_function
    return cors_after_request(app.make_response(f(*args, **kwargs)))
  File "D:\ProgramData\Miniconda3\envs\comp8715\lib\site-packages\flask\app.py", line 1820, in handle_user_exception
    reraise(exc_type, exc_value, tb)
  File "D:\ProgramData\Miniconda3\envs\comp8715\lib\site-packages\flask\_compat.py", line 39, in reraise
    raise value
  File "D:\ProgramData\Miniconda3\envs\comp8715\lib\site-packages\flask\app.py", line 1949, in full_dispatch_request
    rv = self.dispatch_request()
  File "D:\ProgramData\Miniconda3\envs\comp8715\lib\site-packages\flask\app.py", line 1935, in dispatch_request
    return self.view_functions[rule.endpoint](**req.view_args)
  File "D:\TedZhang\Courses\COMP8715\SAT-Track\server\views\view.py", line 139, in search_new_task
    user_input = int(request.args.get('input'))
ValueError: invalid literal for int() with base 10: 'vaguard 1'
[2020-04-19 01:24:04,503][app.py:1891][ERROR][9624] - Exception on /searchSatellite [GET]
Traceback (most recent call last):
  File "D:\ProgramData\Miniconda3\envs\comp8715\lib\site-packages\flask\app.py", line 2446, in wsgi_app
    response = self.full_dispatch_request()
  File "D:\ProgramData\Miniconda3\envs\comp8715\lib\site-packages\flask\app.py", line 1951, in full_dispatch_request
    rv = self.handle_user_exception(e)
  File "D:\ProgramData\Miniconda3\envs\comp8715\lib\site-packages\flask_cors\extension.py", line 161, in wrapped_function
    return cors_after_request(app.make_response(f(*args, **kwargs)))
  File "D:\ProgramData\Miniconda3\envs\comp8715\lib\site-packages\flask\app.py", line 1820, in handle_user_exception
    reraise(exc_type, exc_value, tb)
  File "D:\ProgramData\Miniconda3\envs\comp8715\lib\site-packages\flask\_compat.py", line 39, in reraise
    raise value
  File "D:\ProgramData\Miniconda3\envs\comp8715\lib\site-packages\flask\app.py", line 1949, in full_dispatch_request
    rv = self.dispatch_request()
  File "D:\ProgramData\Miniconda3\envs\comp8715\lib\site-packages\flask\app.py", line 1935, in dispatch_request
    return self.view_functions[rule.endpoint](**req.view_args)
  File "D:\TedZhang\Courses\COMP8715\SAT-Track\server\views\view.py", line 139, in search_new_task
    user_input = int(request.args.get('input'))
ValueError: invalid literal for int() with base 10: 'vaguard 1'
[2020-04-19 01:24:43,877][app.py:1891][ERROR][15900] - Exception on /searchSatellite [GET]
Traceback (most recent call last):
  File "D:\ProgramData\Miniconda3\envs\comp8715\lib\site-packages\flask\app.py", line 2446, in wsgi_app
    response = self.full_dispatch_request()
  File "D:\ProgramData\Miniconda3\envs\comp8715\lib\site-packages\flask\app.py", line 1951, in full_dispatch_request
    rv = self.handle_user_exception(e)
  File "D:\ProgramData\Miniconda3\envs\comp8715\lib\site-packages\flask_cors\extension.py", line 161, in wrapped_function
    return cors_after_request(app.make_response(f(*args, **kwargs)))
  File "D:\ProgramData\Miniconda3\envs\comp8715\lib\site-packages\flask\app.py", line 1820, in handle_user_exception
    reraise(exc_type, exc_value, tb)
  File "D:\ProgramData\Miniconda3\envs\comp8715\lib\site-packages\flask\_compat.py", line 39, in reraise
    raise value
  File "D:\ProgramData\Miniconda3\envs\comp8715\lib\site-packages\flask\app.py", line 1949, in full_dispatch_request
    rv = self.dispatch_request()
  File "D:\ProgramData\Miniconda3\envs\comp8715\lib\site-packages\flask\app.py", line 1935, in dispatch_request
    return self.view_functions[rule.endpoint](**req.view_args)
  File "D:\TedZhang\Courses\COMP8715\SAT-Track\server\views\view.py", line 141, in search_new_task
    status, tasks = controll_search_new_task(user_id, user_input)
  File "D:\TedZhang\Courses\COMP8715\SAT-Track\server\controllers\user_behavior_controller.py", line 69, in controll_search_new_task
    satellite_lst = search_satellites_from_es(user_input)
  File "D:\TedZhang\Courses\COMP8715\SAT-Track\server\services\satellite_search_service.py", line 182, in search_satellites_from_es
    res = satellite_database.search_by_body(search_body)
NameError: name 'satellite_database' is not defined
[2020-04-19 01:42:26,729][app.py:1891][ERROR][12160] - Exception on /index [GET]
Traceback (most recent call last):
  File "D:\ProgramData\Miniconda3\envs\comp8715\lib\site-packages\flask\app.py", line 2446, in wsgi_app
    response = self.full_dispatch_request()
  File "D:\ProgramData\Miniconda3\envs\comp8715\lib\site-packages\flask\app.py", line 1951, in full_dispatch_request
    rv = self.handle_user_exception(e)
  File "D:\ProgramData\Miniconda3\envs\comp8715\lib\site-packages\flask_cors\extension.py", line 161, in wrapped_function
    return cors_after_request(app.make_response(f(*args, **kwargs)))
  File "D:\ProgramData\Miniconda3\envs\comp8715\lib\site-packages\flask\app.py", line 1820, in handle_user_exception
    reraise(exc_type, exc_value, tb)
  File "D:\ProgramData\Miniconda3\envs\comp8715\lib\site-packages\flask\_compat.py", line 39, in reraise
    raise value
  File "D:\ProgramData\Miniconda3\envs\comp8715\lib\site-packages\flask\app.py", line 1949, in full_dispatch_request
    rv = self.dispatch_request()
  File "D:\ProgramData\Miniconda3\envs\comp8715\lib\site-packages\flask\app.py", line 1935, in dispatch_request
    return self.view_functions[rule.endpoint](**req.view_args)
  File "D:\ProgramData\Miniconda3\envs\comp8715\lib\site-packages\flask_login\utils.py", line 272, in decorated_view
    return func(*args, **kwargs)
  File "D:\TedZhang\Courses\COMP8715\SAT-Track\server\views\view.py", line 12, in index
    from utilities.simulate_for_dev import Simulation
ImportError: cannot import name 'Simulation' from 'utilities.simulate_for_dev' (D:\TedZhang\Courses\COMP8715\SAT-Track\utilities\simulate_for_dev.py)
[2020-04-19 01:52:22,462][app.py:1891][ERROR][2388] - Exception on /searchSatellite [GET]
Traceback (most recent call last):
  File "D:\ProgramData\Miniconda3\envs\comp8715\lib\site-packages\flask\app.py", line 2446, in wsgi_app
    response = self.full_dispatch_request()
  File "D:\ProgramData\Miniconda3\envs\comp8715\lib\site-packages\flask\app.py", line 1951, in full_dispatch_request
    rv = self.handle_user_exception(e)
  File "D:\ProgramData\Miniconda3\envs\comp8715\lib\site-packages\flask_cors\extension.py", line 161, in wrapped_function
    return cors_after_request(app.make_response(f(*args, **kwargs)))
  File "D:\ProgramData\Miniconda3\envs\comp8715\lib\site-packages\flask\app.py", line 1820, in handle_user_exception
    reraise(exc_type, exc_value, tb)
  File "D:\ProgramData\Miniconda3\envs\comp8715\lib\site-packages\flask\_compat.py", line 39, in reraise
    raise value
  File "D:\ProgramData\Miniconda3\envs\comp8715\lib\site-packages\flask\app.py", line 1949, in full_dispatch_request
    rv = self.dispatch_request()
  File "D:\ProgramData\Miniconda3\envs\comp8715\lib\site-packages\flask\app.py", line 1935, in dispatch_request
    return self.view_functions[rule.endpoint](**req.view_args)
  File "D:\TedZhang\Courses\COMP8715\SAT-Track\server\views\view.py", line 137, in search_satellite
    status, tasks = controll_search_new_task(user_id, user_input)
  File "D:\TedZhang\Courses\COMP8715\SAT-Track\server\controllers\user_behavior_controller.py", line 78, in controll_search_new_task
    status_, res = SatelliteManager.to_satellites(satellite_lst)
  File "D:\TedZhang\Courses\COMP8715\SAT-Track\server\services\data_storage_service.py", line 140, in to_satellites
    print(len(lst), lst(satellites))
TypeError: 'list' object is not callable
[2020-04-19 02:07:50,794][app.py:1891][ERROR][5336] - Exception on /searchSatellite [GET]
Traceback (most recent call last):
  File "D:\ProgramData\Miniconda3\envs\comp8715\lib\site-packages\flask\app.py", line 2446, in wsgi_app
    response = self.full_dispatch_request()
  File "D:\ProgramData\Miniconda3\envs\comp8715\lib\site-packages\flask\app.py", line 1951, in full_dispatch_request
    rv = self.handle_user_exception(e)
  File "D:\ProgramData\Miniconda3\envs\comp8715\lib\site-packages\flask_cors\extension.py", line 161, in wrapped_function
    return cors_after_request(app.make_response(f(*args, **kwargs)))
  File "D:\ProgramData\Miniconda3\envs\comp8715\lib\site-packages\flask\app.py", line 1820, in handle_user_exception
    reraise(exc_type, exc_value, tb)
  File "D:\ProgramData\Miniconda3\envs\comp8715\lib\site-packages\flask\_compat.py", line 39, in reraise
    raise value
  File "D:\ProgramData\Miniconda3\envs\comp8715\lib\site-packages\flask\app.py", line 1949, in full_dispatch_request
    rv = self.dispatch_request()
  File "D:\ProgramData\Miniconda3\envs\comp8715\lib\site-packages\flask\app.py", line 1935, in dispatch_request
    return self.view_functions[rule.endpoint](**req.view_args)
  File "D:\TedZhang\Courses\COMP8715\SAT-Track\server\views\view.py", line 137, in search_satellite
    status, tasks = controll_search_new_task(user_id, user_input)
  File "D:\TedZhang\Courses\COMP8715\SAT-Track\server\controllers\user_behavior_controller.py", line 69, in controll_search_new_task
    satellite_lst = search_satellites_from_es(user_input)
  File "D:\TedZhang\Courses\COMP8715\SAT-Track\server\services\satellite_search_service.py", line 188, in search_satellites_from_es
    search_body = turn_to_query_body(classes, user_input)
  File "D:\TedZhang\Courses\COMP8715\SAT-Track\server\services\satellite_search_service.py", line 162, in turn_to_query_body
    extract_input = extract_input.lstrip().rstrip()
AttributeError: 'list' object has no attribute 'lstrip'
[2020-04-19 03:40:52,179][app.py:1891][ERROR][2568] - Exception on /searchSatellite [GET]
Traceback (most recent call last):
  File "D:\ProgramData\Miniconda3\envs\comp8715\lib\site-packages\flask\app.py", line 2446, in wsgi_app
    response = self.full_dispatch_request()
  File "D:\ProgramData\Miniconda3\envs\comp8715\lib\site-packages\flask\app.py", line 1951, in full_dispatch_request
    rv = self.handle_user_exception(e)
  File "D:\ProgramData\Miniconda3\envs\comp8715\lib\site-packages\flask_cors\extension.py", line 161, in wrapped_function
    return cors_after_request(app.make_response(f(*args, **kwargs)))
  File "D:\ProgramData\Miniconda3\envs\comp8715\lib\site-packages\flask\app.py", line 1820, in handle_user_exception
    reraise(exc_type, exc_value, tb)
  File "D:\ProgramData\Miniconda3\envs\comp8715\lib\site-packages\flask\_compat.py", line 39, in reraise
    raise value
  File "D:\ProgramData\Miniconda3\envs\comp8715\lib\site-packages\flask\app.py", line 1949, in full_dispatch_request
    rv = self.dispatch_request()
  File "D:\ProgramData\Miniconda3\envs\comp8715\lib\site-packages\flask\app.py", line 1935, in dispatch_request
    return self.view_functions[rule.endpoint](**req.view_args)
  File "D:\TedZhang\Courses\COMP8715\SAT-Track\server\views\view.py", line 137, in search_satellite
    status, satellites = controll_search_satellites(user_id, user_input)
  File "D:\TedZhang\Courses\COMP8715\SAT-Track\server\controllers\user_behavior_controller.py", line 85, in controll_search_satellites
    print('error in controll_search_satellites: errors(' + str(len(errors)) + ') =', errors)
TypeError: object of type 'NoneType' has no len()
[2020-04-19 03:52:31,531][app.py:1891][ERROR][14156] - Exception on /selectSatellite [GET]
Traceback (most recent call last):
  File "D:\ProgramData\Miniconda3\envs\comp8715\lib\site-packages\flask\app.py", line 2446, in wsgi_app
    response = self.full_dispatch_request()
  File "D:\ProgramData\Miniconda3\envs\comp8715\lib\site-packages\flask\app.py", line 1951, in full_dispatch_request
    rv = self.handle_user_exception(e)
  File "D:\ProgramData\Miniconda3\envs\comp8715\lib\site-packages\flask_cors\extension.py", line 161, in wrapped_function
    return cors_after_request(app.make_response(f(*args, **kwargs)))
  File "D:\ProgramData\Miniconda3\envs\comp8715\lib\site-packages\flask\app.py", line 1820, in handle_user_exception
    reraise(exc_type, exc_value, tb)
  File "D:\ProgramData\Miniconda3\envs\comp8715\lib\site-packages\flask\_compat.py", line 39, in reraise
    raise value
  File "D:\ProgramData\Miniconda3\envs\comp8715\lib\site-packages\flask\app.py", line 1949, in full_dispatch_request
    rv = self.dispatch_request()
  File "D:\ProgramData\Miniconda3\envs\comp8715\lib\site-packages\flask\app.py", line 1935, in dispatch_request
    return self.view_functions[rule.endpoint](**req.view_args)
  File "D:\TedZhang\Courses\COMP8715\SAT-Track\server\views\view.py", line 159, in select_satellite
    status, satellites = controll_select_satellite(user_id, satellite_id)
  File "D:\TedZhang\Courses\COMP8715\SAT-Track\server\controllers\user_behavior_controller.py", line 94, in controll_select_satellite
    status, tasks = PriorityManager.insert(user.priority, satellite)
  File "D:\TedZhang\Courses\COMP8715\SAT-Track\server\services\data_storage_service.py", line 107, in insert
    satellite_id = satellite.norad_id
AttributeError: 'tuple' object has no attribute 'norad_id'
[2020-04-19 03:53:42,098][app.py:1891][ERROR][13000] - Exception on /selectSatellite [GET]
Traceback (most recent call last):
  File "D:\ProgramData\Miniconda3\envs\comp8715\lib\site-packages\flask\app.py", line 2446, in wsgi_app
    response = self.full_dispatch_request()
  File "D:\ProgramData\Miniconda3\envs\comp8715\lib\site-packages\flask\app.py", line 1951, in full_dispatch_request
    rv = self.handle_user_exception(e)
  File "D:\ProgramData\Miniconda3\envs\comp8715\lib\site-packages\flask_cors\extension.py", line 161, in wrapped_function
    return cors_after_request(app.make_response(f(*args, **kwargs)))
  File "D:\ProgramData\Miniconda3\envs\comp8715\lib\site-packages\flask\app.py", line 1820, in handle_user_exception
    reraise(exc_type, exc_value, tb)
  File "D:\ProgramData\Miniconda3\envs\comp8715\lib\site-packages\flask\_compat.py", line 39, in reraise
    raise value
  File "D:\ProgramData\Miniconda3\envs\comp8715\lib\site-packages\flask\app.py", line 1949, in full_dispatch_request
    rv = self.dispatch_request()
  File "D:\ProgramData\Miniconda3\envs\comp8715\lib\site-packages\flask\app.py", line 1935, in dispatch_request
    return self.view_functions[rule.endpoint](**req.view_args)
  File "D:\TedZhang\Courses\COMP8715\SAT-Track\server\views\view.py", line 159, in select_satellite
    status, satellites = controll_select_satellite(user_id, satellite_id)
  File "D:\TedZhang\Courses\COMP8715\SAT-Track\server\controllers\user_behavior_controller.py", line 94, in controll_select_satellite
    print(dict(satellite))
TypeError: cannot convert dictionary update sequence element #0 to a sequence
[2020-04-19 03:54:15,042][app.py:1891][ERROR][5248] - Exception on /selectSatellite [GET]
Traceback (most recent call last):
  File "D:\ProgramData\Miniconda3\envs\comp8715\lib\site-packages\flask\app.py", line 2446, in wsgi_app
    response = self.full_dispatch_request()
  File "D:\ProgramData\Miniconda3\envs\comp8715\lib\site-packages\flask\app.py", line 1951, in full_dispatch_request
    rv = self.handle_user_exception(e)
  File "D:\ProgramData\Miniconda3\envs\comp8715\lib\site-packages\flask_cors\extension.py", line 161, in wrapped_function
    return cors_after_request(app.make_response(f(*args, **kwargs)))
  File "D:\ProgramData\Miniconda3\envs\comp8715\lib\site-packages\flask\app.py", line 1820, in handle_user_exception
    reraise(exc_type, exc_value, tb)
  File "D:\ProgramData\Miniconda3\envs\comp8715\lib\site-packages\flask\_compat.py", line 39, in reraise
    raise value
  File "D:\ProgramData\Miniconda3\envs\comp8715\lib\site-packages\flask\app.py", line 1949, in full_dispatch_request
    rv = self.dispatch_request()
  File "D:\ProgramData\Miniconda3\envs\comp8715\lib\site-packages\flask\app.py", line 1935, in dispatch_request
    return self.view_functions[rule.endpoint](**req.view_args)
  File "D:\TedZhang\Courses\COMP8715\SAT-Track\server\views\view.py", line 159, in select_satellite
    status, satellites = controll_select_satellite(user_id, satellite_id)
  File "D:\TedZhang\Courses\COMP8715\SAT-Track\server\controllers\user_behavior_controller.py", line 94, in controll_select_satellite
    print(dict(satellite))
TypeError: cannot convert dictionary update sequence element #0 to a sequence
[2020-04-19 03:55:03,506][app.py:1891][ERROR][2204] - Exception on /selectSatellite [GET]
Traceback (most recent call last):
  File "D:\ProgramData\Miniconda3\envs\comp8715\lib\site-packages\flask\app.py", line 2446, in wsgi_app
    response = self.full_dispatch_request()
  File "D:\ProgramData\Miniconda3\envs\comp8715\lib\site-packages\flask\app.py", line 1951, in full_dispatch_request
    rv = self.handle_user_exception(e)
  File "D:\ProgramData\Miniconda3\envs\comp8715\lib\site-packages\flask_cors\extension.py", line 161, in wrapped_function
    return cors_after_request(app.make_response(f(*args, **kwargs)))
  File "D:\ProgramData\Miniconda3\envs\comp8715\lib\site-packages\flask\app.py", line 1820, in handle_user_exception
    reraise(exc_type, exc_value, tb)
  File "D:\ProgramData\Miniconda3\envs\comp8715\lib\site-packages\flask\_compat.py", line 39, in reraise
    raise value
  File "D:\ProgramData\Miniconda3\envs\comp8715\lib\site-packages\flask\app.py", line 1949, in full_dispatch_request
    rv = self.dispatch_request()
  File "D:\ProgramData\Miniconda3\envs\comp8715\lib\site-packages\flask\app.py", line 1935, in dispatch_request
    return self.view_functions[rule.endpoint](**req.view_args)
  File "D:\TedZhang\Courses\COMP8715\SAT-Track\server\views\view.py", line 159, in select_satellite
    status, satellites = controll_select_satellite(user_id, satellite_id)
  File "D:\TedZhang\Courses\COMP8715\SAT-Track\server\controllers\user_behavior_controller.py", line 94, in controll_select_satellite
    print(dict(satellite))
TypeError: cannot convert dictionary update sequence element #0 to a sequence
[2020-04-19 03:55:34,522][app.py:1891][ERROR][12344] - Exception on /selectSatellite [GET]
Traceback (most recent call last):
  File "D:\ProgramData\Miniconda3\envs\comp8715\lib\site-packages\flask\app.py", line 2446, in wsgi_app
    response = self.full_dispatch_request()
  File "D:\ProgramData\Miniconda3\envs\comp8715\lib\site-packages\flask\app.py", line 1951, in full_dispatch_request
    rv = self.handle_user_exception(e)
  File "D:\ProgramData\Miniconda3\envs\comp8715\lib\site-packages\flask_cors\extension.py", line 161, in wrapped_function
    return cors_after_request(app.make_response(f(*args, **kwargs)))
  File "D:\ProgramData\Miniconda3\envs\comp8715\lib\site-packages\flask\app.py", line 1820, in handle_user_exception
    reraise(exc_type, exc_value, tb)
  File "D:\ProgramData\Miniconda3\envs\comp8715\lib\site-packages\flask\_compat.py", line 39, in reraise
    raise value
  File "D:\ProgramData\Miniconda3\envs\comp8715\lib\site-packages\flask\app.py", line 1949, in full_dispatch_request
    rv = self.dispatch_request()
  File "D:\ProgramData\Miniconda3\envs\comp8715\lib\site-packages\flask\app.py", line 1935, in dispatch_request
    return self.view_functions[rule.endpoint](**req.view_args)
  File "D:\TedZhang\Courses\COMP8715\SAT-Track\server\views\view.py", line 159, in select_satellite
    status, satellites = controll_select_satellite(user_id, satellite_id)
  File "D:\TedZhang\Courses\COMP8715\SAT-Track\server\controllers\user_behavior_controller.py", line 94, in controll_select_satellite
    print(dict(satellite))
TypeError: cannot convert dictionary update sequence element #0 to a sequence
[2020-04-19 03:57:07,894][app.py:1891][ERROR][5792] - Exception on /selectSatellite [GET]
Traceback (most recent call last):
  File "D:\ProgramData\Miniconda3\envs\comp8715\lib\site-packages\flask\app.py", line 2446, in wsgi_app
    response = self.full_dispatch_request()
  File "D:\ProgramData\Miniconda3\envs\comp8715\lib\site-packages\flask\app.py", line 1951, in full_dispatch_request
    rv = self.handle_user_exception(e)
  File "D:\ProgramData\Miniconda3\envs\comp8715\lib\site-packages\flask_cors\extension.py", line 161, in wrapped_function
    return cors_after_request(app.make_response(f(*args, **kwargs)))
  File "D:\ProgramData\Miniconda3\envs\comp8715\lib\site-packages\flask\app.py", line 1820, in handle_user_exception
    reraise(exc_type, exc_value, tb)
  File "D:\ProgramData\Miniconda3\envs\comp8715\lib\site-packages\flask\_compat.py", line 39, in reraise
    raise value
  File "D:\ProgramData\Miniconda3\envs\comp8715\lib\site-packages\flask\app.py", line 1949, in full_dispatch_request
    rv = self.dispatch_request()
  File "D:\ProgramData\Miniconda3\envs\comp8715\lib\site-packages\flask\app.py", line 1935, in dispatch_request
    return self.view_functions[rule.endpoint](**req.view_args)
  File "D:\TedZhang\Courses\COMP8715\SAT-Track\server\views\view.py", line 159, in select_satellite
    status, satellites = controll_select_satellite(user_id, satellite_id)
  File "D:\TedZhang\Courses\COMP8715\SAT-Track\server\controllers\user_behavior_controller.py", line 95, in controll_select_satellite
    status, tasks = PriorityManager.insert(user.priority, satellite)
  File "D:\TedZhang\Courses\COMP8715\SAT-Track\server\services\data_storage_service.py", line 107, in insert
    satellite_id = satellite.norad_id
AttributeError: 'tuple' object has no attribute 'norad_id'
[2020-04-21 17:34:32,484][app.py:1891][ERROR][14032] - Exception on /searchSatellite [GET]
Traceback (most recent call last):
  File "D:\ProgramData\Miniconda3\envs\comp8715\lib\site-packages\flask\app.py", line 2446, in wsgi_app
    response = self.full_dispatch_request()
  File "D:\ProgramData\Miniconda3\envs\comp8715\lib\site-packages\flask\app.py", line 1951, in full_dispatch_request
    rv = self.handle_user_exception(e)
  File "D:\ProgramData\Miniconda3\envs\comp8715\lib\site-packages\flask_cors\extension.py", line 161, in wrapped_function
    return cors_after_request(app.make_response(f(*args, **kwargs)))
  File "D:\ProgramData\Miniconda3\envs\comp8715\lib\site-packages\flask\app.py", line 1820, in handle_user_exception
    reraise(exc_type, exc_value, tb)
  File "D:\ProgramData\Miniconda3\envs\comp8715\lib\site-packages\flask\_compat.py", line 39, in reraise
    raise value
  File "D:\ProgramData\Miniconda3\envs\comp8715\lib\site-packages\flask\app.py", line 1949, in full_dispatch_request
    rv = self.dispatch_request()
  File "D:\ProgramData\Miniconda3\envs\comp8715\lib\site-packages\flask\app.py", line 1935, in dispatch_request
    return self.view_functions[rule.endpoint](**req.view_args)
  File "D:\TedZhang\Courses\COMP8715\SAT-Track\server\views\view.py", line 138, in search_satellite
    status, satellites = controll_search_satellites(user_id, user_input)
  File "D:\TedZhang\Courses\COMP8715\SAT-Track\server\controllers\user_behavior_controller.py", line 69, in controll_search_satellites
    satellite_lst = search_satellites_from_es(user_input)
  File "D:\TedZhang\Courses\COMP8715\SAT-Track\server\services\satellite_search_service.py", line 188, in search_satellites_from_es
    search_body = turn_to_query_body(classes, user_input)
  File "D:\TedZhang\Courses\COMP8715\SAT-Track\server\services\satellite_search_service.py", line 138, in turn_to_query_body
    must.append({'match': {'launch_unixtime': to_date(classes)[1]}})
  File "D:\TedZhang\Courses\COMP8715\SAT-Track\server\services\satellite_search_service.py", line 123, in to_date
    return ripe_date, Utils.to_all_unixtime(ripe_date)
  File "D:\TedZhang\Courses\COMP8715\SAT-Track\utilities\utils.py", line 32, in to_all_unixtime
    date = datetime.datetime.strptime(date + ' 00:00:00', '%Y-%m-%d %H:%M:%S')
  File "D:\ProgramData\Miniconda3\envs\comp8715\lib\_strptime.py", line 577, in _strptime_datetime
    tt, fraction, gmtoff_fraction = _strptime(data_string, format)
  File "D:\ProgramData\Miniconda3\envs\comp8715\lib\_strptime.py", line 359, in _strptime
    (data_string, format))
ValueError: time data '1983-07- 00:00:00' does not match format '%Y-%m-%d %H:%M:%S'
[2020-04-21 17:44:31,169][app.py:1891][ERROR][2000] - Exception on /searchSatellite [GET]
Traceback (most recent call last):
  File "D:\ProgramData\Miniconda3\envs\comp8715\lib\site-packages\flask\app.py", line 2446, in wsgi_app
    response = self.full_dispatch_request()
  File "D:\ProgramData\Miniconda3\envs\comp8715\lib\site-packages\flask\app.py", line 1951, in full_dispatch_request
    rv = self.handle_user_exception(e)
  File "D:\ProgramData\Miniconda3\envs\comp8715\lib\site-packages\flask_cors\extension.py", line 161, in wrapped_function
    return cors_after_request(app.make_response(f(*args, **kwargs)))
  File "D:\ProgramData\Miniconda3\envs\comp8715\lib\site-packages\flask\app.py", line 1820, in handle_user_exception
    reraise(exc_type, exc_value, tb)
  File "D:\ProgramData\Miniconda3\envs\comp8715\lib\site-packages\flask\_compat.py", line 39, in reraise
    raise value
  File "D:\ProgramData\Miniconda3\envs\comp8715\lib\site-packages\flask\app.py", line 1949, in full_dispatch_request
    rv = self.dispatch_request()
  File "D:\ProgramData\Miniconda3\envs\comp8715\lib\site-packages\flask\app.py", line 1935, in dispatch_request
    return self.view_functions[rule.endpoint](**req.view_args)
  File "D:\TedZhang\Courses\COMP8715\SAT-Track\server\views\view.py", line 138, in search_satellite
    status, satellites = controll_search_satellites(user_id, user_input)
  File "D:\TedZhang\Courses\COMP8715\SAT-Track\server\controllers\user_behavior_controller.py", line 69, in controll_search_satellites
    satellite_lst = search_satellites_from_es(user_input)
  File "D:\TedZhang\Courses\COMP8715\SAT-Track\server\services\satellite_search_service.py", line 188, in search_satellites_from_es
    search_body = turn_to_query_body(classes, user_input)
  File "D:\TedZhang\Courses\COMP8715\SAT-Track\server\services\satellite_search_service.py", line 138, in turn_to_query_body
    must.append({'match': {'launch_unixtime': to_date(classes)[1]}})
  File "D:\TedZhang\Courses\COMP8715\SAT-Track\server\services\satellite_search_service.py", line 123, in to_date
    return ripe_date, Utils.to_all_unixtime(ripe_date)
  File "D:\TedZhang\Courses\COMP8715\SAT-Track\utilities\utils.py", line 32, in to_all_unixtime
    date = datetime.datetime.strptime(date + ' 00:00:00', '%Y-%m-%d %H:%M:%S')
  File "D:\ProgramData\Miniconda3\envs\comp8715\lib\_strptime.py", line 577, in _strptime_datetime
    tt, fraction, gmtoff_fraction = _strptime(data_string, format)
  File "D:\ProgramData\Miniconda3\envs\comp8715\lib\_strptime.py", line 359, in _strptime
    (data_string, format))
ValueError: time data '2008-01- 00:00:00' does not match format '%Y-%m-%d %H:%M:%S'
[2020-04-21 17:44:45,856][app.py:1891][ERROR][7336] - Exception on /searchSatellite [GET]
Traceback (most recent call last):
  File "D:\ProgramData\Miniconda3\envs\comp8715\lib\site-packages\flask\app.py", line 2446, in wsgi_app
    response = self.full_dispatch_request()
  File "D:\ProgramData\Miniconda3\envs\comp8715\lib\site-packages\flask\app.py", line 1951, in full_dispatch_request
    rv = self.handle_user_exception(e)
  File "D:\ProgramData\Miniconda3\envs\comp8715\lib\site-packages\flask_cors\extension.py", line 161, in wrapped_function
    return cors_after_request(app.make_response(f(*args, **kwargs)))
  File "D:\ProgramData\Miniconda3\envs\comp8715\lib\site-packages\flask\app.py", line 1820, in handle_user_exception
    reraise(exc_type, exc_value, tb)
  File "D:\ProgramData\Miniconda3\envs\comp8715\lib\site-packages\flask\_compat.py", line 39, in reraise
    raise value
  File "D:\ProgramData\Miniconda3\envs\comp8715\lib\site-packages\flask\app.py", line 1949, in full_dispatch_request
    rv = self.dispatch_request()
  File "D:\ProgramData\Miniconda3\envs\comp8715\lib\site-packages\flask\app.py", line 1935, in dispatch_request
    return self.view_functions[rule.endpoint](**req.view_args)
  File "D:\TedZhang\Courses\COMP8715\SAT-Track\server\views\view.py", line 138, in search_satellite
    status, satellites = controll_search_satellites(user_id, user_input)
  File "D:\TedZhang\Courses\COMP8715\SAT-Track\server\controllers\user_behavior_controller.py", line 69, in controll_search_satellites
    satellite_lst = search_satellites_from_es(user_input)
  File "D:\TedZhang\Courses\COMP8715\SAT-Track\server\services\satellite_search_service.py", line 188, in search_satellites_from_es
    search_body = turn_to_query_body(classes, user_input)
  File "D:\TedZhang\Courses\COMP8715\SAT-Track\server\services\satellite_search_service.py", line 138, in turn_to_query_body
    must.append({'match': {'launch_unixtime': to_date(classes)[1]}})
  File "D:\TedZhang\Courses\COMP8715\SAT-Track\server\services\satellite_search_service.py", line 123, in to_date
    return ripe_date, Utils.to_all_unixtime(ripe_date)
  File "D:\TedZhang\Courses\COMP8715\SAT-Track\utilities\utils.py", line 32, in to_all_unixtime
    date = datetime.datetime.strptime(date + ' 00:00:00', '%Y-%m-%d %H:%M:%S')
  File "D:\ProgramData\Miniconda3\envs\comp8715\lib\_strptime.py", line 577, in _strptime_datetime
    tt, fraction, gmtoff_fraction = _strptime(data_string, format)
  File "D:\ProgramData\Miniconda3\envs\comp8715\lib\_strptime.py", line 359, in _strptime
    (data_string, format))
ValueError: time data '2010-06- 00:00:00' does not match format '%Y-%m-%d %H:%M:%S'
[2020-04-21 18:30:24,024][app.py:1891][ERROR][7852] - Exception on /searchSatellite [GET]
Traceback (most recent call last):
  File "D:\ProgramData\Miniconda3\envs\comp8715\lib\site-packages\flask\app.py", line 2446, in wsgi_app
    response = self.full_dispatch_request()
  File "D:\ProgramData\Miniconda3\envs\comp8715\lib\site-packages\flask\app.py", line 1951, in full_dispatch_request
    rv = self.handle_user_exception(e)
  File "D:\ProgramData\Miniconda3\envs\comp8715\lib\site-packages\flask_cors\extension.py", line 161, in wrapped_function
    return cors_after_request(app.make_response(f(*args, **kwargs)))
  File "D:\ProgramData\Miniconda3\envs\comp8715\lib\site-packages\flask\app.py", line 1820, in handle_user_exception
    reraise(exc_type, exc_value, tb)
  File "D:\ProgramData\Miniconda3\envs\comp8715\lib\site-packages\flask\_compat.py", line 39, in reraise
    raise value
  File "D:\ProgramData\Miniconda3\envs\comp8715\lib\site-packages\flask\app.py", line 1949, in full_dispatch_request
    rv = self.dispatch_request()
  File "D:\ProgramData\Miniconda3\envs\comp8715\lib\site-packages\flask\app.py", line 1935, in dispatch_request
    return self.view_functions[rule.endpoint](**req.view_args)
  File "D:\TedZhang\Courses\COMP8715\SAT-Track\server\views\view.py", line 138, in search_satellite
    status, satellites = controll_search_satellites(user_id, user_input)
  File "D:\TedZhang\Courses\COMP8715\SAT-Track\server\controllers\user_behavior_controller.py", line 69, in controll_search_satellites
    satellite_lst = search_satellites_from_es(user_input)
  File "D:\TedZhang\Courses\COMP8715\SAT-Track\server\services\satellite_search_service.py", line 188, in search_satellites_from_es
    search_body = turn_to_query_body(classes, user_input)
  File "D:\TedZhang\Courses\COMP8715\SAT-Track\server\services\satellite_search_service.py", line 138, in turn_to_query_body
    must.append({'match': {'launch_unixtime': to_date(classes)[1]}})
  File "D:\TedZhang\Courses\COMP8715\SAT-Track\server\services\satellite_search_service.py", line 123, in to_date
    return ripe_date, Utils.to_all_unixtime(ripe_date)
  File "D:\TedZhang\Courses\COMP8715\SAT-Track\utilities\utils.py", line 32, in to_all_unixtime
    date = datetime.datetime.strptime(date + ' 00:00:00', '%Y-%m-%d %H:%M:%S')
  File "D:\ProgramData\Miniconda3\envs\comp8715\lib\_strptime.py", line 577, in _strptime_datetime
    tt, fraction, gmtoff_fraction = _strptime(data_string, format)
  File "D:\ProgramData\Miniconda3\envs\comp8715\lib\_strptime.py", line 359, in _strptime
    (data_string, format))
ValueError: time data '1998-11- 00:00:00' does not match format '%Y-%m-%d %H:%M:%S'
[2020-04-21 18:33:26,985][app.py:1891][ERROR][7564] - Exception on /searchSatellite [GET]
Traceback (most recent call last):
  File "D:\ProgramData\Miniconda3\envs\comp8715\lib\site-packages\flask\app.py", line 2446, in wsgi_app
    response = self.full_dispatch_request()
  File "D:\ProgramData\Miniconda3\envs\comp8715\lib\site-packages\flask\app.py", line 1951, in full_dispatch_request
    rv = self.handle_user_exception(e)
  File "D:\ProgramData\Miniconda3\envs\comp8715\lib\site-packages\flask_cors\extension.py", line 161, in wrapped_function
    return cors_after_request(app.make_response(f(*args, **kwargs)))
  File "D:\ProgramData\Miniconda3\envs\comp8715\lib\site-packages\flask\app.py", line 1820, in handle_user_exception
    reraise(exc_type, exc_value, tb)
  File "D:\ProgramData\Miniconda3\envs\comp8715\lib\site-packages\flask\_compat.py", line 39, in reraise
    raise value
  File "D:\ProgramData\Miniconda3\envs\comp8715\lib\site-packages\flask\app.py", line 1949, in full_dispatch_request
    rv = self.dispatch_request()
  File "D:\ProgramData\Miniconda3\envs\comp8715\lib\site-packages\flask\app.py", line 1935, in dispatch_request
    return self.view_functions[rule.endpoint](**req.view_args)
  File "D:\TedZhang\Courses\COMP8715\SAT-Track\server\views\view.py", line 138, in search_satellite
    status, satellites = controll_search_satellites(user_id, user_input)
  File "D:\TedZhang\Courses\COMP8715\SAT-Track\server\controllers\user_behavior_controller.py", line 69, in controll_search_satellites
    satellite_lst = search_satellites_from_es(user_input)
  File "D:\TedZhang\Courses\COMP8715\SAT-Track\server\services\satellite_search_service.py", line 188, in search_satellites_from_es
    search_body = turn_to_query_body(classes, user_input)
  File "D:\TedZhang\Courses\COMP8715\SAT-Track\server\services\satellite_search_service.py", line 138, in turn_to_query_body
    must.append({'match': {'launch_unixtime': to_date(classes)[1]}})
  File "D:\TedZhang\Courses\COMP8715\SAT-Track\server\services\satellite_search_service.py", line 123, in to_date
    return ripe_date, Utils.to_all_unixtime(ripe_date)
  File "D:\TedZhang\Courses\COMP8715\SAT-Track\utilities\utils.py", line 32, in to_all_unixtime
    date = datetime.datetime.strptime(date + ' 00:00:00', '%Y-%m-%d %H:%M:%S')
  File "D:\ProgramData\Miniconda3\envs\comp8715\lib\_strptime.py", line 577, in _strptime_datetime
    tt, fraction, gmtoff_fraction = _strptime(data_string, format)
  File "D:\ProgramData\Miniconda3\envs\comp8715\lib\_strptime.py", line 359, in _strptime
    (data_string, format))
ValueError: time data '1998-11- 00:00:00' does not match format '%Y-%m-%d %H:%M:%S'
[2020-04-21 18:34:59,496][app.py:1891][ERROR][8420] - Exception on /searchSatellite [GET]
Traceback (most recent call last):
  File "D:\ProgramData\Miniconda3\envs\comp8715\lib\site-packages\flask\app.py", line 2446, in wsgi_app
    response = self.full_dispatch_request()
  File "D:\ProgramData\Miniconda3\envs\comp8715\lib\site-packages\flask\app.py", line 1951, in full_dispatch_request
    rv = self.handle_user_exception(e)
  File "D:\ProgramData\Miniconda3\envs\comp8715\lib\site-packages\flask_cors\extension.py", line 161, in wrapped_function
    return cors_after_request(app.make_response(f(*args, **kwargs)))
  File "D:\ProgramData\Miniconda3\envs\comp8715\lib\site-packages\flask\app.py", line 1820, in handle_user_exception
    reraise(exc_type, exc_value, tb)
  File "D:\ProgramData\Miniconda3\envs\comp8715\lib\site-packages\flask\_compat.py", line 39, in reraise
    raise value
  File "D:\ProgramData\Miniconda3\envs\comp8715\lib\site-packages\flask\app.py", line 1949, in full_dispatch_request
    rv = self.dispatch_request()
  File "D:\ProgramData\Miniconda3\envs\comp8715\lib\site-packages\flask\app.py", line 1935, in dispatch_request
    return self.view_functions[rule.endpoint](**req.view_args)
  File "D:\TedZhang\Courses\COMP8715\SAT-Track\server\views\view.py", line 138, in search_satellite
    status, satellites = controll_search_satellites(user_id, user_input)
  File "D:\TedZhang\Courses\COMP8715\SAT-Track\server\controllers\user_behavior_controller.py", line 69, in controll_search_satellites
    satellite_lst = search_satellites_from_es(user_input)
  File "D:\TedZhang\Courses\COMP8715\SAT-Track\server\services\satellite_search_service.py", line 189, in search_satellites_from_es
    search_body = turn_to_query_body(classes, user_input)
  File "D:\TedZhang\Courses\COMP8715\SAT-Track\server\services\satellite_search_service.py", line 139, in turn_to_query_body
    must.append({'match': {'launch_unixtime': to_date(classes)[1]}})
  File "D:\TedZhang\Courses\COMP8715\SAT-Track\server\services\satellite_search_service.py", line 124, in to_date
    return ripe_date, Utils.to_all_unixtime(ripe_date)
  File "D:\TedZhang\Courses\COMP8715\SAT-Track\utilities\utils.py", line 32, in to_all_unixtime
    date = datetime.datetime.strptime(date + ' 00:00:00', '%Y-%m-%d %H:%M:%S')
  File "D:\ProgramData\Miniconda3\envs\comp8715\lib\_strptime.py", line 577, in _strptime_datetime
    tt, fraction, gmtoff_fraction = _strptime(data_string, format)
  File "D:\ProgramData\Miniconda3\envs\comp8715\lib\_strptime.py", line 359, in _strptime
    (data_string, format))
ValueError: time data '1998-11- 00:00:00' does not match format '%Y-%m-%d %H:%M:%S'
[2020-04-21 18:35:28,796][app.py:1891][ERROR][14048] - Exception on /searchSatellite [GET]
Traceback (most recent call last):
  File "D:\ProgramData\Miniconda3\envs\comp8715\lib\site-packages\flask\app.py", line 2446, in wsgi_app
    response = self.full_dispatch_request()
  File "D:\ProgramData\Miniconda3\envs\comp8715\lib\site-packages\flask\app.py", line 1951, in full_dispatch_request
    rv = self.handle_user_exception(e)
  File "D:\ProgramData\Miniconda3\envs\comp8715\lib\site-packages\flask_cors\extension.py", line 161, in wrapped_function
    return cors_after_request(app.make_response(f(*args, **kwargs)))
  File "D:\ProgramData\Miniconda3\envs\comp8715\lib\site-packages\flask\app.py", line 1820, in handle_user_exception
    reraise(exc_type, exc_value, tb)
  File "D:\ProgramData\Miniconda3\envs\comp8715\lib\site-packages\flask\_compat.py", line 39, in reraise
    raise value
  File "D:\ProgramData\Miniconda3\envs\comp8715\lib\site-packages\flask\app.py", line 1949, in full_dispatch_request
    rv = self.dispatch_request()
  File "D:\ProgramData\Miniconda3\envs\comp8715\lib\site-packages\flask\app.py", line 1935, in dispatch_request
    return self.view_functions[rule.endpoint](**req.view_args)
  File "D:\TedZhang\Courses\COMP8715\SAT-Track\server\views\view.py", line 138, in search_satellite
    status, satellites = controll_search_satellites(user_id, user_input)
  File "D:\TedZhang\Courses\COMP8715\SAT-Track\server\controllers\user_behavior_controller.py", line 69, in controll_search_satellites
    satellite_lst = search_satellites_from_es(user_input)
  File "D:\TedZhang\Courses\COMP8715\SAT-Track\server\services\satellite_search_service.py", line 189, in search_satellites_from_es
    search_body = turn_to_query_body(classes, user_input)
  File "D:\TedZhang\Courses\COMP8715\SAT-Track\server\services\satellite_search_service.py", line 139, in turn_to_query_body
    must.append({'match': {'launch_unixtime': to_date(classes)[1]}})
  File "D:\TedZhang\Courses\COMP8715\SAT-Track\server\services\satellite_search_service.py", line 124, in to_date
    return ripe_date, Utils.to_all_unixtime(ripe_date)
  File "D:\TedZhang\Courses\COMP8715\SAT-Track\utilities\utils.py", line 32, in to_all_unixtime
    date = datetime.datetime.strptime(date + ' 00:00:00', '%Y-%m-%d %H:%M:%S')
  File "D:\ProgramData\Miniconda3\envs\comp8715\lib\_strptime.py", line 577, in _strptime_datetime
    tt, fraction, gmtoff_fraction = _strptime(data_string, format)
  File "D:\ProgramData\Miniconda3\envs\comp8715\lib\_strptime.py", line 359, in _strptime
    (data_string, format))
ValueError: time data '1998-11- 00:00:00' does not match format '%Y-%m-%d %H:%M:%S'
[2020-04-21 18:36:10,179][app.py:1891][ERROR][13816] - Exception on /searchSatellite [GET]
Traceback (most recent call last):
  File "D:\ProgramData\Miniconda3\envs\comp8715\lib\site-packages\flask\app.py", line 2446, in wsgi_app
    response = self.full_dispatch_request()
  File "D:\ProgramData\Miniconda3\envs\comp8715\lib\site-packages\flask\app.py", line 1951, in full_dispatch_request
    rv = self.handle_user_exception(e)
  File "D:\ProgramData\Miniconda3\envs\comp8715\lib\site-packages\flask_cors\extension.py", line 161, in wrapped_function
    return cors_after_request(app.make_response(f(*args, **kwargs)))
  File "D:\ProgramData\Miniconda3\envs\comp8715\lib\site-packages\flask\app.py", line 1820, in handle_user_exception
    reraise(exc_type, exc_value, tb)
  File "D:\ProgramData\Miniconda3\envs\comp8715\lib\site-packages\flask\_compat.py", line 39, in reraise
    raise value
  File "D:\ProgramData\Miniconda3\envs\comp8715\lib\site-packages\flask\app.py", line 1949, in full_dispatch_request
    rv = self.dispatch_request()
  File "D:\ProgramData\Miniconda3\envs\comp8715\lib\site-packages\flask\app.py", line 1935, in dispatch_request
    return self.view_functions[rule.endpoint](**req.view_args)
  File "D:\TedZhang\Courses\COMP8715\SAT-Track\server\views\view.py", line 138, in search_satellite
    status, satellites = controll_search_satellites(user_id, user_input)
  File "D:\TedZhang\Courses\COMP8715\SAT-Track\server\controllers\user_behavior_controller.py", line 69, in controll_search_satellites
    satellite_lst = search_satellites_from_es(user_input)
  File "D:\TedZhang\Courses\COMP8715\SAT-Track\server\services\satellite_search_service.py", line 190, in search_satellites_from_es
    search_body = turn_to_query_body(classes, user_input)
  File "D:\TedZhang\Courses\COMP8715\SAT-Track\server\services\satellite_search_service.py", line 140, in turn_to_query_body
    must.append({'match': {'launch_unixtime': to_date(classes)[1]}})
  File "D:\TedZhang\Courses\COMP8715\SAT-Track\server\services\satellite_search_service.py", line 125, in to_date
    return ripe_date, Utils.to_all_unixtime(ripe_date)
  File "D:\TedZhang\Courses\COMP8715\SAT-Track\utilities\utils.py", line 32, in to_all_unixtime
    date = datetime.datetime.strptime(date + ' 00:00:00', '%Y-%m-%d %H:%M:%S')
  File "D:\ProgramData\Miniconda3\envs\comp8715\lib\_strptime.py", line 577, in _strptime_datetime
    tt, fraction, gmtoff_fraction = _strptime(data_string, format)
  File "D:\ProgramData\Miniconda3\envs\comp8715\lib\_strptime.py", line 359, in _strptime
    (data_string, format))
ValueError: time data '1998-11- 00:00:00' does not match format '%Y-%m-%d %H:%M:%S'
[2020-04-21 21:06:47,471][app.py:1891][ERROR][14132] - Exception on /searchSatellite [GET]
Traceback (most recent call last):
  File "D:\ProgramData\Miniconda3\envs\comp8715\lib\site-packages\flask\app.py", line 2446, in wsgi_app
    response = self.full_dispatch_request()
  File "D:\ProgramData\Miniconda3\envs\comp8715\lib\site-packages\flask\app.py", line 1951, in full_dispatch_request
    rv = self.handle_user_exception(e)
  File "D:\ProgramData\Miniconda3\envs\comp8715\lib\site-packages\flask_cors\extension.py", line 161, in wrapped_function
    return cors_after_request(app.make_response(f(*args, **kwargs)))
  File "D:\ProgramData\Miniconda3\envs\comp8715\lib\site-packages\flask\app.py", line 1820, in handle_user_exception
    reraise(exc_type, exc_value, tb)
  File "D:\ProgramData\Miniconda3\envs\comp8715\lib\site-packages\flask\_compat.py", line 39, in reraise
    raise value
  File "D:\ProgramData\Miniconda3\envs\comp8715\lib\site-packages\flask\app.py", line 1949, in full_dispatch_request
    rv = self.dispatch_request()
  File "D:\ProgramData\Miniconda3\envs\comp8715\lib\site-packages\flask\app.py", line 1935, in dispatch_request
    return self.view_functions[rule.endpoint](**req.view_args)
  File "D:\TedZhang\Courses\COMP8715\SAT-Track\server\views\view.py", line 138, in search_satellite
    status, satellites = controll_search_satellites(user_id, user_input)
  File "D:\TedZhang\Courses\COMP8715\SAT-Track\server\controllers\user_behavior_controller.py", line 69, in controll_search_satellites
    satellite_lst = search_satellites_from_es(user_input)
  File "D:\TedZhang\Courses\COMP8715\SAT-Track\server\services\satellite_search_service.py", line 191, in search_satellites_from_es
    search_body = turn_to_query_body(classes, user_input)
  File "D:\TedZhang\Courses\COMP8715\SAT-Track\server\services\satellite_search_service.py", line 142, in turn_to_query_body
    and ((k == 'is_number' or k == 'is_year' or k == 'is_month' or k == 'is_day') and classes['is_date'][0][0] >= 0.6):
TypeError: '>=' not supported between instances of 'str' and 'float'
[2020-04-21 21:24:56,932][app.py:1891][ERROR][7700] - Exception on /searchSatellite [GET]
Traceback (most recent call last):
  File "D:\ProgramData\Miniconda3\envs\comp8715\lib\site-packages\flask\app.py", line 2446, in wsgi_app
    response = self.full_dispatch_request()
  File "D:\ProgramData\Miniconda3\envs\comp8715\lib\site-packages\flask\app.py", line 1951, in full_dispatch_request
    rv = self.handle_user_exception(e)
  File "D:\ProgramData\Miniconda3\envs\comp8715\lib\site-packages\flask_cors\extension.py", line 161, in wrapped_function
    return cors_after_request(app.make_response(f(*args, **kwargs)))
  File "D:\ProgramData\Miniconda3\envs\comp8715\lib\site-packages\flask\app.py", line 1820, in handle_user_exception
    reraise(exc_type, exc_value, tb)
  File "D:\ProgramData\Miniconda3\envs\comp8715\lib\site-packages\flask\_compat.py", line 39, in reraise
    raise value
  File "D:\ProgramData\Miniconda3\envs\comp8715\lib\site-packages\flask\app.py", line 1949, in full_dispatch_request
    rv = self.dispatch_request()
  File "D:\ProgramData\Miniconda3\envs\comp8715\lib\site-packages\flask\app.py", line 1935, in dispatch_request
    return self.view_functions[rule.endpoint](**req.view_args)
  File "D:\TedZhang\Courses\COMP8715\SAT-Track\server\views\view.py", line 138, in search_satellite
    status, satellites = controll_search_satellites(user_id, user_input)
  File "D:\TedZhang\Courses\COMP8715\SAT-Track\server\controllers\user_behavior_controller.py", line 69, in controll_search_satellites
    satellite_lst = search_satellites_from_es(user_input)
  File "D:\TedZhang\Courses\COMP8715\SAT-Track\server\services\satellite_search_service.py", line 195, in search_satellites_from_es
    res = satellite_database.search_by_body(search_body)
  File "D:\TedZhang\Courses\COMP8715\SAT-Track\utilities\es_io.py", line 137, in search_by_body
    response = es.search(index=self.table, size=conf.ES_QUERY_MAX_SIZE, body=body)
  File "D:\ProgramData\Miniconda3\envs\comp8715\lib\site-packages\elasticsearch\client\utils.py", line 84, in _wrapped
    return func(*args, params=params, **kwargs)
  File "D:\ProgramData\Miniconda3\envs\comp8715\lib\site-packages\elasticsearch\client\__init__.py", line 811, in search
    "GET", _make_path(index, "_search"), params=params, body=body
  File "D:\ProgramData\Miniconda3\envs\comp8715\lib\site-packages\elasticsearch\transport.py", line 358, in perform_request
    timeout=timeout,
  File "D:\ProgramData\Miniconda3\envs\comp8715\lib\site-packages\elasticsearch\connection\http_urllib3.py", line 257, in perform_request
    self._raise_error(response.status, raw_data)
  File "D:\ProgramData\Miniconda3\envs\comp8715\lib\site-packages\elasticsearch\connection\base.py", line 182, in _raise_error
    status_code, error_message, additional_info
elasticsearch.exceptions.RequestError: RequestError(400, 'parsing_exception', "[fuzzy] query doesn't support multiple fields, found [extract] and [fuzziness]")
[2020-04-22 00:46:32,153][app.py:1891][ERROR][12244] - Exception on /searchSatellite [GET]
Traceback (most recent call last):
  File "D:\ProgramData\Miniconda3\envs\comp8715\lib\site-packages\flask\app.py", line 2446, in wsgi_app
    response = self.full_dispatch_request()
  File "D:\ProgramData\Miniconda3\envs\comp8715\lib\site-packages\flask\app.py", line 1951, in full_dispatch_request
    rv = self.handle_user_exception(e)
  File "D:\ProgramData\Miniconda3\envs\comp8715\lib\site-packages\flask_cors\extension.py", line 161, in wrapped_function
    return cors_after_request(app.make_response(f(*args, **kwargs)))
  File "D:\ProgramData\Miniconda3\envs\comp8715\lib\site-packages\flask\app.py", line 1820, in handle_user_exception
    reraise(exc_type, exc_value, tb)
  File "D:\ProgramData\Miniconda3\envs\comp8715\lib\site-packages\flask\_compat.py", line 39, in reraise
    raise value
  File "D:\ProgramData\Miniconda3\envs\comp8715\lib\site-packages\flask\app.py", line 1949, in full_dispatch_request
    rv = self.dispatch_request()
  File "D:\ProgramData\Miniconda3\envs\comp8715\lib\site-packages\flask\app.py", line 1935, in dispatch_request
    return self.view_functions[rule.endpoint](**req.view_args)
  File "D:\TedZhang\Courses\COMP8715\SAT-Track\server\views\view.py", line 138, in search_satellite
    status, satellites = controll_search_satellites(user_id, user_input)
  File "D:\TedZhang\Courses\COMP8715\SAT-Track\server\controllers\user_behavior_controller.py", line 72, in controll_search_satellites
    print(len(satellite_lst))
TypeError: object of type 'NoneType' has no len()
[2020-04-22 02:07:38,645][app.py:1891][ERROR][6132] - Exception on /searchSatellite [GET]
Traceback (most recent call last):
  File "D:\ProgramData\Miniconda3\envs\comp8715\lib\site-packages\flask\app.py", line 2446, in wsgi_app
    response = self.full_dispatch_request()
  File "D:\ProgramData\Miniconda3\envs\comp8715\lib\site-packages\flask\app.py", line 1951, in full_dispatch_request
    rv = self.handle_user_exception(e)
  File "D:\ProgramData\Miniconda3\envs\comp8715\lib\site-packages\flask_cors\extension.py", line 161, in wrapped_function
    return cors_after_request(app.make_response(f(*args, **kwargs)))
  File "D:\ProgramData\Miniconda3\envs\comp8715\lib\site-packages\flask\app.py", line 1820, in handle_user_exception
    reraise(exc_type, exc_value, tb)
  File "D:\ProgramData\Miniconda3\envs\comp8715\lib\site-packages\flask\_compat.py", line 39, in reraise
    raise value
  File "D:\ProgramData\Miniconda3\envs\comp8715\lib\site-packages\flask\app.py", line 1949, in full_dispatch_request
    rv = self.dispatch_request()
  File "D:\ProgramData\Miniconda3\envs\comp8715\lib\site-packages\flask\app.py", line 1935, in dispatch_request
    return self.view_functions[rule.endpoint](**req.view_args)
  File "D:\TedZhang\Courses\COMP8715\SAT-Track\server\views\view.py", line 138, in search_satellite
    status, satellites, beyond_lmt = controll_search_satellites(user_id, user_input)
  File "D:\TedZhang\Courses\COMP8715\SAT-Track\server\controllers\user_behavior_controller.py", line 69, in controll_search_satellites
    satellite_lst = search_satellites_from_es(user_input)
  File "D:\TedZhang\Courses\COMP8715\SAT-Track\server\services\satellite_search_service.py", line 195, in search_satellites_from_es
    search_body, like_norad_ids = turn_to_query_body(classes, user_input)
  File "D:\TedZhang\Courses\COMP8715\SAT-Track\server\services\satellite_search_service.py", line 145, in turn_to_query_body
    like_norad_ids.add(int(hit[0]))
ValueError: invalid literal for int() with base 10: 'mar'
[2020-04-22 02:11:20,171][app.py:1891][ERROR][14812] - Exception on /searchSatellite [GET]
Traceback (most recent call last):
  File "D:\ProgramData\Miniconda3\envs\comp8715\lib\site-packages\flask\app.py", line 2446, in wsgi_app
    response = self.full_dispatch_request()
  File "D:\ProgramData\Miniconda3\envs\comp8715\lib\site-packages\flask\app.py", line 1951, in full_dispatch_request
    rv = self.handle_user_exception(e)
  File "D:\ProgramData\Miniconda3\envs\comp8715\lib\site-packages\flask_cors\extension.py", line 161, in wrapped_function
    return cors_after_request(app.make_response(f(*args, **kwargs)))
  File "D:\ProgramData\Miniconda3\envs\comp8715\lib\site-packages\flask\app.py", line 1820, in handle_user_exception
    reraise(exc_type, exc_value, tb)
  File "D:\ProgramData\Miniconda3\envs\comp8715\lib\site-packages\flask\_compat.py", line 39, in reraise
    raise value
  File "D:\ProgramData\Miniconda3\envs\comp8715\lib\site-packages\flask\app.py", line 1949, in full_dispatch_request
    rv = self.dispatch_request()
  File "D:\ProgramData\Miniconda3\envs\comp8715\lib\site-packages\flask\app.py", line 1935, in dispatch_request
    return self.view_functions[rule.endpoint](**req.view_args)
  File "D:\TedZhang\Courses\COMP8715\SAT-Track\server\views\view.py", line 138, in search_satellite
    status, satellites, beyond_lmt = controll_search_satellites(user_id, user_input)
  File "D:\TedZhang\Courses\COMP8715\SAT-Track\server\controllers\user_behavior_controller.py", line 69, in controll_search_satellites
    satellite_lst = search_satellites_from_es(user_input)
  File "D:\TedZhang\Courses\COMP8715\SAT-Track\server\services\satellite_search_service.py", line 199, in search_satellites_from_es
    search_body, like_norad_ids = turn_to_query_body(classes, user_input)
  File "D:\TedZhang\Courses\COMP8715\SAT-Track\server\services\satellite_search_service.py", line 154, in turn_to_query_body
    if 0.5 <= k == 'is_date' and classes[k][0][1] < 0.7:
TypeError: '<=' not supported between instances of 'float' and 'str'
[2020-04-22 19:42:44,922][app.py:1891][ERROR][10348] - Exception on /searchSatellite [GET]
Traceback (most recent call last):
  File "D:\ProgramData\Miniconda3\envs\comp8715\lib\site-packages\flask\app.py", line 2446, in wsgi_app
    response = self.full_dispatch_request()
  File "D:\ProgramData\Miniconda3\envs\comp8715\lib\site-packages\flask\app.py", line 1951, in full_dispatch_request
    rv = self.handle_user_exception(e)
  File "D:\ProgramData\Miniconda3\envs\comp8715\lib\site-packages\flask_cors\extension.py", line 161, in wrapped_function
    return cors_after_request(app.make_response(f(*args, **kwargs)))
  File "D:\ProgramData\Miniconda3\envs\comp8715\lib\site-packages\flask\app.py", line 1820, in handle_user_exception
    reraise(exc_type, exc_value, tb)
  File "D:\ProgramData\Miniconda3\envs\comp8715\lib\site-packages\flask\_compat.py", line 39, in reraise
    raise value
  File "D:\ProgramData\Miniconda3\envs\comp8715\lib\site-packages\flask\app.py", line 1949, in full_dispatch_request
    rv = self.dispatch_request()
  File "D:\ProgramData\Miniconda3\envs\comp8715\lib\site-packages\flask\app.py", line 1935, in dispatch_request
    return self.view_functions[rule.endpoint](**req.view_args)
  File "D:\TedZhang\Courses\COMP8715\SAT-Track\server\views\view.py", line 138, in search_satellite
    status, satellites, beyond_lmt = controll_search_satellites(user_id, user_input)
  File "D:\TedZhang\Courses\COMP8715\SAT-Track\server\controllers\user_behavior_controller.py", line 69, in controll_search_satellites
    satellite_lst = search_satellites_from_es(user_input)
  File "D:\TedZhang\Courses\COMP8715\SAT-Track\server\services\satellite_search_service.py", line 203, in search_satellites_from_es
    search_body, like_norad_ids = turn_to_query_body(classes, user_input)
  File "D:\TedZhang\Courses\COMP8715\SAT-Track\server\services\satellite_search_service.py", line 149, in turn_to_query_body
    like_norad_ids.add(int(hit[0]))
ValueError: invalid literal for int() with base 10: 'mar'
[2020-04-22 19:43:38,715][app.py:1891][ERROR][11256] - Exception on /searchSatellite [GET]
Traceback (most recent call last):
  File "D:\ProgramData\Miniconda3\envs\comp8715\lib\site-packages\flask\app.py", line 2446, in wsgi_app
    response = self.full_dispatch_request()
  File "D:\ProgramData\Miniconda3\envs\comp8715\lib\site-packages\flask\app.py", line 1951, in full_dispatch_request
    rv = self.handle_user_exception(e)
  File "D:\ProgramData\Miniconda3\envs\comp8715\lib\site-packages\flask_cors\extension.py", line 161, in wrapped_function
    return cors_after_request(app.make_response(f(*args, **kwargs)))
  File "D:\ProgramData\Miniconda3\envs\comp8715\lib\site-packages\flask\app.py", line 1820, in handle_user_exception
    reraise(exc_type, exc_value, tb)
  File "D:\ProgramData\Miniconda3\envs\comp8715\lib\site-packages\flask\_compat.py", line 39, in reraise
    raise value
  File "D:\ProgramData\Miniconda3\envs\comp8715\lib\site-packages\flask\app.py", line 1949, in full_dispatch_request
    rv = self.dispatch_request()
  File "D:\ProgramData\Miniconda3\envs\comp8715\lib\site-packages\flask\app.py", line 1935, in dispatch_request
    return self.view_functions[rule.endpoint](**req.view_args)
  File "D:\TedZhang\Courses\COMP8715\SAT-Track\server\views\view.py", line 138, in search_satellite
    status, satellites, beyond_lmt = controll_search_satellites(user_id, user_input)
  File "D:\TedZhang\Courses\COMP8715\SAT-Track\server\controllers\user_behavior_controller.py", line 69, in controll_search_satellites
    satellite_lst = search_satellites_from_es(user_input)
  File "D:\TedZhang\Courses\COMP8715\SAT-Track\server\services\satellite_search_service.py", line 206, in search_satellites_from_es
    search_body, like_norad_ids = turn_to_query_body(classes, user_input)
  File "D:\TedZhang\Courses\COMP8715\SAT-Track\server\services\satellite_search_service.py", line 162, in turn_to_query_body
    must.append({'match': {'launch_date_text': to_date(classes)[2]}})
  File "D:\TedZhang\Courses\COMP8715\SAT-Track\server\services\satellite_search_service.py", line 117, in to_date
    for s in day_hit[0]:
IndexError: list index out of range
[2020-04-22 19:44:22,046][app.py:1891][ERROR][13552] - Exception on /searchSatellite [GET]
Traceback (most recent call last):
  File "D:\ProgramData\Miniconda3\envs\comp8715\lib\site-packages\flask\app.py", line 2446, in wsgi_app
    response = self.full_dispatch_request()
  File "D:\ProgramData\Miniconda3\envs\comp8715\lib\site-packages\flask\app.py", line 1951, in full_dispatch_request
    rv = self.handle_user_exception(e)
  File "D:\ProgramData\Miniconda3\envs\comp8715\lib\site-packages\flask_cors\extension.py", line 161, in wrapped_function
    return cors_after_request(app.make_response(f(*args, **kwargs)))
  File "D:\ProgramData\Miniconda3\envs\comp8715\lib\site-packages\flask\app.py", line 1820, in handle_user_exception
    reraise(exc_type, exc_value, tb)
  File "D:\ProgramData\Miniconda3\envs\comp8715\lib\site-packages\flask\_compat.py", line 39, in reraise
    raise value
  File "D:\ProgramData\Miniconda3\envs\comp8715\lib\site-packages\flask\app.py", line 1949, in full_dispatch_request
    rv = self.dispatch_request()
  File "D:\ProgramData\Miniconda3\envs\comp8715\lib\site-packages\flask\app.py", line 1935, in dispatch_request
    return self.view_functions[rule.endpoint](**req.view_args)
  File "D:\TedZhang\Courses\COMP8715\SAT-Track\server\views\view.py", line 138, in search_satellite
    status, satellites, beyond_lmt = controll_search_satellites(user_id, user_input)
  File "D:\TedZhang\Courses\COMP8715\SAT-Track\server\controllers\user_behavior_controller.py", line 69, in controll_search_satellites
    satellite_lst = search_satellites_from_es(user_input)
  File "D:\TedZhang\Courses\COMP8715\SAT-Track\server\services\satellite_search_service.py", line 206, in search_satellites_from_es
    search_body, like_norad_ids = turn_to_query_body(classes, user_input)
  File "D:\TedZhang\Courses\COMP8715\SAT-Track\server\services\satellite_search_service.py", line 162, in turn_to_query_body
    must.append({'match': {'launch_date_text': to_date(classes)[2]}})
  File "D:\TedZhang\Courses\COMP8715\SAT-Track\server\services\satellite_search_service.py", line 127, in to_date
    return ripe_date, Utils.to_all_unixtime(ripe_date), text_date
  File "D:\TedZhang\Courses\COMP8715\SAT-Track\utilities\utils.py", line 32, in to_all_unixtime
    date = datetime.datetime.strptime(date + ' 00:00:00', '%Y-%m-%d %H:%M:%S')
  File "D:\ProgramData\Miniconda3\envs\comp8715\lib\_strptime.py", line 577, in _strptime_datetime
    tt, fraction, gmtoff_fraction = _strptime(data_string, format)
  File "D:\ProgramData\Miniconda3\envs\comp8715\lib\_strptime.py", line 359, in _strptime
    (data_string, format))
ValueError: time data '1958-03-0 00:00:00' does not match format '%Y-%m-%d %H:%M:%S'
[2020-04-22 19:45:54,494][app.py:1891][ERROR][12668] - Exception on /searchSatellite [GET]
Traceback (most recent call last):
  File "D:\ProgramData\Miniconda3\envs\comp8715\lib\site-packages\flask\app.py", line 2446, in wsgi_app
    response = self.full_dispatch_request()
  File "D:\ProgramData\Miniconda3\envs\comp8715\lib\site-packages\flask\app.py", line 1951, in full_dispatch_request
    rv = self.handle_user_exception(e)
  File "D:\ProgramData\Miniconda3\envs\comp8715\lib\site-packages\flask_cors\extension.py", line 161, in wrapped_function
    return cors_after_request(app.make_response(f(*args, **kwargs)))
  File "D:\ProgramData\Miniconda3\envs\comp8715\lib\site-packages\flask\app.py", line 1820, in handle_user_exception
    reraise(exc_type, exc_value, tb)
  File "D:\ProgramData\Miniconda3\envs\comp8715\lib\site-packages\flask\_compat.py", line 39, in reraise
    raise value
  File "D:\ProgramData\Miniconda3\envs\comp8715\lib\site-packages\flask\app.py", line 1949, in full_dispatch_request
    rv = self.dispatch_request()
  File "D:\ProgramData\Miniconda3\envs\comp8715\lib\site-packages\flask\app.py", line 1935, in dispatch_request
    return self.view_functions[rule.endpoint](**req.view_args)
  File "D:\TedZhang\Courses\COMP8715\SAT-Track\server\views\view.py", line 138, in search_satellite
    status, satellites, beyond_lmt = controll_search_satellites(user_id, user_input)
  File "D:\TedZhang\Courses\COMP8715\SAT-Track\server\controllers\user_behavior_controller.py", line 69, in controll_search_satellites
    satellite_lst = search_satellites_from_es(user_input)
  File "D:\TedZhang\Courses\COMP8715\SAT-Track\server\services\satellite_search_service.py", line 207, in search_satellites_from_es
    search_body, like_norad_ids = turn_to_query_body(classes, user_input)
  File "D:\TedZhang\Courses\COMP8715\SAT-Track\server\services\satellite_search_service.py", line 163, in turn_to_query_body
    must.append({'match': {'launch_date_text': to_date(classes)[2]}})
  File "D:\TedZhang\Courses\COMP8715\SAT-Track\server\services\satellite_search_service.py", line 128, in to_date
    return ripe_date, Utils.to_all_unixtime(ripe_date), text_date
  File "D:\TedZhang\Courses\COMP8715\SAT-Track\utilities\utils.py", line 32, in to_all_unixtime
    date = datetime.datetime.strptime(date + ' 00:00:00', '%Y-%m-%d %H:%M:%S')
  File "D:\ProgramData\Miniconda3\envs\comp8715\lib\_strptime.py", line 577, in _strptime_datetime
    tt, fraction, gmtoff_fraction = _strptime(data_string, format)
  File "D:\ProgramData\Miniconda3\envs\comp8715\lib\_strptime.py", line 359, in _strptime
    (data_string, format))
ValueError: time data '1958-03-0 00:00:00' does not match format '%Y-%m-%d %H:%M:%S'
[2020-04-22 19:46:22,640][app.py:1891][ERROR][7280] - Exception on /searchSatellite [GET]
Traceback (most recent call last):
  File "D:\ProgramData\Miniconda3\envs\comp8715\lib\site-packages\flask\app.py", line 2446, in wsgi_app
    response = self.full_dispatch_request()
  File "D:\ProgramData\Miniconda3\envs\comp8715\lib\site-packages\flask\app.py", line 1951, in full_dispatch_request
    rv = self.handle_user_exception(e)
  File "D:\ProgramData\Miniconda3\envs\comp8715\lib\site-packages\flask_cors\extension.py", line 161, in wrapped_function
    return cors_after_request(app.make_response(f(*args, **kwargs)))
  File "D:\ProgramData\Miniconda3\envs\comp8715\lib\site-packages\flask\app.py", line 1820, in handle_user_exception
    reraise(exc_type, exc_value, tb)
  File "D:\ProgramData\Miniconda3\envs\comp8715\lib\site-packages\flask\_compat.py", line 39, in reraise
    raise value
  File "D:\ProgramData\Miniconda3\envs\comp8715\lib\site-packages\flask\app.py", line 1949, in full_dispatch_request
    rv = self.dispatch_request()
  File "D:\ProgramData\Miniconda3\envs\comp8715\lib\site-packages\flask\app.py", line 1935, in dispatch_request
    return self.view_functions[rule.endpoint](**req.view_args)
  File "D:\TedZhang\Courses\COMP8715\SAT-Track\server\views\view.py", line 138, in search_satellite
    status, satellites, beyond_lmt = controll_search_satellites(user_id, user_input)
  File "D:\TedZhang\Courses\COMP8715\SAT-Track\server\controllers\user_behavior_controller.py", line 69, in controll_search_satellites
    satellite_lst = search_satellites_from_es(user_input)
  File "D:\TedZhang\Courses\COMP8715\SAT-Track\server\services\satellite_search_service.py", line 208, in search_satellites_from_es
    search_body, like_norad_ids = turn_to_query_body(classes, user_input)
  File "D:\TedZhang\Courses\COMP8715\SAT-Track\server\services\satellite_search_service.py", line 164, in turn_to_query_body
    must.append({'match': {'launch_date_text': to_date(classes)[2]}})
  File "D:\TedZhang\Courses\COMP8715\SAT-Track\server\services\satellite_search_service.py", line 120, in to_date
    day = '0' + day if len(day) == 1 else day
TypeError: object of type 'int' has no len()
[2020-04-22 19:47:10,912][app.py:1891][ERROR][6600] - Exception on /searchSatellite [GET]
Traceback (most recent call last):
  File "D:\ProgramData\Miniconda3\envs\comp8715\lib\site-packages\flask\app.py", line 2446, in wsgi_app
    response = self.full_dispatch_request()
  File "D:\ProgramData\Miniconda3\envs\comp8715\lib\site-packages\flask\app.py", line 1951, in full_dispatch_request
    rv = self.handle_user_exception(e)
  File "D:\ProgramData\Miniconda3\envs\comp8715\lib\site-packages\flask_cors\extension.py", line 161, in wrapped_function
    return cors_after_request(app.make_response(f(*args, **kwargs)))
  File "D:\ProgramData\Miniconda3\envs\comp8715\lib\site-packages\flask\app.py", line 1820, in handle_user_exception
    reraise(exc_type, exc_value, tb)
  File "D:\ProgramData\Miniconda3\envs\comp8715\lib\site-packages\flask\_compat.py", line 39, in reraise
    raise value
  File "D:\ProgramData\Miniconda3\envs\comp8715\lib\site-packages\flask\app.py", line 1949, in full_dispatch_request
    rv = self.dispatch_request()
  File "D:\ProgramData\Miniconda3\envs\comp8715\lib\site-packages\flask\app.py", line 1935, in dispatch_request
    return self.view_functions[rule.endpoint](**req.view_args)
  File "D:\TedZhang\Courses\COMP8715\SAT-Track\server\views\view.py", line 138, in search_satellite
    status, satellites, beyond_lmt = controll_search_satellites(user_id, user_input)
  File "D:\TedZhang\Courses\COMP8715\SAT-Track\server\controllers\user_behavior_controller.py", line 69, in controll_search_satellites
    satellite_lst = search_satellites_from_es(user_input)
  File "D:\TedZhang\Courses\COMP8715\SAT-Track\server\services\satellite_search_service.py", line 208, in search_satellites_from_es
    search_body, like_norad_ids = turn_to_query_body(classes, user_input)
  File "D:\TedZhang\Courses\COMP8715\SAT-Track\server\services\satellite_search_service.py", line 164, in turn_to_query_body
    must.append({'match': {'launch_date_text': to_date(classes)[2]}})
  File "D:\TedZhang\Courses\COMP8715\SAT-Track\server\services\satellite_search_service.py", line 129, in to_date
    return ripe_date, Utils.to_all_unixtime(ripe_date), text_date
  File "D:\TedZhang\Courses\COMP8715\SAT-Track\utilities\utils.py", line 32, in to_all_unixtime
    date = datetime.datetime.strptime(date + ' 00:00:00', '%Y-%m-%d %H:%M:%S')
  File "D:\ProgramData\Miniconda3\envs\comp8715\lib\_strptime.py", line 577, in _strptime_datetime
    tt, fraction, gmtoff_fraction = _strptime(data_string, format)
  File "D:\ProgramData\Miniconda3\envs\comp8715\lib\_strptime.py", line 359, in _strptime
    (data_string, format))
ValueError: time data '1958-03-00 00:00:00' does not match format '%Y-%m-%d %H:%M:%S'
[2020-05-19 14:06:07,071][view.py:195][INFO][15264] - {"api_name": "http://127.0.0.1:5000/", "user_ip": "127.0.0.1", "status_code":"200"}
[2020-05-19 14:06:07,597][view.py:195][INFO][11100] - {"api_name": "http://127.0.0.1:5000/getUserInfo", "user_ip": "127.0.0.1", "status_code":"200"}
[2020-05-19 14:06:12,149][view.py:195][INFO][8284] - {"api_name": "http://127.0.0.1:5000/searchSatellite?input=oidsaa+", "user_ip": "127.0.0.1", "status_code":"200"}
[2020-05-19 14:06:14,092][view.py:195][INFO][10444] - {"api_name": "http://127.0.0.1:5000/searchSatellite?input=V", "user_ip": "127.0.0.1", "status_code":"200"}
[2020-05-19 14:06:37,048][view.py:195][INFO][956] - {"api_name": "http://127.0.0.1:5000/selectSatellite?id=25856", "user_ip": "127.0.0.1", "status_code":"200"}
[2020-05-19 14:09:08,012][view.py:195][INFO][10304] - {"api_name": "http://127.0.0.1:5000/", "user_ip": "127.0.0.1", "status_code":"200"}
[2020-05-19 14:09:08,679][view.py:195][INFO][12028] - {"api_name": "http://127.0.0.1:5000/getUserInfo", "user_ip": "127.0.0.1", "status_code":"200"}
[2020-05-19 14:09:11,550][view.py:195][INFO][15300] - {"api_name": "http://127.0.0.1:5000/searchSatellite?input=vv", "user_ip": "127.0.0.1", "status_code":"200"}
[2020-05-19 14:09:16,148][view.py:195][INFO][15144] - {"api_name": "http://127.0.0.1:5000/searchSatellite?input=v", "user_ip": "127.0.0.1", "status_code":"200"}
[2020-05-19 14:21:54,208][app.py:1891][ERROR][12960] - Exception on / [GET]
Traceback (most recent call last):
  File "D:\ProgramData\Miniconda3\envs\comp8715\lib\site-packages\flask\app.py", line 2446, in wsgi_app
    response = self.full_dispatch_request()
  File "D:\ProgramData\Miniconda3\envs\comp8715\lib\site-packages\flask\app.py", line 1951, in full_dispatch_request
    rv = self.handle_user_exception(e)
  File "D:\ProgramData\Miniconda3\envs\comp8715\lib\site-packages\flask_cors\extension.py", line 161, in wrapped_function
    return cors_after_request(app.make_response(f(*args, **kwargs)))
  File "D:\ProgramData\Miniconda3\envs\comp8715\lib\site-packages\flask\app.py", line 1820, in handle_user_exception
    reraise(exc_type, exc_value, tb)
  File "D:\ProgramData\Miniconda3\envs\comp8715\lib\site-packages\flask\_compat.py", line 39, in reraise
    raise value
  File "D:\ProgramData\Miniconda3\envs\comp8715\lib\site-packages\flask\app.py", line 1949, in full_dispatch_request
    rv = self.dispatch_request()
  File "D:\ProgramData\Miniconda3\envs\comp8715\lib\site-packages\flask\app.py", line 1935, in dispatch_request
    return self.view_functions[rule.endpoint](**req.view_args)
  File "D:\ProgramData\Miniconda3\envs\comp8715\lib\site-packages\flask_login\utils.py", line 270, in decorated_view
    elif not current_user.is_authenticated:
  File "D:\ProgramData\Miniconda3\envs\comp8715\lib\site-packages\werkzeug\local.py", line 347, in __getattr__
    return getattr(self._get_current_object(), name)
  File "D:\ProgramData\Miniconda3\envs\comp8715\lib\site-packages\werkzeug\local.py", line 306, in _get_current_object
    return self.__local()
  File "D:\ProgramData\Miniconda3\envs\comp8715\lib\site-packages\flask_login\utils.py", line 26, in <lambda>
    current_user = LocalProxy(lambda: _get_user())
  File "D:\ProgramData\Miniconda3\envs\comp8715\lib\site-packages\flask_login\utils.py", line 346, in _get_user
    current_app.login_manager._load_user()
  File "D:\ProgramData\Miniconda3\envs\comp8715\lib\site-packages\flask_login\login_manager.py", line 318, in _load_user
    user = self._user_callback(user_id)
  File "D:\TedZhang\Courses\COMP8715\SAT-Track\server\__init__.py", line 42, in load_user
    return UserManager.get(user_id)
  File "D:\TedZhang\Courses\COMP8715\SAT-Track\server\services\data_storage_service.py", line 23, in get
    ip=res['ip']
KeyError: 'ip'
[2020-05-19 14:21:54,314][app.py:1975][ERROR][12960] - Request finalizing failed with an error while handling an error
Traceback (most recent call last):
  File "D:\ProgramData\Miniconda3\envs\comp8715\lib\site-packages\flask\app.py", line 2446, in wsgi_app
    response = self.full_dispatch_request()
  File "D:\ProgramData\Miniconda3\envs\comp8715\lib\site-packages\flask\app.py", line 1951, in full_dispatch_request
    rv = self.handle_user_exception(e)
  File "D:\ProgramData\Miniconda3\envs\comp8715\lib\site-packages\flask_cors\extension.py", line 161, in wrapped_function
    return cors_after_request(app.make_response(f(*args, **kwargs)))
  File "D:\ProgramData\Miniconda3\envs\comp8715\lib\site-packages\flask\app.py", line 1820, in handle_user_exception
    reraise(exc_type, exc_value, tb)
  File "D:\ProgramData\Miniconda3\envs\comp8715\lib\site-packages\flask\_compat.py", line 39, in reraise
    raise value
  File "D:\ProgramData\Miniconda3\envs\comp8715\lib\site-packages\flask\app.py", line 1949, in full_dispatch_request
    rv = self.dispatch_request()
  File "D:\ProgramData\Miniconda3\envs\comp8715\lib\site-packages\flask\app.py", line 1935, in dispatch_request
    return self.view_functions[rule.endpoint](**req.view_args)
  File "D:\ProgramData\Miniconda3\envs\comp8715\lib\site-packages\flask_login\utils.py", line 270, in decorated_view
    elif not current_user.is_authenticated:
  File "D:\ProgramData\Miniconda3\envs\comp8715\lib\site-packages\werkzeug\local.py", line 347, in __getattr__
    return getattr(self._get_current_object(), name)
  File "D:\ProgramData\Miniconda3\envs\comp8715\lib\site-packages\werkzeug\local.py", line 306, in _get_current_object
    return self.__local()
  File "D:\ProgramData\Miniconda3\envs\comp8715\lib\site-packages\flask_login\utils.py", line 26, in <lambda>
    current_user = LocalProxy(lambda: _get_user())
  File "D:\ProgramData\Miniconda3\envs\comp8715\lib\site-packages\flask_login\utils.py", line 346, in _get_user
    current_app.login_manager._load_user()
  File "D:\ProgramData\Miniconda3\envs\comp8715\lib\site-packages\flask_login\login_manager.py", line 318, in _load_user
    user = self._user_callback(user_id)
  File "D:\TedZhang\Courses\COMP8715\SAT-Track\server\__init__.py", line 42, in load_user
    return UserManager.get(user_id)
  File "D:\TedZhang\Courses\COMP8715\SAT-Track\server\services\data_storage_service.py", line 23, in get
    ip=res['ip']
KeyError: 'ip'

During handling of the above exception, another exception occurred:

Traceback (most recent call last):
  File "D:\ProgramData\Miniconda3\envs\comp8715\lib\site-packages\flask\app.py", line 1969, in finalize_request
    response = self.process_response(response)
  File "D:\ProgramData\Miniconda3\envs\comp8715\lib\site-packages\flask\app.py", line 2266, in process_response
    response = handler(response)
  File "D:\TedZhang\Courses\COMP8715\SAT-Track\server\views\view.py", line 192, in after_app_request
    user = UserManager.get(user_id)
  File "D:\TedZhang\Courses\COMP8715\SAT-Track\server\services\data_storage_service.py", line 23, in get
    ip=res['ip']
KeyError: 'ip'
[2020-05-19 14:22:24,921][app.py:1891][ERROR][11896] - Exception on / [GET]
Traceback (most recent call last):
  File "D:\ProgramData\Miniconda3\envs\comp8715\lib\site-packages\flask\app.py", line 2446, in wsgi_app
    response = self.full_dispatch_request()
  File "D:\ProgramData\Miniconda3\envs\comp8715\lib\site-packages\flask\app.py", line 1952, in full_dispatch_request
    return self.finalize_request(rv)
  File "D:\ProgramData\Miniconda3\envs\comp8715\lib\site-packages\flask\app.py", line 1969, in finalize_request
    response = self.process_response(response)
  File "D:\ProgramData\Miniconda3\envs\comp8715\lib\site-packages\flask\app.py", line 2266, in process_response
    response = handler(response)
  File "D:\TedZhang\Courses\COMP8715\SAT-Track\server\views\view.py", line 193, in after_app_request
    UserManager.set(user.set_ip(user_ip))
AttributeError: 'NoneType' object has no attribute 'set_ip'
[2020-05-19 14:22:24,924][app.py:1975][ERROR][11896] - Request finalizing failed with an error while handling an error
Traceback (most recent call last):
  File "D:\ProgramData\Miniconda3\envs\comp8715\lib\site-packages\flask\app.py", line 2446, in wsgi_app
    response = self.full_dispatch_request()
  File "D:\ProgramData\Miniconda3\envs\comp8715\lib\site-packages\flask\app.py", line 1952, in full_dispatch_request
    return self.finalize_request(rv)
  File "D:\ProgramData\Miniconda3\envs\comp8715\lib\site-packages\flask\app.py", line 1969, in finalize_request
    response = self.process_response(response)
  File "D:\ProgramData\Miniconda3\envs\comp8715\lib\site-packages\flask\app.py", line 2266, in process_response
    response = handler(response)
  File "D:\TedZhang\Courses\COMP8715\SAT-Track\server\views\view.py", line 193, in after_app_request
    UserManager.set(user.set_ip(user_ip))
AttributeError: 'NoneType' object has no attribute 'set_ip'

During handling of the above exception, another exception occurred:

Traceback (most recent call last):
  File "D:\ProgramData\Miniconda3\envs\comp8715\lib\site-packages\flask\app.py", line 1969, in finalize_request
    response = self.process_response(response)
  File "D:\ProgramData\Miniconda3\envs\comp8715\lib\site-packages\flask\app.py", line 2266, in process_response
    response = handler(response)
  File "D:\TedZhang\Courses\COMP8715\SAT-Track\server\views\view.py", line 193, in after_app_request
    UserManager.set(user.set_ip(user_ip))
AttributeError: 'NoneType' object has no attribute 'set_ip'
[2020-05-19 14:22:26,857][app.py:1891][ERROR][9636] - Exception on / [GET]
Traceback (most recent call last):
  File "D:\ProgramData\Miniconda3\envs\comp8715\lib\site-packages\flask\app.py", line 2446, in wsgi_app
    response = self.full_dispatch_request()
  File "D:\ProgramData\Miniconda3\envs\comp8715\lib\site-packages\flask\app.py", line 1952, in full_dispatch_request
    return self.finalize_request(rv)
  File "D:\ProgramData\Miniconda3\envs\comp8715\lib\site-packages\flask\app.py", line 1969, in finalize_request
    response = self.process_response(response)
  File "D:\ProgramData\Miniconda3\envs\comp8715\lib\site-packages\flask\app.py", line 2266, in process_response
    response = handler(response)
  File "D:\TedZhang\Courses\COMP8715\SAT-Track\server\views\view.py", line 193, in after_app_request
    UserManager.set(user.set_ip(user_ip))
AttributeError: 'NoneType' object has no attribute 'set_ip'
[2020-05-19 14:22:26,859][app.py:1975][ERROR][9636] - Request finalizing failed with an error while handling an error
Traceback (most recent call last):
  File "D:\ProgramData\Miniconda3\envs\comp8715\lib\site-packages\flask\app.py", line 2446, in wsgi_app
    response = self.full_dispatch_request()
  File "D:\ProgramData\Miniconda3\envs\comp8715\lib\site-packages\flask\app.py", line 1952, in full_dispatch_request
    return self.finalize_request(rv)
  File "D:\ProgramData\Miniconda3\envs\comp8715\lib\site-packages\flask\app.py", line 1969, in finalize_request
    response = self.process_response(response)
  File "D:\ProgramData\Miniconda3\envs\comp8715\lib\site-packages\flask\app.py", line 2266, in process_response
    response = handler(response)
  File "D:\TedZhang\Courses\COMP8715\SAT-Track\server\views\view.py", line 193, in after_app_request
    UserManager.set(user.set_ip(user_ip))
AttributeError: 'NoneType' object has no attribute 'set_ip'

During handling of the above exception, another exception occurred:

Traceback (most recent call last):
  File "D:\ProgramData\Miniconda3\envs\comp8715\lib\site-packages\flask\app.py", line 1969, in finalize_request
    response = self.process_response(response)
  File "D:\ProgramData\Miniconda3\envs\comp8715\lib\site-packages\flask\app.py", line 2266, in process_response
    response = handler(response)
  File "D:\TedZhang\Courses\COMP8715\SAT-Track\server\views\view.py", line 193, in after_app_request
    UserManager.set(user.set_ip(user_ip))
AttributeError: 'NoneType' object has no attribute 'set_ip'
[2020-05-19 14:23:14,490][app.py:1891][ERROR][13456] - Exception on /login [GET]
Traceback (most recent call last):
  File "D:\ProgramData\Miniconda3\envs\comp8715\lib\site-packages\flask\app.py", line 2446, in wsgi_app
    response = self.full_dispatch_request()
  File "D:\ProgramData\Miniconda3\envs\comp8715\lib\site-packages\flask\app.py", line 1951, in full_dispatch_request
    rv = self.handle_user_exception(e)
  File "D:\ProgramData\Miniconda3\envs\comp8715\lib\site-packages\flask_cors\extension.py", line 161, in wrapped_function
    return cors_after_request(app.make_response(f(*args, **kwargs)))
  File "D:\ProgramData\Miniconda3\envs\comp8715\lib\site-packages\flask\app.py", line 1820, in handle_user_exception
    reraise(exc_type, exc_value, tb)
  File "D:\ProgramData\Miniconda3\envs\comp8715\lib\site-packages\flask\_compat.py", line 39, in reraise
    raise value
  File "D:\ProgramData\Miniconda3\envs\comp8715\lib\site-packages\flask\app.py", line 1949, in full_dispatch_request
    rv = self.dispatch_request()
  File "D:\ProgramData\Miniconda3\envs\comp8715\lib\site-packages\flask\app.py", line 1935, in dispatch_request
    return self.view_functions[rule.endpoint](**req.view_args)
  File "D:\TedZhang\Courses\COMP8715\SAT-Track\server\views\auth.py", line 68, in login
    return render_template('login.html', title="Login", form=form)
  File "D:\ProgramData\Miniconda3\envs\comp8715\lib\site-packages\flask\templating.py", line 136, in render_template
    ctx.app.update_template_context(context)
  File "D:\ProgramData\Miniconda3\envs\comp8715\lib\site-packages\flask\app.py", line 838, in update_template_context
    context.update(func())
  File "D:\ProgramData\Miniconda3\envs\comp8715\lib\site-packages\flask_login\utils.py", line 379, in _user_context_processor
    return dict(current_user=_get_user())
  File "D:\ProgramData\Miniconda3\envs\comp8715\lib\site-packages\flask_login\utils.py", line 346, in _get_user
    current_app.login_manager._load_user()
  File "D:\ProgramData\Miniconda3\envs\comp8715\lib\site-packages\flask_login\login_manager.py", line 318, in _load_user
    user = self._user_callback(user_id)
  File "D:\TedZhang\Courses\COMP8715\SAT-Track\server\__init__.py", line 42, in load_user
    return UserManager.get(user_id)
  File "D:\TedZhang\Courses\COMP8715\SAT-Track\server\services\data_storage_service.py", line 23, in get
    ip=res['ip']
KeyError: 'ip'
[2020-05-19 14:26:13,106][app.py:1891][ERROR][15256] - Exception on /login [GET]
Traceback (most recent call last):
  File "D:\ProgramData\Miniconda3\envs\comp8715\lib\site-packages\flask\app.py", line 2446, in wsgi_app
    response = self.full_dispatch_request()
  File "D:\ProgramData\Miniconda3\envs\comp8715\lib\site-packages\flask\app.py", line 1951, in full_dispatch_request
    rv = self.handle_user_exception(e)
  File "D:\ProgramData\Miniconda3\envs\comp8715\lib\site-packages\flask_cors\extension.py", line 161, in wrapped_function
    return cors_after_request(app.make_response(f(*args, **kwargs)))
  File "D:\ProgramData\Miniconda3\envs\comp8715\lib\site-packages\flask\app.py", line 1820, in handle_user_exception
    reraise(exc_type, exc_value, tb)
  File "D:\ProgramData\Miniconda3\envs\comp8715\lib\site-packages\flask\_compat.py", line 39, in reraise
    raise value
  File "D:\ProgramData\Miniconda3\envs\comp8715\lib\site-packages\flask\app.py", line 1949, in full_dispatch_request
    rv = self.dispatch_request()
  File "D:\ProgramData\Miniconda3\envs\comp8715\lib\site-packages\flask\app.py", line 1935, in dispatch_request
    return self.view_functions[rule.endpoint](**req.view_args)
  File "D:\TedZhang\Courses\COMP8715\SAT-Track\server\views\auth.py", line 68, in login
    return render_template('login.html', title="Login", form=form)
  File "D:\ProgramData\Miniconda3\envs\comp8715\lib\site-packages\flask\templating.py", line 136, in render_template
    ctx.app.update_template_context(context)
  File "D:\ProgramData\Miniconda3\envs\comp8715\lib\site-packages\flask\app.py", line 838, in update_template_context
    context.update(func())
  File "D:\ProgramData\Miniconda3\envs\comp8715\lib\site-packages\flask_login\utils.py", line 379, in _user_context_processor
    return dict(current_user=_get_user())
  File "D:\ProgramData\Miniconda3\envs\comp8715\lib\site-packages\flask_login\utils.py", line 346, in _get_user
    current_app.login_manager._load_user()
  File "D:\ProgramData\Miniconda3\envs\comp8715\lib\site-packages\flask_login\login_manager.py", line 318, in _load_user
    user = self._user_callback(user_id)
  File "D:\TedZhang\Courses\COMP8715\SAT-Track\server\__init__.py", line 42, in load_user
    return UserManager.get(user_id)
  File "D:\TedZhang\Courses\COMP8715\SAT-Track\server\services\data_storage_service.py", line 23, in get
    ip=res['ip']
KeyError: 'ip'
[2020-05-19 14:26:27,404][app.py:1891][ERROR][11724] - Exception on / [GET]
Traceback (most recent call last):
  File "D:\ProgramData\Miniconda3\envs\comp8715\lib\site-packages\flask\app.py", line 2446, in wsgi_app
    response = self.full_dispatch_request()
  File "D:\ProgramData\Miniconda3\envs\comp8715\lib\site-packages\flask\app.py", line 1951, in full_dispatch_request
    rv = self.handle_user_exception(e)
  File "D:\ProgramData\Miniconda3\envs\comp8715\lib\site-packages\flask_cors\extension.py", line 161, in wrapped_function
    return cors_after_request(app.make_response(f(*args, **kwargs)))
  File "D:\ProgramData\Miniconda3\envs\comp8715\lib\site-packages\flask\app.py", line 1820, in handle_user_exception
    reraise(exc_type, exc_value, tb)
  File "D:\ProgramData\Miniconda3\envs\comp8715\lib\site-packages\flask\_compat.py", line 39, in reraise
    raise value
  File "D:\ProgramData\Miniconda3\envs\comp8715\lib\site-packages\flask\app.py", line 1949, in full_dispatch_request
    rv = self.dispatch_request()
  File "D:\ProgramData\Miniconda3\envs\comp8715\lib\site-packages\flask\app.py", line 1935, in dispatch_request
    return self.view_functions[rule.endpoint](**req.view_args)
  File "D:\ProgramData\Miniconda3\envs\comp8715\lib\site-packages\flask_login\utils.py", line 270, in decorated_view
    elif not current_user.is_authenticated:
  File "D:\ProgramData\Miniconda3\envs\comp8715\lib\site-packages\werkzeug\local.py", line 347, in __getattr__
    return getattr(self._get_current_object(), name)
  File "D:\ProgramData\Miniconda3\envs\comp8715\lib\site-packages\werkzeug\local.py", line 306, in _get_current_object
    return self.__local()
  File "D:\ProgramData\Miniconda3\envs\comp8715\lib\site-packages\flask_login\utils.py", line 26, in <lambda>
    current_user = LocalProxy(lambda: _get_user())
  File "D:\ProgramData\Miniconda3\envs\comp8715\lib\site-packages\flask_login\utils.py", line 346, in _get_user
    current_app.login_manager._load_user()
  File "D:\ProgramData\Miniconda3\envs\comp8715\lib\site-packages\flask_login\login_manager.py", line 318, in _load_user
    user = self._user_callback(user_id)
  File "D:\TedZhang\Courses\COMP8715\SAT-Track\server\__init__.py", line 42, in load_user
    return UserManager.get(user_id)
  File "D:\TedZhang\Courses\COMP8715\SAT-Track\server\services\data_storage_service.py", line 23, in get
    ip=res['ip']
KeyError: 'ip'
[2020-05-19 14:26:27,407][app.py:1975][ERROR][11724] - Request finalizing failed with an error while handling an error
Traceback (most recent call last):
  File "D:\ProgramData\Miniconda3\envs\comp8715\lib\site-packages\flask\app.py", line 2446, in wsgi_app
    response = self.full_dispatch_request()
  File "D:\ProgramData\Miniconda3\envs\comp8715\lib\site-packages\flask\app.py", line 1951, in full_dispatch_request
    rv = self.handle_user_exception(e)
  File "D:\ProgramData\Miniconda3\envs\comp8715\lib\site-packages\flask_cors\extension.py", line 161, in wrapped_function
    return cors_after_request(app.make_response(f(*args, **kwargs)))
  File "D:\ProgramData\Miniconda3\envs\comp8715\lib\site-packages\flask\app.py", line 1820, in handle_user_exception
    reraise(exc_type, exc_value, tb)
  File "D:\ProgramData\Miniconda3\envs\comp8715\lib\site-packages\flask\_compat.py", line 39, in reraise
    raise value
  File "D:\ProgramData\Miniconda3\envs\comp8715\lib\site-packages\flask\app.py", line 1949, in full_dispatch_request
    rv = self.dispatch_request()
  File "D:\ProgramData\Miniconda3\envs\comp8715\lib\site-packages\flask\app.py", line 1935, in dispatch_request
    return self.view_functions[rule.endpoint](**req.view_args)
  File "D:\ProgramData\Miniconda3\envs\comp8715\lib\site-packages\flask_login\utils.py", line 270, in decorated_view
    elif not current_user.is_authenticated:
  File "D:\ProgramData\Miniconda3\envs\comp8715\lib\site-packages\werkzeug\local.py", line 347, in __getattr__
    return getattr(self._get_current_object(), name)
  File "D:\ProgramData\Miniconda3\envs\comp8715\lib\site-packages\werkzeug\local.py", line 306, in _get_current_object
    return self.__local()
  File "D:\ProgramData\Miniconda3\envs\comp8715\lib\site-packages\flask_login\utils.py", line 26, in <lambda>
    current_user = LocalProxy(lambda: _get_user())
  File "D:\ProgramData\Miniconda3\envs\comp8715\lib\site-packages\flask_login\utils.py", line 346, in _get_user
    current_app.login_manager._load_user()
  File "D:\ProgramData\Miniconda3\envs\comp8715\lib\site-packages\flask_login\login_manager.py", line 318, in _load_user
    user = self._user_callback(user_id)
  File "D:\TedZhang\Courses\COMP8715\SAT-Track\server\__init__.py", line 42, in load_user
    return UserManager.get(user_id)
  File "D:\TedZhang\Courses\COMP8715\SAT-Track\server\services\data_storage_service.py", line 23, in get
    ip=res['ip']
KeyError: 'ip'

During handling of the above exception, another exception occurred:

Traceback (most recent call last):
  File "D:\ProgramData\Miniconda3\envs\comp8715\lib\site-packages\flask\app.py", line 1969, in finalize_request
    response = self.process_response(response)
  File "D:\ProgramData\Miniconda3\envs\comp8715\lib\site-packages\flask\app.py", line 2266, in process_response
    response = handler(response)
  File "D:\TedZhang\Courses\COMP8715\SAT-Track\server\views\view.py", line 192, in after_app_request
    user = UserManager.get(user_id)
  File "D:\TedZhang\Courses\COMP8715\SAT-Track\server\services\data_storage_service.py", line 23, in get
    ip=res['ip']
KeyError: 'ip'
[2020-05-19 21:22:45,741][app.py:1891][ERROR][9336] - Exception on /selectSatellite [GET]
Traceback (most recent call last):
  File "D:\ProgramData\Miniconda3\envs\comp8715\lib\site-packages\flask\app.py", line 2446, in wsgi_app
    response = self.full_dispatch_request()
  File "D:\ProgramData\Miniconda3\envs\comp8715\lib\site-packages\flask\app.py", line 1951, in full_dispatch_request
    rv = self.handle_user_exception(e)
  File "D:\ProgramData\Miniconda3\envs\comp8715\lib\site-packages\flask_cors\extension.py", line 161, in wrapped_function
    return cors_after_request(app.make_response(f(*args, **kwargs)))
  File "D:\ProgramData\Miniconda3\envs\comp8715\lib\site-packages\flask\app.py", line 1820, in handle_user_exception
    reraise(exc_type, exc_value, tb)
  File "D:\ProgramData\Miniconda3\envs\comp8715\lib\site-packages\flask\_compat.py", line 39, in reraise
    raise value
  File "D:\ProgramData\Miniconda3\envs\comp8715\lib\site-packages\flask\app.py", line 1949, in full_dispatch_request
    rv = self.dispatch_request()
  File "D:\ProgramData\Miniconda3\envs\comp8715\lib\site-packages\flask\app.py", line 1935, in dispatch_request
    return self.view_functions[rule.endpoint](**req.view_args)
  File "D:\TedZhang\Courses\COMP8715\SAT-Track\server\views\view.py", line 164, in select_satellite
    satellite_id = int(request.args.get('id'))
TypeError: int() argument must be a string, a bytes-like object or a number, not 'NoneType'
[2020-05-19 21:22:46,528][app.py:1891][ERROR][15880] - Exception on /selectSatellite [GET]
Traceback (most recent call last):
  File "D:\ProgramData\Miniconda3\envs\comp8715\lib\site-packages\flask\app.py", line 2446, in wsgi_app
    response = self.full_dispatch_request()
  File "D:\ProgramData\Miniconda3\envs\comp8715\lib\site-packages\flask\app.py", line 1951, in full_dispatch_request
    rv = self.handle_user_exception(e)
  File "D:\ProgramData\Miniconda3\envs\comp8715\lib\site-packages\flask_cors\extension.py", line 161, in wrapped_function
    return cors_after_request(app.make_response(f(*args, **kwargs)))
  File "D:\ProgramData\Miniconda3\envs\comp8715\lib\site-packages\flask\app.py", line 1820, in handle_user_exception
    reraise(exc_type, exc_value, tb)
  File "D:\ProgramData\Miniconda3\envs\comp8715\lib\site-packages\flask\_compat.py", line 39, in reraise
    raise value
  File "D:\ProgramData\Miniconda3\envs\comp8715\lib\site-packages\flask\app.py", line 1949, in full_dispatch_request
    rv = self.dispatch_request()
  File "D:\ProgramData\Miniconda3\envs\comp8715\lib\site-packages\flask\app.py", line 1935, in dispatch_request
    return self.view_functions[rule.endpoint](**req.view_args)
  File "D:\TedZhang\Courses\COMP8715\SAT-Track\server\views\view.py", line 164, in select_satellite
    satellite_id = int(request.args.get('id'))
TypeError: int() argument must be a string, a bytes-like object or a number, not 'NoneType'
[2020-05-20 00:37:38,807][app.py:1891][ERROR][2708] - Exception on /getSatInfo [GET]
Traceback (most recent call last):
  File "D:\ProgramData\Miniconda3\envs\comp8715\lib\site-packages\flask\app.py", line 2446, in wsgi_app
    response = self.full_dispatch_request()
  File "D:\ProgramData\Miniconda3\envs\comp8715\lib\site-packages\flask\app.py", line 1951, in full_dispatch_request
    rv = self.handle_user_exception(e)
  File "D:\ProgramData\Miniconda3\envs\comp8715\lib\site-packages\flask_cors\extension.py", line 161, in wrapped_function
    return cors_after_request(app.make_response(f(*args, **kwargs)))
  File "D:\ProgramData\Miniconda3\envs\comp8715\lib\site-packages\flask\app.py", line 1820, in handle_user_exception
    reraise(exc_type, exc_value, tb)
  File "D:\ProgramData\Miniconda3\envs\comp8715\lib\site-packages\flask\_compat.py", line 39, in reraise
    raise value
  File "D:\ProgramData\Miniconda3\envs\comp8715\lib\site-packages\flask\app.py", line 1949, in full_dispatch_request
    rv = self.dispatch_request()
  File "D:\ProgramData\Miniconda3\envs\comp8715\lib\site-packages\flask\app.py", line 1935, in dispatch_request
    return self.view_functions[rule.endpoint](**req.view_args)
  File "D:\TedZhang\Courses\COMP8715\SAT-Track\server\views\view.py", line 216, in get_sat_info
    return redirect(url_for('satelliteInfo', satinfo=satinfo))
  File "D:\ProgramData\Miniconda3\envs\comp8715\lib\site-packages\flask\helpers.py", line 370, in url_for
    return appctx.app.handle_url_build_error(error, endpoint, values)
  File "D:\ProgramData\Miniconda3\envs\comp8715\lib\site-packages\flask\app.py", line 2215, in handle_url_build_error
    reraise(exc_type, exc_value, tb)
  File "D:\ProgramData\Miniconda3\envs\comp8715\lib\site-packages\flask\_compat.py", line 39, in reraise
    raise value
  File "D:\ProgramData\Miniconda3\envs\comp8715\lib\site-packages\flask\helpers.py", line 358, in url_for
    endpoint, values, method=method, force_external=external
  File "D:\ProgramData\Miniconda3\envs\comp8715\lib\site-packages\werkzeug\routing.py", line 2179, in build
    raise BuildError(endpoint, values, method, self)
werkzeug.routing.BuildError: Could not build url for endpoint 'satelliteInfo'. Did you mean 'view.satellite_info' instead?
[2020-05-20 00:38:42,890][app.py:1891][ERROR][16228] - Exception on /getSatInfo [GET]
Traceback (most recent call last):
  File "D:\ProgramData\Miniconda3\envs\comp8715\lib\site-packages\flask\app.py", line 2446, in wsgi_app
    response = self.full_dispatch_request()
  File "D:\ProgramData\Miniconda3\envs\comp8715\lib\site-packages\flask\app.py", line 1951, in full_dispatch_request
    rv = self.handle_user_exception(e)
  File "D:\ProgramData\Miniconda3\envs\comp8715\lib\site-packages\flask_cors\extension.py", line 161, in wrapped_function
    return cors_after_request(app.make_response(f(*args, **kwargs)))
  File "D:\ProgramData\Miniconda3\envs\comp8715\lib\site-packages\flask\app.py", line 1820, in handle_user_exception
    reraise(exc_type, exc_value, tb)
  File "D:\ProgramData\Miniconda3\envs\comp8715\lib\site-packages\flask\_compat.py", line 39, in reraise
    raise value
  File "D:\ProgramData\Miniconda3\envs\comp8715\lib\site-packages\flask\app.py", line 1949, in full_dispatch_request
    rv = self.dispatch_request()
  File "D:\ProgramData\Miniconda3\envs\comp8715\lib\site-packages\flask\app.py", line 1935, in dispatch_request
    return self.view_functions[rule.endpoint](**req.view_args)
  File "D:\TedZhang\Courses\COMP8715\SAT-Track\server\views\view.py", line 216, in get_sat_info
    return redirect(url_for('view.satelliteInfo', satinfo=satinfo))
  File "D:\ProgramData\Miniconda3\envs\comp8715\lib\site-packages\flask\helpers.py", line 370, in url_for
    return appctx.app.handle_url_build_error(error, endpoint, values)
  File "D:\ProgramData\Miniconda3\envs\comp8715\lib\site-packages\flask\app.py", line 2215, in handle_url_build_error
    reraise(exc_type, exc_value, tb)
  File "D:\ProgramData\Miniconda3\envs\comp8715\lib\site-packages\flask\_compat.py", line 39, in reraise
    raise value
  File "D:\ProgramData\Miniconda3\envs\comp8715\lib\site-packages\flask\helpers.py", line 358, in url_for
    endpoint, values, method=method, force_external=external
  File "D:\ProgramData\Miniconda3\envs\comp8715\lib\site-packages\werkzeug\routing.py", line 2179, in build
    raise BuildError(endpoint, values, method, self)
werkzeug.routing.BuildError: Could not build url for endpoint 'view.satelliteInfo'. Did you mean 'view.satellite_info' instead?
[2020-05-20 00:41:31,451][app.py:1891][ERROR][15988] - Exception on /satelliteInfo [GET]
Traceback (most recent call last):
  File "D:\ProgramData\Miniconda3\envs\comp8715\lib\site-packages\flask\app.py", line 2446, in wsgi_app
    response = self.full_dispatch_request()
  File "D:\ProgramData\Miniconda3\envs\comp8715\lib\site-packages\flask\app.py", line 1951, in full_dispatch_request
    rv = self.handle_user_exception(e)
  File "D:\ProgramData\Miniconda3\envs\comp8715\lib\site-packages\flask_cors\extension.py", line 161, in wrapped_function
    return cors_after_request(app.make_response(f(*args, **kwargs)))
  File "D:\ProgramData\Miniconda3\envs\comp8715\lib\site-packages\flask\app.py", line 1820, in handle_user_exception
    reraise(exc_type, exc_value, tb)
  File "D:\ProgramData\Miniconda3\envs\comp8715\lib\site-packages\flask\_compat.py", line 39, in reraise
    raise value
  File "D:\ProgramData\Miniconda3\envs\comp8715\lib\site-packages\flask\app.py", line 1949, in full_dispatch_request
    rv = self.dispatch_request()
  File "D:\ProgramData\Miniconda3\envs\comp8715\lib\site-packages\flask\app.py", line 1935, in dispatch_request
    return self.view_functions[rule.endpoint](**req.view_args)
  File "D:\TedZhang\Courses\COMP8715\SAT-Track\server\views\view.py", line 194, in satellite_info
    mag='this is satellite info html' + str(satinfo)
NameError: name 'satinfo' is not defined
[2020-05-20 01:18:07,419][app.py:1891][ERROR][14848] - Exception on /satelliteInfo [GET]
Traceback (most recent call last):
  File "D:\ProgramData\Miniconda3\envs\comp8715\lib\site-packages\flask\app.py", line 2446, in wsgi_app
    response = self.full_dispatch_request()
  File "D:\ProgramData\Miniconda3\envs\comp8715\lib\site-packages\flask\app.py", line 1951, in full_dispatch_request
    rv = self.handle_user_exception(e)
  File "D:\ProgramData\Miniconda3\envs\comp8715\lib\site-packages\flask_cors\extension.py", line 161, in wrapped_function
    return cors_after_request(app.make_response(f(*args, **kwargs)))
  File "D:\ProgramData\Miniconda3\envs\comp8715\lib\site-packages\flask\app.py", line 1820, in handle_user_exception
    reraise(exc_type, exc_value, tb)
  File "D:\ProgramData\Miniconda3\envs\comp8715\lib\site-packages\flask\_compat.py", line 39, in reraise
    raise value
  File "D:\ProgramData\Miniconda3\envs\comp8715\lib\site-packages\flask\app.py", line 1949, in full_dispatch_request
    rv = self.dispatch_request()
  File "D:\ProgramData\Miniconda3\envs\comp8715\lib\site-packages\flask\app.py", line 1935, in dispatch_request
    return self.view_functions[rule.endpoint](**req.view_args)
TypeError: satellite_info() missing 1 required positional argument: 'satinfo'
[2020-05-20 01:19:58,503][app.py:1891][ERROR][15816] - Exception on /satelliteInfo?{"intl_code": "1978-093A", "norad_id": 11054, "name": "NAVSTAR 3 (OPS 5113)", "source": "us", "launch_date_text": "1978 10 07", "launch_date": "1978-10-07", "decay_date": null, "launch_unixtime": 276537600, "decay_unixtime": null, "launch_site": "afwtr", "status": "m*- (nonoperational active)", "extract": "navstar 3 (ops 5113) | us united states   us usa united states of america (usa)    | 1978 10 07 |  afwtr  air force western test range (afwtr) |  global positioning system (gps) constellation | m*- nonoperational active | trackable", "tle": ["1 11054U 78093A   20109.40549764 -.00000097 +00000-0 +00000-0 0  9996", "2 11054 064.0663 006.1805 0090677 231.2897 256.6120 01.93503869297126"], "ip": "127.0.0.1", "az": 99.99814269456955, "alt": -25.171200525599613, "vel": -687.9077758789062, "lat": -35.2712287902832, "long": 149.1183624267578, "elev": 565.9379272460938} [GET]
Traceback (most recent call last):
  File "D:\ProgramData\Miniconda3\envs\comp8715\lib\site-packages\flask\app.py", line 2446, in wsgi_app
    response = self.full_dispatch_request()
  File "D:\ProgramData\Miniconda3\envs\comp8715\lib\site-packages\flask\app.py", line 1951, in full_dispatch_request
    rv = self.handle_user_exception(e)
  File "D:\ProgramData\Miniconda3\envs\comp8715\lib\site-packages\flask_cors\extension.py", line 161, in wrapped_function
    return cors_after_request(app.make_response(f(*args, **kwargs)))
  File "D:\ProgramData\Miniconda3\envs\comp8715\lib\site-packages\flask\app.py", line 1820, in handle_user_exception
    reraise(exc_type, exc_value, tb)
  File "D:\ProgramData\Miniconda3\envs\comp8715\lib\site-packages\flask\_compat.py", line 39, in reraise
    raise value
  File "D:\ProgramData\Miniconda3\envs\comp8715\lib\site-packages\flask\app.py", line 1949, in full_dispatch_request
    rv = self.dispatch_request()
  File "D:\ProgramData\Miniconda3\envs\comp8715\lib\site-packages\flask\app.py", line 1935, in dispatch_request
    return self.view_functions[rule.endpoint](**req.view_args)
  File "D:\TedZhang\Courses\COMP8715\SAT-Track\server\views\view.py", line 188, in satellite_info
    return jsonify(**satinfo)
TypeError: jsonify() argument after ** must be a mapping, not str
[2020-05-20 01:43:57,695][app.py:1891][ERROR][15796] - Exception on /satelliteInfo?{"intl_code": "1978-093A", "norad_id": 11054, "name": "NAVSTAR 3 (OPS 5113)", "source": "us", "launch_date_text": "1978 10 07", "launch_date": "1978-10-07", "decay_date": null, "launch_unixtime": 276537600, "decay_unixtime": null, "launch_site": "afwtr", "status": "m*- (nonoperational active)", "extract": "navstar 3 (ops 5113) | us united states   us usa united states of america (usa)    | 1978 10 07 |  afwtr  air force western test range (afwtr) |  global positioning system (gps) constellation | m*- nonoperational active | trackable", "tle": ["1 11054U 78093A   20109.40549764 -.00000097 +00000-0 +00000-0 0  9996", "2 11054 064.0663 006.1805 0090677 231.2897 256.6120 01.93503869297126"], "ip": "127.0.0.1", "az": 99.75653841305869, "alt": -17.779428079386534, "vel": -732.994140625, "lat": -35.2712287902832, "long": 149.1183624267578, "elev": 565.9379272460938} [GET]
Traceback (most recent call last):
  File "D:\ProgramData\Miniconda3\envs\comp8715\lib\site-packages\flask\app.py", line 2446, in wsgi_app
    response = self.full_dispatch_request()
  File "D:\ProgramData\Miniconda3\envs\comp8715\lib\site-packages\flask\app.py", line 1951, in full_dispatch_request
    rv = self.handle_user_exception(e)
  File "D:\ProgramData\Miniconda3\envs\comp8715\lib\site-packages\flask_cors\extension.py", line 161, in wrapped_function
    return cors_after_request(app.make_response(f(*args, **kwargs)))
  File "D:\ProgramData\Miniconda3\envs\comp8715\lib\site-packages\flask\app.py", line 1820, in handle_user_exception
    reraise(exc_type, exc_value, tb)
  File "D:\ProgramData\Miniconda3\envs\comp8715\lib\site-packages\flask\_compat.py", line 39, in reraise
    raise value
  File "D:\ProgramData\Miniconda3\envs\comp8715\lib\site-packages\flask\app.py", line 1949, in full_dispatch_request
    rv = self.dispatch_request()
  File "D:\ProgramData\Miniconda3\envs\comp8715\lib\site-packages\flask\app.py", line 1935, in dispatch_request
    return self.view_functions[rule.endpoint](**req.view_args)
  File "D:\TedZhang\Courses\COMP8715\SAT-Track\server\views\view.py", line 197, in satellite_info
    username = UserManager.get(user_id).get_name()
AttributeError: 'NoneType' object has no attribute 'get_name'
[2020-05-20 01:57:14,562][app.py:1891][ERROR][10596] - Exception on /satelliteInfo?{"intl_code": "2018-102G", "norad_id": 43837, "name": "OBJECT G", "source": "tbd", "launch_date_text": "2018 12 07", "launch_date": "2018-12-07", "decay_date": null, "launch_unixtime": 1544112000, "decay_unixtime": null, "launch_site": "jsc", "status": "*+ (operational active)", "extract": "object g | tbd none    | 2018 12 07 |  jsc  jiuquan space center (jsc) |  | *+ operational active | trackable", "tle": ["1 43837U 18102G   20111.08665807  .00000832  00000-0  56134-4 0  9998", "2 43837  97.5753 188.8890 0015572  17.3823  99.8120 15.09292041 75384"], "lat": null, "long": null, "elev": null, "az": null, "alt": null, "vel": null} [GET]
Traceback (most recent call last):
  File "D:\ProgramData\Miniconda3\envs\comp8715\lib\site-packages\flask\app.py", line 2446, in wsgi_app
    response = self.full_dispatch_request()
  File "D:\ProgramData\Miniconda3\envs\comp8715\lib\site-packages\flask\app.py", line 1951, in full_dispatch_request
    rv = self.handle_user_exception(e)
  File "D:\ProgramData\Miniconda3\envs\comp8715\lib\site-packages\flask_cors\extension.py", line 161, in wrapped_function
    return cors_after_request(app.make_response(f(*args, **kwargs)))
  File "D:\ProgramData\Miniconda3\envs\comp8715\lib\site-packages\flask\app.py", line 1820, in handle_user_exception
    reraise(exc_type, exc_value, tb)
  File "D:\ProgramData\Miniconda3\envs\comp8715\lib\site-packages\flask\_compat.py", line 39, in reraise
    raise value
  File "D:\ProgramData\Miniconda3\envs\comp8715\lib\site-packages\flask\app.py", line 1949, in full_dispatch_request
    rv = self.dispatch_request()
  File "D:\ProgramData\Miniconda3\envs\comp8715\lib\site-packages\flask\app.py", line 1935, in dispatch_request
    return self.view_functions[rule.endpoint](**req.view_args)
  File "D:\TedZhang\Courses\COMP8715\SAT-Track\server\views\view.py", line 197, in satellite_info
    username = UserManager.get(user_id).get_name()
AttributeError: 'NoneType' object has no attribute 'get_name'
[2020-05-20 04:04:06,990][app.py:1891][ERROR][5544] - Exception on /satelliteInfo?null [GET]
Traceback (most recent call last):
  File "D:\ProgramData\Miniconda3\envs\comp8715\lib\site-packages\flask\app.py", line 2446, in wsgi_app
    response = self.full_dispatch_request()
  File "D:\ProgramData\Miniconda3\envs\comp8715\lib\site-packages\flask\app.py", line 1951, in full_dispatch_request
    rv = self.handle_user_exception(e)
  File "D:\ProgramData\Miniconda3\envs\comp8715\lib\site-packages\flask_cors\extension.py", line 161, in wrapped_function
    return cors_after_request(app.make_response(f(*args, **kwargs)))
  File "D:\ProgramData\Miniconda3\envs\comp8715\lib\site-packages\flask\app.py", line 1820, in handle_user_exception
    reraise(exc_type, exc_value, tb)
  File "D:\ProgramData\Miniconda3\envs\comp8715\lib\site-packages\flask\_compat.py", line 39, in reraise
    raise value
  File "D:\ProgramData\Miniconda3\envs\comp8715\lib\site-packages\flask\app.py", line 1949, in full_dispatch_request
    rv = self.dispatch_request()
  File "D:\ProgramData\Miniconda3\envs\comp8715\lib\site-packages\flask\app.py", line 1935, in dispatch_request
    return self.view_functions[rule.endpoint](**req.view_args)
  File "D:\TedZhang\Courses\COMP8715\SAT-Track\server\views\view.py", line 205, in satellite_info
    data.update({field: satinfo[field]})
TypeError: 'NoneType' object is not subscriptable
[2020-05-20 04:06:29,723][app.py:1891][ERROR][15104] - Exception on /satelliteInfo?{"intl_code": "1977-112F", "norad_id": 10594, "name": "SS 3", "source": "us", "launch_date_text": "1977 12 08", "launch_date": "1977-12-08", "decay_date": null, "launch_unixtime": 250358400, "decay_unixtime": null, "launch_site": "afwtr", "status": "* (active)", "group": "military", "extract": "ss 3 | us united states   us usa united states of america (usa)    | 1977 12 08 |  afwtr  air force western test range (afwtr) |  military | * active | trackable", "tle": ["1 10594U 77112F   20110.38649673  .00000477  00000-0  51204-4 0  9991", "2 10594  63.3014  63.6078 0735573 125.1451 242.0810 13.90856946 53137"], "full_src": "united states", "full_site": "air force western test range (afwtr)", "lat": null, "long": null, "elev": null, "az": null, "alt": null, "vel": null} [GET]
Traceback (most recent call last):
  File "D:\ProgramData\Miniconda3\envs\comp8715\lib\site-packages\flask\app.py", line 2446, in wsgi_app
    response = self.full_dispatch_request()
  File "D:\ProgramData\Miniconda3\envs\comp8715\lib\site-packages\flask\app.py", line 1951, in full_dispatch_request
    rv = self.handle_user_exception(e)
  File "D:\ProgramData\Miniconda3\envs\comp8715\lib\site-packages\flask_cors\extension.py", line 161, in wrapped_function
    return cors_after_request(app.make_response(f(*args, **kwargs)))
  File "D:\ProgramData\Miniconda3\envs\comp8715\lib\site-packages\flask\app.py", line 1820, in handle_user_exception
    reraise(exc_type, exc_value, tb)
  File "D:\ProgramData\Miniconda3\envs\comp8715\lib\site-packages\flask\_compat.py", line 39, in reraise
    raise value
  File "D:\ProgramData\Miniconda3\envs\comp8715\lib\site-packages\flask\app.py", line 1949, in full_dispatch_request
    rv = self.dispatch_request()
  File "D:\ProgramData\Miniconda3\envs\comp8715\lib\site-packages\flask\app.py", line 1935, in dispatch_request
    return self.view_functions[rule.endpoint](**req.view_args)
  File "D:\TedZhang\Courses\COMP8715\SAT-Track\server\views\view.py", line 206, in satellite_info
    data.update({'username': user.get_name(), 'ip': user.ip})
AttributeError: 'NoneType' object has no attribute 'get_name'
[2020-05-20 04:06:31,141][app.py:1891][ERROR][9480] - Exception on /satelliteInfo?{"intl_code": "2016-033E", "norad_id": 43427, "name": "NUSAT 1 DEB", "source": "argn", "launch_date_text": "2016 05 30", "launch_date": "2016-05-30", "decay_date": null, "launch_unixtime": 1464537600, "decay_unixtime": null, "launch_site": "taisc", "status": "none", "extract": "nusat 1 deb | argn argentina   ar arg argentina    | 2016 05 30 |  taisc  taiyuan space center (taisc) |  |  | trackable", "tle": ["1 43427U 16033E   20110.78246692 +.00000887 +00000-0 +91058-4 0  9991", "2 43427 097.4695 105.0152 0207107 215.6634 143.0595 14.78364441198827"], "lat": null, "long": null, "elev": null, "az": null, "alt": null, "vel": null} [GET]
Traceback (most recent call last):
  File "D:\ProgramData\Miniconda3\envs\comp8715\lib\site-packages\flask\app.py", line 2446, in wsgi_app
    response = self.full_dispatch_request()
  File "D:\ProgramData\Miniconda3\envs\comp8715\lib\site-packages\flask\app.py", line 1951, in full_dispatch_request
    rv = self.handle_user_exception(e)
  File "D:\ProgramData\Miniconda3\envs\comp8715\lib\site-packages\flask_cors\extension.py", line 161, in wrapped_function
    return cors_after_request(app.make_response(f(*args, **kwargs)))
  File "D:\ProgramData\Miniconda3\envs\comp8715\lib\site-packages\flask\app.py", line 1820, in handle_user_exception
    reraise(exc_type, exc_value, tb)
  File "D:\ProgramData\Miniconda3\envs\comp8715\lib\site-packages\flask\_compat.py", line 39, in reraise
    raise value
  File "D:\ProgramData\Miniconda3\envs\comp8715\lib\site-packages\flask\app.py", line 1949, in full_dispatch_request
    rv = self.dispatch_request()
  File "D:\ProgramData\Miniconda3\envs\comp8715\lib\site-packages\flask\app.py", line 1935, in dispatch_request
    return self.view_functions[rule.endpoint](**req.view_args)
  File "D:\TedZhang\Courses\COMP8715\SAT-Track\server\views\view.py", line 205, in satellite_info
    data.update({field: satinfo[field]})
KeyError: 'full_site'
[2020-05-20 05:04:55,335][app.py:1891][ERROR][11328] - Exception on /satelliteInfo?{"intl_code": "2016-025F", "norad_id": 41461, "name": "ASAP-S", "source": "fr", "launch_date_text": "2016 04 25", "launch_date": "2016-04-25", "decay_date": null, "launch_unixtime": 1461513600, "decay_unixtime": null, "launch_site": "frgui", "status": "none", "group": null, "extract": "asap-s | fr france   fr fra france    | 2016 04 25 |  frgui  europe's spaceport (frgui) |  |  | trackable", "tle": ["1 41461U 16025F   20110.85252785 +.00001369 +00000-0 +72853-4 0  9994", "2 41461 098.1234 219.7523 0173366 059.3237 302.4946 15.05183534218542"], "full_src": "france", "full_site": "europe's spaceport (frgui)", "lat": null, "long": null, "elev": null, "az": null, "alt": null, "vel": null} [GET]
Traceback (most recent call last):
  File "D:\ProgramData\Miniconda3\envs\comp8715\lib\site-packages\flask\app.py", line 2446, in wsgi_app
    response = self.full_dispatch_request()
  File "D:\ProgramData\Miniconda3\envs\comp8715\lib\site-packages\flask\app.py", line 1951, in full_dispatch_request
    rv = self.handle_user_exception(e)
  File "D:\ProgramData\Miniconda3\envs\comp8715\lib\site-packages\flask_cors\extension.py", line 161, in wrapped_function
    return cors_after_request(app.make_response(f(*args, **kwargs)))
  File "D:\ProgramData\Miniconda3\envs\comp8715\lib\site-packages\flask\app.py", line 1820, in handle_user_exception
    reraise(exc_type, exc_value, tb)
  File "D:\ProgramData\Miniconda3\envs\comp8715\lib\site-packages\flask\_compat.py", line 39, in reraise
    raise value
  File "D:\ProgramData\Miniconda3\envs\comp8715\lib\site-packages\flask\app.py", line 1949, in full_dispatch_request
    rv = self.dispatch_request()
  File "D:\ProgramData\Miniconda3\envs\comp8715\lib\site-packages\flask\app.py", line 1935, in dispatch_request
    return self.view_functions[rule.endpoint](**req.view_args)
  File "D:\TedZhang\Courses\COMP8715\SAT-Track\server\views\view.py", line 206, in satellite_info
    data.update({'username': user.get_name(), 'ip': user.ip, 'time': Utils.to_datetime(Utils.get_current_time())})
  File "D:\TedZhang\Courses\COMP8715\SAT-Track\utilities\utils.py", line 17, in to_datetime
    return datetime.datetime.fromtimestamp(unixtime, pytz.timezone('Asia/Shanghai')).strftime('%Y-%m-%d %H:%M:%S')
TypeError: an integer is required (got type tuple)
[2020-05-20 06:25:19,226][app.py:1891][ERROR][13344] - Exception on /searchSatellite [GET]
Traceback (most recent call last):
  File "D:\ProgramData\Miniconda3\envs\comp8715\lib\site-packages\flask\app.py", line 2446, in wsgi_app
    response = self.full_dispatch_request()
  File "D:\ProgramData\Miniconda3\envs\comp8715\lib\site-packages\flask\app.py", line 1951, in full_dispatch_request
    rv = self.handle_user_exception(e)
  File "D:\ProgramData\Miniconda3\envs\comp8715\lib\site-packages\flask_cors\extension.py", line 161, in wrapped_function
    return cors_after_request(app.make_response(f(*args, **kwargs)))
  File "D:\ProgramData\Miniconda3\envs\comp8715\lib\site-packages\flask\app.py", line 1820, in handle_user_exception
    reraise(exc_type, exc_value, tb)
  File "D:\ProgramData\Miniconda3\envs\comp8715\lib\site-packages\flask\_compat.py", line 39, in reraise
    raise value
  File "D:\ProgramData\Miniconda3\envs\comp8715\lib\site-packages\flask\app.py", line 1949, in full_dispatch_request
    rv = self.dispatch_request()
  File "D:\ProgramData\Miniconda3\envs\comp8715\lib\site-packages\flask\app.py", line 1935, in dispatch_request
    return self.view_functions[rule.endpoint](**req.view_args)
  File "D:\TedZhang\Courses\COMP8715\SAT-Track\server\views\view.py", line 144, in search_satellite
    status, satellites, beyond_lmt = controll_search_satellites(user_id, user_input)
ValueError: not enough values to unpack (expected 3, got 2)
